Process A [NEW] (arrival time 9 ms) 16 CPU bursts
Process B [NEW] (arrival time 18 ms) 21 CPU bursts
time 0ms: Simulator started for FCFS [Q <empty>]
time 9ms: Process A arrived; added to ready queue [Q A]
time 11ms: Process A started using the CPU for 56ms burst [Q <empty>]
time 18ms: Process B arrived; added to ready queue [Q B]
time 67ms: Process A completed a CPU burst; 15 bursts to go [Q B]
time 67ms: Process A switching out of CPU; will block on I/O until time 92ms [Q B]
time 71ms: Process B started using the CPU for 106ms burst [Q <empty>]
time 92ms: Process A completed I/O; added to ready queue [Q A]
time 177ms: Process B completed a CPU burst; 20 bursts to go [Q A]
time 177ms: Process B switching out of CPU; will block on I/O until time 335ms [Q A]
time 181ms: Process A started using the CPU for 60ms burst [Q <empty>]
time 241ms: Process A completed a CPU burst; 14 bursts to go [Q <empty>]
time 241ms: Process A switching out of CPU; will block on I/O until time 396ms [Q <empty>]
time 335ms: Process B completed I/O; added to ready queue [Q B]
time 337ms: Process B started using the CPU for 198ms burst [Q <empty>]
time 396ms: Process A completed I/O; added to ready queue [Q A]
time 535ms: Process B completed a CPU burst; 19 bursts to go [Q A]
time 535ms: Process B switching out of CPU; will block on I/O until time 650ms [Q A]
time 539ms: Process A started using the CPU for 39ms burst [Q <empty>]
time 578ms: Process A completed a CPU burst; 13 bursts to go [Q <empty>]
time 578ms: Process A switching out of CPU; will block on I/O until time 630ms [Q <empty>]
time 630ms: Process A completed I/O; added to ready queue [Q A]
time 632ms: Process A started using the CPU for 47ms burst [Q <empty>]
time 650ms: Process B completed I/O; added to ready queue [Q B]
time 679ms: Process A completed a CPU burst; 12 bursts to go [Q B]
time 679ms: Process A switching out of CPU; will block on I/O until time 683ms [Q B]
time 683ms: Process B started using the CPU for 208ms burst [Q <empty>]
time 683ms: Process A completed I/O; added to ready queue [Q A]
time 891ms: Process B completed a CPU burst; 18 bursts to go [Q A]
time 891ms: Process B switching out of CPU; will block on I/O until time 1055ms [Q A]
time 895ms: Process A started using the CPU for 137ms burst [Q <empty>]
time 1032ms: Process A completed a CPU burst; 11 bursts to go [Q <empty>]
time 1032ms: Process A switching out of CPU; will block on I/O until time 1058ms [Q <empty>]
time 1055ms: Process B completed I/O; added to ready queue [Q B]
time 1057ms: Process B started using the CPU for 50ms burst [Q <empty>]
time 1058ms: Process A completed I/O; added to ready queue [Q A]
time 1107ms: Process B completed a CPU burst; 17 bursts to go [Q A]
time 1107ms: Process B switching out of CPU; will block on I/O until time 1155ms [Q A]
time 1111ms: Process A started using the CPU for 64ms burst [Q <empty>]
time 1155ms: Process B completed I/O; added to ready queue [Q B]
time 1175ms: Process A completed a CPU burst; 10 bursts to go [Q B]
time 1175ms: Process A switching out of CPU; will block on I/O until time 1192ms [Q B]
time 1179ms: Process B started using the CPU for 82ms burst [Q <empty>]
time 1192ms: Process A completed I/O; added to ready queue [Q A]
time 1261ms: Process B completed a CPU burst; 16 bursts to go [Q A]
time 1261ms: Process B switching out of CPU; will block on I/O until time 1279ms [Q A]
time 1265ms: Process A started using the CPU for 68ms burst [Q <empty>]
time 1279ms: Process B completed I/O; added to ready queue [Q B]
time 1333ms: Process A completed a CPU burst; 9 bursts to go [Q B]
time 1333ms: Process A switching out of CPU; will block on I/O until time 1399ms [Q B]
time 1337ms: Process B started using the CPU for 7ms burst [Q <empty>]
time 1344ms: Process B completed a CPU burst; 15 bursts to go [Q <empty>]
time 1344ms: Process B switching out of CPU; will block on I/O until time 1376ms [Q <empty>]
time 1376ms: Process B completed I/O; added to ready queue [Q B]
time 1378ms: Process B started using the CPU for 52ms burst [Q <empty>]
time 1399ms: Process A completed I/O; added to ready queue [Q A]
time 1430ms: Process B completed a CPU burst; 14 bursts to go [Q A]
time 1430ms: Process B switching out of CPU; will block on I/O until time 1444ms [Q A]
time 1434ms: Process A started using the CPU for 113ms burst [Q <empty>]
time 1444ms: Process B completed I/O; added to ready queue [Q B]
time 1547ms: Process A completed a CPU burst; 8 bursts to go [Q B]
time 1547ms: Process A switching out of CPU; will block on I/O until time 1565ms [Q B]
time 1551ms: Process B started using the CPU for 228ms burst [Q <empty>]
time 1565ms: Process A completed I/O; added to ready queue [Q A]
time 1779ms: Process B completed a CPU burst; 13 bursts to go [Q A]
time 1779ms: Process B switching out of CPU; will block on I/O until time 1858ms [Q A]
time 1783ms: Process A started using the CPU for 11ms burst [Q <empty>]
time 1794ms: Process A completed a CPU burst; 7 bursts to go [Q <empty>]
time 1794ms: Process A switching out of CPU; will block on I/O until time 1958ms [Q <empty>]
time 1858ms: Process B completed I/O; added to ready queue [Q B]
time 1860ms: Process B started using the CPU for 138ms burst [Q <empty>]
time 1958ms: Process A completed I/O; added to ready queue [Q A]
time 1998ms: Process B completed a CPU burst; 12 bursts to go [Q A]
time 1998ms: Process B switching out of CPU; will block on I/O until time 2082ms [Q A]
time 2002ms: Process A started using the CPU for 24ms burst [Q <empty>]
time 2026ms: Process A completed a CPU burst; 6 bursts to go [Q <empty>]
time 2026ms: Process A switching out of CPU; will block on I/O until time 2145ms [Q <empty>]
time 2082ms: Process B completed I/O; added to ready queue [Q B]
time 2084ms: Process B started using the CPU for 67ms burst [Q <empty>]
time 2145ms: Process A completed I/O; added to ready queue [Q A]
time 2151ms: Process B completed a CPU burst; 11 bursts to go [Q A]
time 2151ms: Process B switching out of CPU; will block on I/O until time 2160ms [Q A]
time 2155ms: Process A started using the CPU for 76ms burst [Q <empty>]
time 2160ms: Process B completed I/O; added to ready queue [Q B]
time 2231ms: Process A completed a CPU burst; 5 bursts to go [Q B]
time 2231ms: Process A switching out of CPU; will block on I/O until time 2261ms [Q B]
time 2235ms: Process B started using the CPU for 120ms burst [Q <empty>]
time 2261ms: Process A completed I/O; added to ready queue [Q A]
time 2355ms: Process B completed a CPU burst; 10 bursts to go [Q A]
time 2355ms: Process B switching out of CPU; will block on I/O until time 2370ms [Q A]
time 2359ms: Process A started using the CPU for 122ms burst [Q <empty>]
time 2370ms: Process B completed I/O; added to ready queue [Q B]
time 2481ms: Process A completed a CPU burst; 4 bursts to go [Q B]
time 2481ms: Process A switching out of CPU; will block on I/O until time 2516ms [Q B]
time 2485ms: Process B started using the CPU for 49ms burst [Q <empty>]
time 2516ms: Process A completed I/O; added to ready queue [Q A]
time 2534ms: Process B completed a CPU burst; 9 bursts to go [Q A]
time 2534ms: Process B switching out of CPU; will block on I/O until time 2578ms [Q A]
time 2538ms: Process A started using the CPU for 9ms burst [Q <empty>]
time 2547ms: Process A completed a CPU burst; 3 bursts to go [Q <empty>]
time 2547ms: Process A switching out of CPU; will block on I/O until time 2617ms [Q <empty>]
time 2578ms: Process B completed I/O; added to ready queue [Q B]
time 2580ms: Process B started using the CPU for 134ms burst [Q <empty>]
time 2617ms: Process A completed I/O; added to ready queue [Q A]
time 2714ms: Process B completed a CPU burst; 8 bursts to go [Q A]
time 2714ms: Process B switching out of CPU; will block on I/O until time 2748ms [Q A]
time 2718ms: Process A started using the CPU for 62ms burst [Q <empty>]
time 2748ms: Process B completed I/O; added to ready queue [Q B]
time 2780ms: Process A completed a CPU burst; 2 bursts to go [Q B]
time 2780ms: Process A switching out of CPU; will block on I/O until time 2859ms [Q B]
time 2784ms: Process B started using the CPU for 144ms burst [Q <empty>]
time 2859ms: Process A completed I/O; added to ready queue [Q A]
time 2928ms: Process B completed a CPU burst; 7 bursts to go [Q A]
time 2928ms: Process B switching out of CPU; will block on I/O until time 3009ms [Q A]
time 2932ms: Process A started using the CPU for 200ms burst [Q <empty>]
time 3009ms: Process B completed I/O; added to ready queue [Q B]
time 3132ms: Process A completed a CPU burst; 1 burst to go [Q B]
time 3132ms: Process A switching out of CPU; will block on I/O until time 3145ms [Q B]
time 3136ms: Process B started using the CPU for 183ms burst [Q <empty>]
time 3145ms: Process A completed I/O; added to ready queue [Q A]
time 3319ms: Process B completed a CPU burst; 6 bursts to go [Q A]
time 3319ms: Process B switching out of CPU; will block on I/O until time 3327ms [Q A]
time 3323ms: Process A started using the CPU for 197ms burst [Q <empty>]
time 3327ms: Process B completed I/O; added to ready queue [Q B]
time 3520ms: Process A terminated [Q B]
time 3524ms: Process B started using the CPU for 219ms burst [Q <empty>]
time 3743ms: Process B completed a CPU burst; 5 bursts to go [Q <empty>]
time 3743ms: Process B switching out of CPU; will block on I/O until time 3768ms [Q <empty>]
time 3768ms: Process B completed I/O; added to ready queue [Q B]
time 3770ms: Process B started using the CPU for 64ms burst [Q <empty>]
time 3834ms: Process B completed a CPU burst; 4 bursts to go [Q <empty>]
time 3834ms: Process B switching out of CPU; will block on I/O until time 3916ms [Q <empty>]
time 3916ms: Process B completed I/O; added to ready queue [Q B]
time 3918ms: Process B started using the CPU for 33ms burst [Q <empty>]
time 3951ms: Process B completed a CPU burst; 3 bursts to go [Q <empty>]
time 3951ms: Process B switching out of CPU; will block on I/O until time 4027ms [Q <empty>]
time 4027ms: Process B completed I/O; added to ready queue [Q B]
time 4029ms: Process B started using the CPU for 63ms burst [Q <empty>]
time 4092ms: Process B completed a CPU burst; 2 bursts to go [Q <empty>]
time 4092ms: Process B switching out of CPU; will block on I/O until time 4325ms [Q <empty>]
time 4325ms: Process B completed I/O; added to ready queue [Q B]
time 4327ms: Process B started using the CPU for 170ms burst [Q <empty>]
time 4497ms: Process B completed a CPU burst; 1 burst to go [Q <empty>]
time 4497ms: Process B switching out of CPU; will block on I/O until time 4556ms [Q <empty>]
time 4556ms: Process B completed I/O; added to ready queue [Q B]
time 4558ms: Process B started using the CPU for 212ms burst [Q <empty>]
time 4770ms: Process B terminated [Q <empty>]
time 4772ms: Simulator ended for FCFS [Q <empty>]

Process A [NEW] (arrival time 9 ms) 16 CPU bursts (tau 100ms)
Process B [NEW] (arrival time 18 ms) 21 CPU bursts (tau 100ms)
time 0ms: Simulator started for SJF [Q <empty>]
time 9ms: Process A (tau 100ms) arrived; added to ready queue [Q A]
time 11ms: Process A (tau 100ms) started using the CPU for 56ms burst [Q <empty>]
time 18ms: Process B (tau 100ms) arrived; added to ready queue [Q B]
time 67ms: Process A (tau 100ms) completed a CPU burst; 15 bursts to go [Q B]
time 67ms: Recalculated tau = 78ms for process A [Q B]
time 67ms: Process A switching out of CPU; will block on I/O until time 92ms [Q B]
time 71ms: Process B (tau 100ms) started using the CPU for 106ms burst [Q <empty>]
time 92ms: Process A (tau 78ms) completed I/O; added to ready queue [Q A]
time 177ms: Process B (tau 100ms) completed a CPU burst; 20 bursts to go [Q A]
time 177ms: Recalculated tau = 103ms for process B [Q A]
time 177ms: Process B switching out of CPU; will block on I/O until time 335ms [Q A]
time 181ms: Process A (tau 78ms) started using the CPU for 60ms burst [Q <empty>]
time 241ms: Process A (tau 78ms) completed a CPU burst; 14 bursts to go [Q <empty>]
time 241ms: Recalculated tau = 69ms for process A [Q <empty>]
time 241ms: Process A switching out of CPU; will block on I/O until time 396ms [Q <empty>]
time 335ms: Process B (tau 103ms) completed I/O; added to ready queue [Q B]
time 337ms: Process B (tau 103ms) started using the CPU for 198ms burst [Q <empty>]
time 396ms: Process A (tau 69ms) completed I/O; added to ready queue [Q A]
time 535ms: Process B (tau 103ms) completed a CPU burst; 19 bursts to go [Q A]
time 535ms: Recalculated tau = 151ms for process B [Q A]
time 535ms: Process B switching out of CPU; will block on I/O until time 650ms [Q A]
time 539ms: Process A (tau 69ms) started using the CPU for 39ms burst [Q <empty>]
time 578ms: Process A (tau 69ms) completed a CPU burst; 13 bursts to go [Q <empty>]
time 578ms: Recalculated tau = 54ms for process A [Q <empty>]
time 578ms: Process A switching out of CPU; will block on I/O until time 630ms [Q <empty>]
time 630ms: Process A (tau 54ms) completed I/O; added to ready queue [Q A]
time 632ms: Process A (tau 54ms) started using the CPU for 47ms burst [Q <empty>]
time 650ms: Process B (tau 151ms) completed I/O; added to ready queue [Q B]
time 679ms: Process A (tau 54ms) completed a CPU burst; 12 bursts to go [Q B]
time 679ms: Recalculated tau = 51ms for process A [Q B]
time 679ms: Process A switching out of CPU; will block on I/O until time 683ms [Q B]
time 683ms: Process B (tau 151ms) started using the CPU for 208ms burst [Q <empty>]
time 683ms: Process A (tau 51ms) completed I/O; added to ready queue [Q A]
time 891ms: Process B (tau 151ms) completed a CPU burst; 18 bursts to go [Q A]
time 891ms: Recalculated tau = 180ms for process B [Q A]
time 891ms: Process B switching out of CPU; will block on I/O until time 1055ms [Q A]
time 895ms: Process A (tau 51ms) started using the CPU for 137ms burst [Q <empty>]
time 1032ms: Process A (tau 51ms) completed a CPU burst; 11 bursts to go [Q <empty>]
time 1032ms: Recalculated tau = 94ms for process A [Q <empty>]
time 1032ms: Process A switching out of CPU; will block on I/O until time 1058ms [Q <empty>]
time 1055ms: Process B (tau 180ms) completed I/O; added to ready queue [Q B]
time 1057ms: Process B (tau 180ms) started using the CPU for 50ms burst [Q <empty>]
time 1058ms: Process A (tau 94ms) completed I/O; added to ready queue [Q A]
time 1107ms: Process B (tau 180ms) completed a CPU burst; 17 bursts to go [Q A]
time 1107ms: Recalculated tau = 115ms for process B [Q A]
time 1107ms: Process B switching out of CPU; will block on I/O until time 1155ms [Q A]
time 1111ms: Process A (tau 94ms) started using the CPU for 64ms burst [Q <empty>]
time 1155ms: Process B (tau 115ms) completed I/O; added to ready queue [Q B]
time 1175ms: Process A (tau 94ms) completed a CPU burst; 10 bursts to go [Q B]
time 1175ms: Recalculated tau = 79ms for process A [Q B]
time 1175ms: Process A switching out of CPU; will block on I/O until time 1192ms [Q B]
time 1179ms: Process B (tau 115ms) started using the CPU for 82ms burst [Q <empty>]
time 1192ms: Process A (tau 79ms) completed I/O; added to ready queue [Q A]
time 1261ms: Process B (tau 115ms) completed a CPU burst; 16 bursts to go [Q A]
time 1261ms: Recalculated tau = 99ms for process B [Q A]
time 1261ms: Process B switching out of CPU; will block on I/O until time 1279ms [Q A]
time 1265ms: Process A (tau 79ms) started using the CPU for 68ms burst [Q <empty>]
time 1279ms: Process B (tau 99ms) completed I/O; added to ready queue [Q B]
time 1333ms: Process A (tau 79ms) completed a CPU burst; 9 bursts to go [Q B]
time 1333ms: Recalculated tau = 74ms for process A [Q B]
time 1333ms: Process A switching out of CPU; will block on I/O until time 1399ms [Q B]
time 1337ms: Process B (tau 99ms) started using the CPU for 7ms burst [Q <empty>]
time 1344ms: Process B (tau 99ms) completed a CPU burst; 15 bursts to go [Q <empty>]
time 1344ms: Recalculated tau = 53ms for process B [Q <empty>]
time 1344ms: Process B switching out of CPU; will block on I/O until time 1376ms [Q <empty>]
time 1376ms: Process B (tau 53ms) completed I/O; added to ready queue [Q B]
time 1378ms: Process B (tau 53ms) started using the CPU for 52ms burst [Q <empty>]
time 1399ms: Process A (tau 74ms) completed I/O; added to ready queue [Q A]
time 1430ms: Process B (tau 53ms) completed a CPU burst; 14 bursts to go [Q A]
time 1430ms: Recalculated tau = 53ms for process B [Q A]
time 1430ms: Process B switching out of CPU; will block on I/O until time 1444ms [Q A]
time 1434ms: Process A (tau 74ms) started using the CPU for 113ms burst [Q <empty>]
time 1444ms: Process B (tau 53ms) completed I/O; added to ready queue [Q B]
time 1547ms: Process A (tau 74ms) completed a CPU burst; 8 bursts to go [Q B]
time 1547ms: Recalculated tau = 94ms for process A [Q B]
time 1547ms: Process A switching out of CPU; will block on I/O until time 1565ms [Q B]
time 1551ms: Process B (tau 53ms) started using the CPU for 228ms burst [Q <empty>]
time 1565ms: Process A (tau 94ms) completed I/O; added to ready queue [Q A]
time 1779ms: Process B (tau 53ms) completed a CPU burst; 13 bursts to go [Q A]
time 1779ms: Recalculated tau = 141ms for process B [Q A]
time 1779ms: Process B switching out of CPU; will block on I/O until time 1858ms [Q A]
time 1783ms: Process A (tau 94ms) started using the CPU for 11ms burst [Q <empty>]
time 1794ms: Process A (tau 94ms) completed a CPU burst; 7 bursts to go [Q <empty>]
time 1794ms: Recalculated tau = 53ms for process A [Q <empty>]
time 1794ms: Process A switching out of CPU; will block on I/O until time 1958ms [Q <empty>]
time 1858ms: Process B (tau 141ms) completed I/O; added to ready queue [Q B]
time 1860ms: Process B (tau 141ms) started using the CPU for 138ms burst [Q <empty>]
time 1958ms: Process A (tau 53ms) completed I/O; added to ready queue [Q A]
time 1998ms: Process B (tau 141ms) completed a CPU burst; 12 bursts to go [Q A]
time 1998ms: Recalculated tau = 140ms for process B [Q A]
time 1998ms: Process B switching out of CPU; will block on I/O until time 2082ms [Q A]
time 2002ms: Process A (tau 53ms) started using the CPU for 24ms burst [Q <empty>]
time 2026ms: Process A (tau 53ms) completed a CPU burst; 6 bursts to go [Q <empty>]
time 2026ms: Recalculated tau = 39ms for process A [Q <empty>]
time 2026ms: Process A switching out of CPU; will block on I/O until time 2145ms [Q <empty>]
time 2082ms: Process B (tau 140ms) completed I/O; added to ready queue [Q B]
time 2084ms: Process B (tau 140ms) started using the CPU for 67ms burst [Q <empty>]
time 2145ms: Process A (tau 39ms) completed I/O; added to ready queue [Q A]
time 2151ms: Process B (tau 140ms) completed a CPU burst; 11 bursts to go [Q A]
time 2151ms: Recalculated tau = 104ms for process B [Q A]
time 2151ms: Process B switching out of CPU; will block on I/O until time 2160ms [Q A]
time 2155ms: Process A (tau 39ms) started using the CPU for 76ms burst [Q <empty>]
time 2160ms: Process B (tau 104ms) completed I/O; added to ready queue [Q B]
time 2231ms: Process A (tau 39ms) completed a CPU burst; 5 bursts to go [Q B]
time 2231ms: Recalculated tau = 58ms for process A [Q B]
time 2231ms: Process A switching out of CPU; will block on I/O until time 2261ms [Q B]
time 2235ms: Process B (tau 104ms) started using the CPU for 120ms burst [Q <empty>]
time 2261ms: Process A (tau 58ms) completed I/O; added to ready queue [Q A]
time 2355ms: Process B (tau 104ms) completed a CPU burst; 10 bursts to go [Q A]
time 2355ms: Recalculated tau = 112ms for process B [Q A]
time 2355ms: Process B switching out of CPU; will block on I/O until time 2370ms [Q A]
time 2359ms: Process A (tau 58ms) started using the CPU for 122ms burst [Q <empty>]
time 2370ms: Process B (tau 112ms) completed I/O; added to ready queue [Q B]
time 2481ms: Process A (tau 58ms) completed a CPU burst; 4 bursts to go [Q B]
time 2481ms: Recalculated tau = 90ms for process A [Q B]
time 2481ms: Process A switching out of CPU; will block on I/O until time 2516ms [Q B]
time 2485ms: Process B (tau 112ms) started using the CPU for 49ms burst [Q <empty>]
time 2516ms: Process A (tau 90ms) completed I/O; added to ready queue [Q A]
time 2534ms: Process B (tau 112ms) completed a CPU burst; 9 bursts to go [Q A]
time 2534ms: Recalculated tau = 81ms for process B [Q A]
time 2534ms: Process B switching out of CPU; will block on I/O until time 2578ms [Q A]
time 2538ms: Process A (tau 90ms) started using the CPU for 9ms burst [Q <empty>]
time 2547ms: Process A (tau 90ms) completed a CPU burst; 3 bursts to go [Q <empty>]
time 2547ms: Recalculated tau = 50ms for process A [Q <empty>]
time 2547ms: Process A switching out of CPU; will block on I/O until time 2617ms [Q <empty>]
time 2578ms: Process B (tau 81ms) completed I/O; added to ready queue [Q B]
time 2580ms: Process B (tau 81ms) started using the CPU for 134ms burst [Q <empty>]
time 2617ms: Process A (tau 50ms) completed I/O; added to ready queue [Q A]
time 2714ms: Process B (tau 81ms) completed a CPU burst; 8 bursts to go [Q A]
time 2714ms: Recalculated tau = 108ms for process B [Q A]
time 2714ms: Process B switching out of CPU; will block on I/O until time 2748ms [Q A]
time 2718ms: Process A (tau 50ms) started using the CPU for 62ms burst [Q <empty>]
time 2748ms: Process B (tau 108ms) completed I/O; added to ready queue [Q B]
time 2780ms: Process A (tau 50ms) completed a CPU burst; 2 bursts to go [Q B]
time 2780ms: Recalculated tau = 56ms for process A [Q B]
time 2780ms: Process A switching out of CPU; will block on I/O until time 2859ms [Q B]
time 2784ms: Process B (tau 108ms) started using the CPU for 144ms burst [Q <empty>]
time 2859ms: Process A (tau 56ms) completed I/O; added to ready queue [Q A]
time 2928ms: Process B (tau 108ms) completed a CPU burst; 7 bursts to go [Q A]
time 2928ms: Recalculated tau = 126ms for process B [Q A]
time 2928ms: Process B switching out of CPU; will block on I/O until time 3009ms [Q A]
time 2932ms: Process A (tau 56ms) started using the CPU for 200ms burst [Q <empty>]
time 3009ms: Process B (tau 126ms) completed I/O; added to ready queue [Q B]
time 3132ms: Process A (tau 56ms) completed a CPU burst; 1 burst to go [Q B]
time 3132ms: Recalculated tau = 128ms for process A [Q B]
time 3132ms: Process A switching out of CPU; will block on I/O until time 3145ms [Q B]
time 3136ms: Process B (tau 126ms) started using the CPU for 183ms burst [Q <empty>]
time 3145ms: Process A (tau 128ms) completed I/O; added to ready queue [Q A]
time 3319ms: Process B (tau 126ms) completed a CPU burst; 6 bursts to go [Q A]
time 3319ms: Recalculated tau = 155ms for process B [Q A]
time 3319ms: Process B switching out of CPU; will block on I/O until time 3327ms [Q A]
time 3323ms: Process A (tau 128ms) started using the CPU for 197ms burst [Q <empty>]
time 3327ms: Process B (tau 155ms) completed I/O; added to ready queue [Q B]
time 3520ms: Process A terminated [Q B]
time 3524ms: Process B (tau 155ms) started using the CPU for 219ms burst [Q <empty>]
time 3743ms: Process B (tau 155ms) completed a CPU burst; 5 bursts to go [Q <empty>]
time 3743ms: Recalculated tau = 187ms for process B [Q <empty>]
time 3743ms: Process B switching out of CPU; will block on I/O until time 3768ms [Q <empty>]
time 3768ms: Process B (tau 187ms) completed I/O; added to ready queue [Q B]
time 3770ms: Process B (tau 187ms) started using the CPU for 64ms burst [Q <empty>]
time 3834ms: Process B (tau 187ms) completed a CPU burst; 4 bursts to go [Q <empty>]
time 3834ms: Recalculated tau = 126ms for process B [Q <empty>]
time 3834ms: Process B switching out of CPU; will block on I/O until time 3916ms [Q <empty>]
time 3916ms: Process B (tau 126ms) completed I/O; added to ready queue [Q B]
time 3918ms: Process B (tau 126ms) started using the CPU for 33ms burst [Q <empty>]
time 3951ms: Process B (tau 126ms) completed a CPU burst; 3 bursts to go [Q <empty>]
time 3951ms: Recalculated tau = 80ms for process B [Q <empty>]
time 3951ms: Process B switching out of CPU; will block on I/O until time 4027ms [Q <empty>]
time 4027ms: Process B (tau 80ms) completed I/O; added to ready queue [Q B]
time 4029ms: Process B (tau 80ms) started using the CPU for 63ms burst [Q <empty>]
time 4092ms: Process B (tau 80ms) completed a CPU burst; 2 bursts to go [Q <empty>]
time 4092ms: Recalculated tau = 72ms for process B [Q <empty>]
time 4092ms: Process B switching out of CPU; will block on I/O until time 4325ms [Q <empty>]
time 4325ms: Process B (tau 72ms) completed I/O; added to ready queue [Q B]
time 4327ms: Process B (tau 72ms) started using the CPU for 170ms burst [Q <empty>]
time 4497ms: Process B (tau 72ms) completed a CPU burst; 1 burst to go [Q <empty>]
time 4497ms: Recalculated tau = 121ms for process B [Q <empty>]
time 4497ms: Process B switching out of CPU; will block on I/O until time 4556ms [Q <empty>]
time 4556ms: Process B (tau 121ms) completed I/O; added to ready queue [Q B]
time 4558ms: Process B (tau 121ms) started using the CPU for 212ms burst [Q <empty>]
time 4770ms: Process B terminated [Q <empty>]
time 4772ms: Simulator ended for SJF [Q <empty>]

Process A [NEW] (arrival time 9 ms) 16 CPU bursts (tau 100ms)
Process B [NEW] (arrival time 18 ms) 21 CPU bursts (tau 100ms)
time 0ms: Simulator started for SRT [Q <empty>]
time 9ms: Process A (tau 100ms) arrived; added to ready queue [Q A]
time 11ms: Process A (tau 100ms) started using the CPU with 56ms burst remaining [Q <empty>]
time 18ms: Process B (tau 100ms) arrived; added to ready queue [Q B]
time 67ms: Process A (tau 100ms) completed a CPU burst; 15 bursts to go [Q B]
time 67ms: Recalculated tau = 78ms for process A [Q B]
time 67ms: Process A switching out of CPU; will block on I/O until time 92ms [Q B]
time 71ms: Process B (tau 100ms) started using the CPU with 106ms burst remaining [Q <empty>]
time 92ms: Process A (tau 78ms) completed I/O; preempting B [Q A]
time 96ms: Process A (tau 78ms) started using the CPU with 60ms burst remaining [Q B]
time 156ms: Process A (tau 78ms) completed a CPU burst; 14 bursts to go [Q B]
time 156ms: Recalculated tau = 69ms for process A [Q B]
time 156ms: Process A switching out of CPU; will block on I/O until time 311ms [Q B]
time 160ms: Process B (tau 100ms) started using the CPU with 85ms burst remaining [Q <empty>]
time 245ms: Process B (tau 100ms) completed a CPU burst; 20 bursts to go [Q <empty>]
time 245ms: Recalculated tau = 103ms for process B [Q <empty>]
time 245ms: Process B switching out of CPU; will block on I/O until time 403ms [Q <empty>]
time 311ms: Process A (tau 69ms) completed I/O; added to ready queue [Q A]
time 313ms: Process A (tau 69ms) started using the CPU with 39ms burst remaining [Q <empty>]
time 352ms: Process A (tau 69ms) completed a CPU burst; 13 bursts to go [Q <empty>]
time 352ms: Recalculated tau = 54ms for process A [Q <empty>]
time 352ms: Process A switching out of CPU; will block on I/O until time 404ms [Q <empty>]
time 403ms: Process B (tau 103ms) completed I/O; added to ready queue [Q B]
time 404ms: Process A (tau 54ms) completed I/O; added to ready queue [Q A]
time 405ms: Process B (tau 103ms) started using the CPU with 198ms burst remaining [Q A]
time 405ms: Process A (tau 54ms) will preempt B [Q A]
time 409ms: Process A (tau 54ms) started using the CPU with 47ms burst remaining [Q B]
time 456ms: Process A (tau 54ms) completed a CPU burst; 12 bursts to go [Q B]
time 456ms: Recalculated tau = 51ms for process A [Q B]
time 456ms: Process A switching out of CPU; will block on I/O until time 460ms [Q B]
time 460ms: Process B (tau 103ms) started using the CPU with 198ms burst remaining [Q <empty>]
time 460ms: Process A (tau 51ms) completed I/O; preempting B [Q A]
time 464ms: Process A (tau 51ms) started using the CPU with 137ms burst remaining [Q B]
time 601ms: Process A (tau 51ms) completed a CPU burst; 11 bursts to go [Q B]
time 601ms: Recalculated tau = 94ms for process A [Q B]
time 601ms: Process A switching out of CPU; will block on I/O until time 627ms [Q B]
time 605ms: Process B (tau 103ms) started using the CPU with 198ms burst remaining [Q <empty>]
time 627ms: Process A (tau 94ms) completed I/O; added to ready queue [Q A]
time 803ms: Process B (tau 103ms) completed a CPU burst; 19 bursts to go [Q A]
time 803ms: Recalculated tau = 151ms for process B [Q A]
time 803ms: Process B switching out of CPU; will block on I/O until time 918ms [Q A]
time 807ms: Process A (tau 94ms) started using the CPU with 64ms burst remaining [Q <empty>]
time 871ms: Process A (tau 94ms) completed a CPU burst; 10 bursts to go [Q <empty>]
time 871ms: Recalculated tau = 79ms for process A [Q <empty>]
time 871ms: Process A switching out of CPU; will block on I/O until time 888ms [Q <empty>]
time 888ms: Process A (tau 79ms) completed I/O; added to ready queue [Q A]
time 890ms: Process A (tau 79ms) started using the CPU with 68ms burst remaining [Q <empty>]
time 918ms: Process B (tau 151ms) completed I/O; added to ready queue [Q B]
time 958ms: Process A (tau 79ms) completed a CPU burst; 9 bursts to go [Q B]
time 958ms: Recalculated tau = 74ms for process A [Q B]
time 958ms: Process A switching out of CPU; will block on I/O until time 1024ms [Q B]
time 962ms: Process B (tau 151ms) started using the CPU with 208ms burst remaining [Q <empty>]
time 1024ms: Process A (tau 74ms) completed I/O; preempting B [Q A]
time 1028ms: Process A (tau 74ms) started using the CPU with 113ms burst remaining [Q B]
time 1141ms: Process A (tau 74ms) completed a CPU burst; 8 bursts to go [Q B]
time 1141ms: Recalculated tau = 94ms for process A [Q B]
time 1141ms: Process A switching out of CPU; will block on I/O until time 1159ms [Q B]
time 1145ms: Process B (tau 151ms) started using the CPU with 146ms burst remaining [Q <empty>]
time 1159ms: Process A (tau 94ms) completed I/O; added to ready queue [Q A]
time 1291ms: Process B (tau 151ms) completed a CPU burst; 18 bursts to go [Q A]
time 1291ms: Recalculated tau = 180ms for process B [Q A]
time 1291ms: Process B switching out of CPU; will block on I/O until time 1455ms [Q A]
time 1295ms: Process A (tau 94ms) started using the CPU with 11ms burst remaining [Q <empty>]
time 1306ms: Process A (tau 94ms) completed a CPU burst; 7 bursts to go [Q <empty>]
time 1306ms: Recalculated tau = 53ms for process A [Q <empty>]
time 1306ms: Process A switching out of CPU; will block on I/O until time 1470ms [Q <empty>]
time 1455ms: Process B (tau 180ms) completed I/O; added to ready queue [Q B]
time 1457ms: Process B (tau 180ms) started using the CPU with 50ms burst remaining [Q <empty>]
time 1470ms: Process A (tau 53ms) completed I/O; preempting B [Q A]
time 1474ms: Process A (tau 53ms) started using the CPU with 24ms burst remaining [Q B]
time 1498ms: Process A (tau 53ms) completed a CPU burst; 6 bursts to go [Q B]
time 1498ms: Recalculated tau = 39ms for process A [Q B]
time 1498ms: Process A switching out of CPU; will block on I/O until time 1617ms [Q B]
time 1502ms: Process B (tau 180ms) started using the CPU with 37ms burst remaining [Q <empty>]
time 1539ms: Process B (tau 180ms) completed a CPU burst; 17 bursts to go [Q <empty>]
time 1539ms: Recalculated tau = 115ms for process B [Q <empty>]
time 1539ms: Process B switching out of CPU; will block on I/O until time 1587ms [Q <empty>]
time 1587ms: Process B (tau 115ms) completed I/O; added to ready queue [Q B]
time 1589ms: Process B (tau 115ms) started using the CPU with 82ms burst remaining [Q <empty>]
time 1617ms: Process A (tau 39ms) completed I/O; preempting B [Q A]
time 1621ms: Process A (tau 39ms) started using the CPU with 76ms burst remaining [Q B]
time 1697ms: Process A (tau 39ms) completed a CPU burst; 5 bursts to go [Q B]
time 1697ms: Recalculated tau = 58ms for process A [Q B]
time 1697ms: Process A switching out of CPU; will block on I/O until time 1727ms [Q B]
time 1701ms: Process B (tau 115ms) started using the CPU with 54ms burst remaining [Q <empty>]
time 1727ms: Process A (tau 58ms) completed I/O; preempting B [Q A]
time 1731ms: Process A (tau 58ms) started using the CPU with 122ms burst remaining [Q B]
time 1853ms: Process A (tau 58ms) completed a CPU burst; 4 bursts to go [Q B]
time 1853ms: Recalculated tau = 90ms for process A [Q B]
time 1853ms: Process A switching out of CPU; will block on I/O until time 1888ms [Q B]
time 1857ms: Process B (tau 115ms) started using the CPU with 28ms burst remaining [Q <empty>]
time 1885ms: Process B (tau 115ms) completed a CPU burst; 16 bursts to go [Q <empty>]
time 1885ms: Recalculated tau = 99ms for process B [Q <empty>]
time 1885ms: Process B switching out of CPU; will block on I/O until time 1903ms [Q <empty>]
time 1888ms: Process A (tau 90ms) completed I/O; added to ready queue [Q A]
time 1890ms: Process A (tau 90ms) started using the CPU with 9ms burst remaining [Q <empty>]
time 1899ms: Process A (tau 90ms) completed a CPU burst; 3 bursts to go [Q <empty>]
time 1899ms: Recalculated tau = 50ms for process A [Q <empty>]
time 1899ms: Process A switching out of CPU; will block on I/O until time 1969ms [Q <empty>]
time 1903ms: Process B (tau 99ms) completed I/O; added to ready queue [Q B]
time 1905ms: Process B (tau 99ms) started using the CPU with 7ms burst remaining [Q <empty>]
time 1912ms: Process B (tau 99ms) completed a CPU burst; 15 bursts to go [Q <empty>]
time 1912ms: Recalculated tau = 53ms for process B [Q <empty>]
time 1912ms: Process B switching out of CPU; will block on I/O until time 1944ms [Q <empty>]
time 1944ms: Process B (tau 53ms) completed I/O; added to ready queue [Q B]
time 1946ms: Process B (tau 53ms) started using the CPU with 52ms burst remaining [Q <empty>]
time 1969ms: Process A (tau 50ms) completed I/O; added to ready queue [Q A]
time 1998ms: Process B (tau 53ms) completed a CPU burst; 14 bursts to go [Q A]
time 1998ms: Recalculated tau = 53ms for process B [Q A]
time 1998ms: Process B switching out of CPU; will block on I/O until time 2012ms [Q A]
time 2002ms: Process A (tau 50ms) started using the CPU with 62ms burst remaining [Q <empty>]
time 2012ms: Process B (tau 53ms) completed I/O; added to ready queue [Q B]
time 2064ms: Process A (tau 50ms) completed a CPU burst; 2 bursts to go [Q B]
time 2064ms: Recalculated tau = 56ms for process A [Q B]
time 2064ms: Process A switching out of CPU; will block on I/O until time 2143ms [Q B]
time 2068ms: Process B (tau 53ms) started using the CPU with 228ms burst remaining [Q <empty>]
time 2143ms: Process A (tau 56ms) completed I/O; added to ready queue [Q A]
time 2296ms: Process B (tau 53ms) completed a CPU burst; 13 bursts to go [Q A]
time 2296ms: Recalculated tau = 141ms for process B [Q A]
time 2296ms: Process B switching out of CPU; will block on I/O until time 2375ms [Q A]
time 2300ms: Process A (tau 56ms) started using the CPU with 200ms burst remaining [Q <empty>]
time 2375ms: Process B (tau 141ms) completed I/O; added to ready queue [Q B]
time 2500ms: Process A (tau 56ms) completed a CPU burst; 1 burst to go [Q B]
time 2500ms: Recalculated tau = 128ms for process A [Q B]
time 2500ms: Process A switching out of CPU; will block on I/O until time 2513ms [Q B]
time 2504ms: Process B (tau 141ms) started using the CPU with 138ms burst remaining [Q <empty>]
time 2513ms: Process A (tau 128ms) completed I/O; preempting B [Q A]
time 2517ms: Process A (tau 128ms) started using the CPU with 197ms burst remaining [Q B]
time 2714ms: Process A terminated [Q B]
time 2718ms: Process B (tau 141ms) started using the CPU with 129ms burst remaining [Q <empty>]
time 2847ms: Process B (tau 141ms) completed a CPU burst; 12 bursts to go [Q <empty>]
time 2847ms: Recalculated tau = 140ms for process B [Q <empty>]
time 2847ms: Process B switching out of CPU; will block on I/O until time 2931ms [Q <empty>]
time 2931ms: Process B (tau 140ms) completed I/O; added to ready queue [Q B]
time 2933ms: Process B (tau 140ms) started using the CPU with 67ms burst remaining [Q <empty>]
time 3000ms: Process B (tau 140ms) completed a CPU burst; 11 bursts to go [Q <empty>]
time 3000ms: Recalculated tau = 104ms for process B [Q <empty>]
time 3000ms: Process B switching out of CPU; will block on I/O until time 3009ms [Q <empty>]
time 3009ms: Process B (tau 104ms) completed I/O; added to ready queue [Q B]
time 3011ms: Process B (tau 104ms) started using the CPU with 120ms burst remaining [Q <empty>]
time 3131ms: Process B (tau 104ms) completed a CPU burst; 10 bursts to go [Q <empty>]
time 3131ms: Recalculated tau = 112ms for process B [Q <empty>]
time 3131ms: Process B switching out of CPU; will block on I/O until time 3146ms [Q <empty>]
time 3146ms: Process B (tau 112ms) completed I/O; added to ready queue [Q B]
time 3148ms: Process B (tau 112ms) started using the CPU with 49ms burst remaining [Q <empty>]
time 3197ms: Process B (tau 112ms) completed a CPU burst; 9 bursts to go [Q <empty>]
time 3197ms: Recalculated tau = 81ms for process B [Q <empty>]
time 3197ms: Process B switching out of CPU; will block on I/O until time 3241ms [Q <empty>]
time 3241ms: Process B (tau 81ms) completed I/O; added to ready queue [Q B]
time 3243ms: Process B (tau 81ms) started using the CPU with 134ms burst remaining [Q <empty>]
time 3377ms: Process B (tau 81ms) completed a CPU burst; 8 bursts to go [Q <empty>]
time 3377ms: Recalculated tau = 108ms for process B [Q <empty>]
time 3377ms: Process B switching out of CPU; will block on I/O until time 3411ms [Q <empty>]
time 3411ms: Process B (tau 108ms) completed I/O; added to ready queue [Q B]
time 3413ms: Process B (tau 108ms) started using the CPU with 144ms burst remaining [Q <empty>]
time 3557ms: Process B (tau 108ms) completed a CPU burst; 7 bursts to go [Q <empty>]
time 3557ms: Recalculated tau = 126ms for process B [Q <empty>]
time 3557ms: Process B switching out of CPU; will block on I/O until time 3638ms [Q <empty>]
time 3638ms: Process B (tau 126ms) completed I/O; added to ready queue [Q B]
time 3640ms: Process B (tau 126ms) started using the CPU with 183ms burst remaining [Q <empty>]
time 3823ms: Process B (tau 126ms) completed a CPU burst; 6 bursts to go [Q <empty>]
time 3823ms: Recalculated tau = 155ms for process B [Q <empty>]
time 3823ms: Process B switching out of CPU; will block on I/O until time 3831ms [Q <empty>]
time 3831ms: Process B (tau 155ms) completed I/O; added to ready queue [Q B]
time 3833ms: Process B (tau 155ms) started using the CPU with 219ms burst remaining [Q <empty>]
time 4052ms: Process B (tau 155ms) completed a CPU burst; 5 bursts to go [Q <empty>]
time 4052ms: Recalculated tau = 187ms for process B [Q <empty>]
time 4052ms: Process B switching out of CPU; will block on I/O until time 4077ms [Q <empty>]
time 4077ms: Process B (tau 187ms) completed I/O; added to ready queue [Q B]
time 4079ms: Process B (tau 187ms) started using the CPU with 64ms burst remaining [Q <empty>]
time 4143ms: Process B (tau 187ms) completed a CPU burst; 4 bursts to go [Q <empty>]
time 4143ms: Recalculated tau = 126ms for process B [Q <empty>]
time 4143ms: Process B switching out of CPU; will block on I/O until time 4225ms [Q <empty>]
time 4225ms: Process B (tau 126ms) completed I/O; added to ready queue [Q B]
time 4227ms: Process B (tau 126ms) started using the CPU with 33ms burst remaining [Q <empty>]
time 4260ms: Process B (tau 126ms) completed a CPU burst; 3 bursts to go [Q <empty>]
time 4260ms: Recalculated tau = 80ms for process B [Q <empty>]
time 4260ms: Process B switching out of CPU; will block on I/O until time 4336ms [Q <empty>]
time 4336ms: Process B (tau 80ms) completed I/O; added to ready queue [Q B]
time 4338ms: Process B (tau 80ms) started using the CPU with 63ms burst remaining [Q <empty>]
time 4401ms: Process B (tau 80ms) completed a CPU burst; 2 bursts to go [Q <empty>]
time 4401ms: Recalculated tau = 72ms for process B [Q <empty>]
time 4401ms: Process B switching out of CPU; will block on I/O until time 4634ms [Q <empty>]
time 4634ms: Process B (tau 72ms) completed I/O; added to ready queue [Q B]
time 4636ms: Process B (tau 72ms) started using the CPU with 170ms burst remaining [Q <empty>]
time 4806ms: Process B (tau 72ms) completed a CPU burst; 1 burst to go [Q <empty>]
time 4806ms: Recalculated tau = 121ms for process B [Q <empty>]
time 4806ms: Process B switching out of CPU; will block on I/O until time 4865ms [Q <empty>]
time 4865ms: Process B (tau 121ms) completed I/O; added to ready queue [Q B]
time 4867ms: Process B (tau 121ms) started using the CPU with 212ms burst remaining [Q <empty>]
time 5079ms: Process B terminated [Q <empty>]
time 5081ms: Simulator ended for SRT [Q <empty>]

Process A [NEW] (arrival time 9 ms) 16 CPU bursts
Process B [NEW] (arrival time 18 ms) 21 CPU bursts
time 0ms: Simulator started for RR [Q <empty>]
time 9ms: Process A arrived; added to ready queue [Q A]
time 11ms: Process A started using the CPU for 56ms burst [Q <empty>]
time 18ms: Process B arrived; added to ready queue [Q B]
time 67ms: Process A completed a CPU burst; 15 bursts to go [Q B]
time 67ms: Process A switching out of CPU; will block on I/O until time 92ms [Q B]
time 71ms: Process B started using the CPU for 106ms burst [Q <empty>]
time 92ms: Process A completed I/O; added to ready queue [Q A]
time 177ms: Process B completed a CPU burst; 20 bursts to go [Q A]
time 177ms: Process B switching out of CPU; will block on I/O until time 335ms [Q A]
time 181ms: Process A started using the CPU for 60ms burst [Q <empty>]
time 241ms: Process A completed a CPU burst; 14 bursts to go [Q <empty>]
time 241ms: Process A switching out of CPU; will block on I/O until time 396ms [Q <empty>]
time 335ms: Process B completed I/O; added to ready queue [Q B]
time 337ms: Process B started using the CPU for 198ms burst [Q <empty>]
time 396ms: Process A completed I/O; added to ready queue [Q A]
time 465ms: Time slice expired; process B preempted with 70ms to go [Q A]
time 469ms: Process A started using the CPU for 39ms burst [Q B]
time 508ms: Process A completed a CPU burst; 13 bursts to go [Q B]
time 508ms: Process A switching out of CPU; will block on I/O until time 560ms [Q B]
time 512ms: Process B started using the CPU with 70ms burst remaining [Q <empty>]
time 560ms: Process A completed I/O; added to ready queue [Q A]
time 582ms: Process B completed a CPU burst; 19 bursts to go [Q A]
time 582ms: Process B switching out of CPU; will block on I/O until time 697ms [Q A]
time 586ms: Process A started using the CPU for 47ms burst [Q <empty>]
time 633ms: Process A completed a CPU burst; 12 bursts to go [Q <empty>]
time 633ms: Process A switching out of CPU; will block on I/O until time 637ms [Q <empty>]
time 637ms: Process A completed I/O; added to ready queue [Q A]
time 639ms: Process A started using the CPU for 137ms burst [Q <empty>]
time 697ms: Process B completed I/O; added to ready queue [Q B]
time 767ms: Time slice expired; process A preempted with 9ms to go [Q B]
time 771ms: Process B started using the CPU for 208ms burst [Q A]
time 899ms: Time slice expired; process B preempted with 80ms to go [Q A]
time 903ms: Process A started using the CPU with 9ms burst remaining [Q B]
time 912ms: Process A completed a CPU burst; 11 bursts to go [Q B]
time 912ms: Process A switching out of CPU; will block on I/O until time 938ms [Q B]
time 916ms: Process B started using the CPU with 80ms burst remaining [Q <empty>]
time 938ms: Process A completed I/O; added to ready queue [Q A]
time 996ms: Process B completed a CPU burst; 18 bursts to go [Q A]
time 996ms: Process B switching out of CPU; will block on I/O until time 1160ms [Q A]
time 1000ms: Process A started using the CPU for 64ms burst [Q <empty>]
time 1064ms: Process A completed a CPU burst; 10 bursts to go [Q <empty>]
time 1064ms: Process A switching out of CPU; will block on I/O until time 1081ms [Q <empty>]
time 1081ms: Process A completed I/O; added to ready queue [Q A]
time 1083ms: Process A started using the CPU for 68ms burst [Q <empty>]
time 1151ms: Process A completed a CPU burst; 9 bursts to go [Q <empty>]
time 1151ms: Process A switching out of CPU; will block on I/O until time 1217ms [Q <empty>]
time 1160ms: Process B completed I/O; added to ready queue [Q B]
time 1162ms: Process B started using the CPU for 50ms burst [Q <empty>]
time 1212ms: Process B completed a CPU burst; 17 bursts to go [Q <empty>]
time 1212ms: Process B switching out of CPU; will block on I/O until time 1260ms [Q <empty>]
time 1217ms: Process A completed I/O; added to ready queue [Q A]
time 1219ms: Process A started using the CPU for 113ms burst [Q <empty>]
time 1260ms: Process B completed I/O; added to ready queue [Q B]
time 1332ms: Process A completed a CPU burst; 8 bursts to go [Q B]
time 1332ms: Process A switching out of CPU; will block on I/O until time 1350ms [Q B]
time 1336ms: Process B started using the CPU for 82ms burst [Q <empty>]
time 1350ms: Process A completed I/O; added to ready queue [Q A]
time 1418ms: Process B completed a CPU burst; 16 bursts to go [Q A]
time 1418ms: Process B switching out of CPU; will block on I/O until time 1436ms [Q A]
time 1422ms: Process A started using the CPU for 11ms burst [Q <empty>]
time 1433ms: Process A completed a CPU burst; 7 bursts to go [Q <empty>]
time 1433ms: Process A switching out of CPU; will block on I/O until time 1597ms [Q <empty>]
time 1436ms: Process B completed I/O; added to ready queue [Q B]
time 1438ms: Process B started using the CPU for 7ms burst [Q <empty>]
time 1445ms: Process B completed a CPU burst; 15 bursts to go [Q <empty>]
time 1445ms: Process B switching out of CPU; will block on I/O until time 1477ms [Q <empty>]
time 1477ms: Process B completed I/O; added to ready queue [Q B]
time 1479ms: Process B started using the CPU for 52ms burst [Q <empty>]
time 1531ms: Process B completed a CPU burst; 14 bursts to go [Q <empty>]
time 1531ms: Process B switching out of CPU; will block on I/O until time 1545ms [Q <empty>]
time 1545ms: Process B completed I/O; added to ready queue [Q B]
time 1547ms: Process B started using the CPU for 228ms burst [Q <empty>]
time 1597ms: Process A completed I/O; added to ready queue [Q A]
time 1675ms: Time slice expired; process B preempted with 100ms to go [Q A]
time 1679ms: Process A started using the CPU for 24ms burst [Q B]
time 1703ms: Process A completed a CPU burst; 6 bursts to go [Q B]
time 1703ms: Process A switching out of CPU; will block on I/O until time 1822ms [Q B]
time 1707ms: Process B started using the CPU with 100ms burst remaining [Q <empty>]
time 1807ms: Process B completed a CPU burst; 13 bursts to go [Q <empty>]
time 1807ms: Process B switching out of CPU; will block on I/O until time 1886ms [Q <empty>]
time 1822ms: Process A completed I/O; added to ready queue [Q A]
time 1824ms: Process A started using the CPU for 76ms burst [Q <empty>]
time 1886ms: Process B completed I/O; added to ready queue [Q B]
time 1900ms: Process A completed a CPU burst; 5 bursts to go [Q B]
time 1900ms: Process A switching out of CPU; will block on I/O until time 1930ms [Q B]
time 1904ms: Process B started using the CPU for 138ms burst [Q <empty>]
time 1930ms: Process A completed I/O; added to ready queue [Q A]
time 2032ms: Time slice expired; process B preempted with 10ms to go [Q A]
time 2036ms: Process A started using the CPU for 122ms burst [Q B]
time 2158ms: Process A completed a CPU burst; 4 bursts to go [Q B]
time 2158ms: Process A switching out of CPU; will block on I/O until time 2193ms [Q B]
time 2162ms: Process B started using the CPU with 10ms burst remaining [Q <empty>]
time 2172ms: Process B completed a CPU burst; 12 bursts to go [Q <empty>]
time 2172ms: Process B switching out of CPU; will block on I/O until time 2256ms [Q <empty>]
time 2193ms: Process A completed I/O; added to ready queue [Q A]
time 2195ms: Process A started using the CPU for 9ms burst [Q <empty>]
time 2204ms: Process A completed a CPU burst; 3 bursts to go [Q <empty>]
time 2204ms: Process A switching out of CPU; will block on I/O until time 2274ms [Q <empty>]
time 2256ms: Process B completed I/O; added to ready queue [Q B]
time 2258ms: Process B started using the CPU for 67ms burst [Q <empty>]
time 2274ms: Process A completed I/O; added to ready queue [Q A]
time 2325ms: Process B completed a CPU burst; 11 bursts to go [Q A]
time 2325ms: Process B switching out of CPU; will block on I/O until time 2334ms [Q A]
time 2329ms: Process A started using the CPU for 62ms burst [Q <empty>]
time 2334ms: Process B completed I/O; added to ready queue [Q B]
time 2391ms: Process A completed a CPU burst; 2 bursts to go [Q B]
time 2391ms: Process A switching out of CPU; will block on I/O until time 2470ms [Q B]
time 2395ms: Process B started using the CPU for 120ms burst [Q <empty>]
time 2470ms: Process A completed I/O; added to ready queue [Q A]
time 2515ms: Process B completed a CPU burst; 10 bursts to go [Q A]
time 2515ms: Process B switching out of CPU; will block on I/O until time 2530ms [Q A]
time 2519ms: Process A started using the CPU for 200ms burst [Q <empty>]
time 2530ms: Process B completed I/O; added to ready queue [Q B]
time 2647ms: Time slice expired; process A preempted with 72ms to go [Q B]
time 2651ms: Process B started using the CPU for 49ms burst [Q A]
time 2700ms: Process B completed a CPU burst; 9 bursts to go [Q A]
time 2700ms: Process B switching out of CPU; will block on I/O until time 2744ms [Q A]
time 2704ms: Process A started using the CPU with 72ms burst remaining [Q <empty>]
time 2744ms: Process B completed I/O; added to ready queue [Q B]
time 2776ms: Process A completed a CPU burst; 1 burst to go [Q B]
time 2776ms: Process A switching out of CPU; will block on I/O until time 2789ms [Q B]
time 2780ms: Process B started using the CPU for 134ms burst [Q <empty>]
time 2789ms: Process A completed I/O; added to ready queue [Q A]
time 2908ms: Time slice expired; process B preempted with 6ms to go [Q A]
time 2912ms: Process A started using the CPU for 197ms burst [Q B]
time 3040ms: Time slice expired; process A preempted with 69ms to go [Q B]
time 3044ms: Process B started using the CPU with 6ms burst remaining [Q A]
time 3050ms: Process B completed a CPU burst; 8 bursts to go [Q A]
time 3050ms: Process B switching out of CPU; will block on I/O until time 3084ms [Q A]
time 3054ms: Process A started using the CPU with 69ms burst remaining [Q <empty>]
time 3084ms: Process B completed I/O; added to ready queue [Q B]
time 3123ms: Process A terminated [Q B]
time 3127ms: Process B started using the CPU for 144ms burst [Q <empty>]
time 3255ms: Time slice expired; no preemption because ready queue is empty [Q <empty>]
time 3271ms: Process B completed a CPU burst; 7 bursts to go [Q <empty>]
time 3271ms: Process B switching out of CPU; will block on I/O until time 3352ms [Q <empty>]
time 3352ms: Process B completed I/O; added to ready queue [Q B]
time 3354ms: Process B started using the CPU for 183ms burst [Q <empty>]
time 3482ms: Time slice expired; no preemption because ready queue is empty [Q <empty>]
time 3537ms: Process B completed a CPU burst; 6 bursts to go [Q <empty>]
time 3537ms: Process B switching out of CPU; will block on I/O until time 3545ms [Q <empty>]
time 3545ms: Process B completed I/O; added to ready queue [Q B]
time 3547ms: Process B started using the CPU for 219ms burst [Q <empty>]
time 3675ms: Time slice expired; no preemption because ready queue is empty [Q <empty>]
time 3766ms: Process B completed a CPU burst; 5 bursts to go [Q <empty>]
time 3766ms: Process B switching out of CPU; will block on I/O until time 3791ms [Q <empty>]
time 3791ms: Process B completed I/O; added to ready queue [Q B]
time 3793ms: Process B started using the CPU for 64ms burst [Q <empty>]
time 3857ms: Process B completed a CPU burst; 4 bursts to go [Q <empty>]
time 3857ms: Process B switching out of CPU; will block on I/O until time 3939ms [Q <empty>]
time 3939ms: Process B completed I/O; added to ready queue [Q B]
time 3941ms: Process B started using the CPU for 33ms burst [Q <empty>]
time 3974ms: Process B completed a CPU burst; 3 bursts to go [Q <empty>]
time 3974ms: Process B switching out of CPU; will block on I/O until time 4050ms [Q <empty>]
time 4050ms: Process B completed I/O; added to ready queue [Q B]
time 4052ms: Process B started using the CPU for 63ms burst [Q <empty>]
time 4115ms: Process B completed a CPU burst; 2 bursts to go [Q <empty>]
time 4115ms: Process B switching out of CPU; will block on I/O until time 4348ms [Q <empty>]
time 4348ms: Process B completed I/O; added to ready queue [Q B]
time 4350ms: Process B started using the CPU for 170ms burst [Q <empty>]
time 4478ms: Time slice expired; no preemption because ready queue is empty [Q <empty>]
time 4520ms: Process B completed a CPU burst; 1 burst to go [Q <empty>]
time 4520ms: Process B switching out of CPU; will block on I/O until time 4579ms [Q <empty>]
time 4579ms: Process B completed I/O; added to ready queue [Q B]
time 4581ms: Process B started using the CPU for 212ms burst [Q <empty>]
time 4709ms: Time slice expired; no preemption because ready queue is empty [Q <empty>]
time 4793ms: Process B terminated [Q <empty>]
time 4795ms: Simulator ended for RR [Q <empty>]
