Process A [NEW] (arrival time 9 ms) 16 CPU bursts
Process B [NEW] (arrival time 18 ms) 21 CPU bursts
time 0ms: Simulator started for RR [Q <empty>]
time 9ms: Process A arrived; added to ready queue [Q A]
time 11ms: Process A started using the CPU for 56ms burst [Q <empty>]
time 18ms: Process B arrived; added to ready queue [Q B]
time 67ms: Process A completed a CPU burst; 15 bursts to go [Q B]
time 67ms: Process A switching out of CPU; will block on I/O until time 92ms [Q B]
time 71ms: Process B started using the CPU for 106ms burst [Q <empty>]
time 92ms: Process A completed I/O; added to ready queue [Q A]
time 177ms: Process B completed a CPU burst; 20 bursts to go [Q A]
time 177ms: Process B switching out of CPU; will block on I/O until time 335ms [Q A]
time 181ms: Process A started using the CPU for 60ms burst [Q <empty>]
time 241ms: Process A completed a CPU burst; 14 bursts to go [Q <empty>]
time 241ms: Process A switching out of CPU; will block on I/O until time 396ms [Q <empty>]
time 335ms: Process B completed I/O; added to ready queue [Q B]
time 337ms: Process B started using the CPU for 198ms burst [Q <empty>]
time 396ms: Process A completed I/O; added to ready queue [Q A]
time 465ms: Time slice expired; process B preempted with 70ms to go [Q A]
time 469ms: Process A started using the CPU for 39ms burst [Q B]
time 508ms: Process A completed a CPU burst; 13 bursts to go [Q B]
time 508ms: Process A switching out of CPU; will block on I/O until time 560ms [Q B]
time 512ms: Process B started using the CPU with 70ms burst remaining [Q <empty>]
time 560ms: Process A completed I/O; added to ready queue [Q A]
time 582ms: Process B completed a CPU burst; 19 bursts to go [Q A]
time 582ms: Process B switching out of CPU; will block on I/O until time 697ms [Q A]
time 586ms: Process A started using the CPU for 47ms burst [Q <empty>]
time 633ms: Process A completed a CPU burst; 12 bursts to go [Q <empty>]
time 633ms: Process A switching out of CPU; will block on I/O until time 637ms [Q <empty>]
time 637ms: Process A completed I/O; added to ready queue [Q A]
time 639ms: Process A started using the CPU for 137ms burst [Q <empty>]
time 697ms: Process B completed I/O; added to ready queue [Q B]
time 767ms: Time slice expired; process A preempted with 9ms to go [Q B]
time 771ms: Process B started using the CPU for 208ms burst [Q A]
time 899ms: Time slice expired; process B preempted with 80ms to go [Q A]
time 903ms: Process A started using the CPU with 9ms burst remaining [Q B]
time 912ms: Process A completed a CPU burst; 11 bursts to go [Q B]
time 912ms: Process A switching out of CPU; will block on I/O until time 938ms [Q B]
time 916ms: Process B started using the CPU with 80ms burst remaining [Q <empty>]
time 938ms: Process A completed I/O; added to ready queue [Q A]
time 996ms: Process B completed a CPU burst; 18 bursts to go [Q A]
time 996ms: Process B switching out of CPU; will block on I/O until time 1160ms [Q A]
time 1000ms: Process A started using the CPU for 64ms burst [Q <empty>]
time 1064ms: Process A completed a CPU burst; 10 bursts to go [Q <empty>]
time 1064ms: Process A switching out of CPU; will block on I/O until time 1081ms [Q <empty>]
time 1081ms: Process A completed I/O; added to ready queue [Q A]
time 1083ms: Process A started using the CPU for 68ms burst [Q <empty>]
time 1151ms: Process A completed a CPU burst; 9 bursts to go [Q <empty>]
time 1151ms: Process A switching out of CPU; will block on I/O until time 1217ms [Q <empty>]
time 1160ms: Process B completed I/O; added to ready queue [Q B]
time 1162ms: Process B started using the CPU for 50ms burst [Q <empty>]
time 1212ms: Process B completed a CPU burst; 17 bursts to go [Q <empty>]
time 1212ms: Process B switching out of CPU; will block on I/O until time 1260ms [Q <empty>]
time 1217ms: Process A completed I/O; added to ready queue [Q A]
time 1219ms: Process A started using the CPU for 113ms burst [Q <empty>]
time 1260ms: Process B completed I/O; added to ready queue [Q B]
time 1332ms: Process A completed a CPU burst; 8 bursts to go [Q B]
time 1332ms: Process A switching out of CPU; will block on I/O until time 1350ms [Q B]
time 1336ms: Process B started using the CPU for 82ms burst [Q <empty>]
time 1350ms: Process A completed I/O; added to ready queue [Q A]
time 1418ms: Process B completed a CPU burst; 16 bursts to go [Q A]
time 1418ms: Process B switching out of CPU; will block on I/O until time 1436ms [Q A]
time 1422ms: Process A started using the CPU for 11ms burst [Q <empty>]
time 1433ms: Process A completed a CPU burst; 7 bursts to go [Q <empty>]
time 1433ms: Process A switching out of CPU; will block on I/O until time 1597ms [Q <empty>]
time 1436ms: Process B completed I/O; added to ready queue [Q B]
time 1438ms: Process B started using the CPU for 7ms burst [Q <empty>]
time 1445ms: Process B completed a CPU burst; 15 bursts to go [Q <empty>]
time 1445ms: Process B switching out of CPU; will block on I/O until time 1477ms [Q <empty>]
time 1477ms: Process B completed I/O; added to ready queue [Q B]
time 1479ms: Process B started using the CPU for 52ms burst [Q <empty>]
time 1531ms: Process B completed a CPU burst; 14 bursts to go [Q <empty>]
time 1531ms: Process B switching out of CPU; will block on I/O until time 1545ms [Q <empty>]
time 1545ms: Process B completed I/O; added to ready queue [Q B]
time 1547ms: Process B started using the CPU for 228ms burst [Q <empty>]
time 1597ms: Process A completed I/O; added to ready queue [Q A]
time 1675ms: Time slice expired; process B preempted with 100ms to go [Q A]
time 1679ms: Process A started using the CPU for 24ms burst [Q B]
time 1703ms: Process A completed a CPU burst; 6 bursts to go [Q B]
time 1703ms: Process A switching out of CPU; will block on I/O until time 1822ms [Q B]
time 1707ms: Process B started using the CPU with 100ms burst remaining [Q <empty>]
time 1807ms: Process B completed a CPU burst; 13 bursts to go [Q <empty>]
time 1807ms: Process B switching out of CPU; will block on I/O until time 1886ms [Q <empty>]
time 1822ms: Process A completed I/O; added to ready queue [Q A]
time 1824ms: Process A started using the CPU for 76ms burst [Q <empty>]
time 1886ms: Process B completed I/O; added to ready queue [Q B]
time 1900ms: Process A completed a CPU burst; 5 bursts to go [Q B]
time 1900ms: Process A switching out of CPU; will block on I/O until time 1930ms [Q B]
time 1904ms: Process B started using the CPU for 138ms burst [Q <empty>]
time 1930ms: Process A completed I/O; added to ready queue [Q A]
time 2032ms: Time slice expired; process B preempted with 10ms to go [Q A]
time 2036ms: Process A started using the CPU for 122ms burst [Q B]
time 2158ms: Process A completed a CPU burst; 4 bursts to go [Q B]
time 2158ms: Process A switching out of CPU; will block on I/O until time 2193ms [Q B]
time 2162ms: Process B started using the CPU with 10ms burst remaining [Q <empty>]
time 2172ms: Process B completed a CPU burst; 12 bursts to go [Q <empty>]
time 2172ms: Process B switching out of CPU; will block on I/O until time 2256ms [Q <empty>]
time 2193ms: Process A completed I/O; added to ready queue [Q A]
time 2195ms: Process A started using the CPU for 9ms burst [Q <empty>]
time 2204ms: Process A completed a CPU burst; 3 bursts to go [Q <empty>]
time 2204ms: Process A switching out of CPU; will block on I/O until time 2274ms [Q <empty>]
time 2256ms: Process B completed I/O; added to ready queue [Q B]
time 2258ms: Process B started using the CPU for 67ms burst [Q <empty>]
time 2274ms: Process A completed I/O; added to ready queue [Q A]
time 2325ms: Process B completed a CPU burst; 11 bursts to go [Q A]
time 2325ms: Process B switching out of CPU; will block on I/O until time 2334ms [Q A]
time 2329ms: Process A started using the CPU for 62ms burst [Q <empty>]
time 2334ms: Process B completed I/O; added to ready queue [Q B]
time 2391ms: Process A completed a CPU burst; 2 bursts to go [Q B]
time 2391ms: Process A switching out of CPU; will block on I/O until time 2470ms [Q B]
time 2395ms: Process B started using the CPU for 120ms burst [Q <empty>]
time 2470ms: Process A completed I/O; added to ready queue [Q A]
time 2515ms: Process B completed a CPU burst; 10 bursts to go [Q A]
time 2515ms: Process B switching out of CPU; will block on I/O until time 2530ms [Q A]
time 2519ms: Process A started using the CPU for 200ms burst [Q <empty>]
time 2530ms: Process B completed I/O; added to ready queue [Q B]
time 2647ms: Time slice expired; process A preempted with 72ms to go [Q B]
time 2651ms: Process B started using the CPU for 49ms burst [Q A]
time 2700ms: Process B completed a CPU burst; 9 bursts to go [Q A]
time 2700ms: Process B switching out of CPU; will block on I/O until time 2744ms [Q A]
time 2704ms: Process A started using the CPU with 72ms burst remaining [Q <empty>]
time 2744ms: Process B completed I/O; added to ready queue [Q B]
time 2776ms: Process A completed a CPU burst; 1 burst to go [Q B]
time 2776ms: Process A switching out of CPU; will block on I/O until time 2789ms [Q B]
time 2780ms: Process B started using the CPU for 134ms burst [Q <empty>]
time 2789ms: Process A completed I/O; added to ready queue [Q A]
time 2908ms: Time slice expired; process B preempted with 6ms to go [Q A]
time 2912ms: Process A started using the CPU for 197ms burst [Q B]
time 3040ms: Time slice expired; process A preempted with 69ms to go [Q B]
time 3044ms: Process B started using the CPU with 6ms burst remaining [Q A]
time 3050ms: Process B completed a CPU burst; 8 bursts to go [Q A]
time 3050ms: Process B switching out of CPU; will block on I/O until time 3084ms [Q A]
time 3054ms: Process A started using the CPU with 69ms burst remaining [Q <empty>]
time 3084ms: Process B completed I/O; added to ready queue [Q B]
time 3123ms: Process A terminated [Q B]
time 3127ms: Process B started using the CPU for 144ms burst [Q <empty>]
time 3255ms: Time slice expired; no preemption because ready queue is empty [Q <empty>]
time 3271ms: Process B completed a CPU burst; 7 bursts to go [Q <empty>]
time 3271ms: Process B switching out of CPU; will block on I/O until time 3352ms [Q <empty>]
time 3352ms: Process B completed I/O; added to ready queue [Q B]
time 3354ms: Process B started using the CPU for 183ms burst [Q <empty>]
time 3482ms: Time slice expired; no preemption because ready queue is empty [Q <empty>]
time 3537ms: Process B completed a CPU burst; 6 bursts to go [Q <empty>]
time 3537ms: Process B switching out of CPU; will block on I/O until time 3545ms [Q <empty>]
time 3545ms: Process B completed I/O; added to ready queue [Q B]
time 3547ms: Process B started using the CPU for 219ms burst [Q <empty>]
time 3675ms: Time slice expired; no preemption because ready queue is empty [Q <empty>]
time 3766ms: Process B completed a CPU burst; 5 bursts to go [Q <empty>]
time 3766ms: Process B switching out of CPU; will block on I/O until time 3791ms [Q <empty>]
time 3791ms: Process B completed I/O; added to ready queue [Q B]
time 3793ms: Process B started using the CPU for 64ms burst [Q <empty>]
time 3857ms: Process B completed a CPU burst; 4 bursts to go [Q <empty>]
time 3857ms: Process B switching out of CPU; will block on I/O until time 3939ms [Q <empty>]
time 3939ms: Process B completed I/O; added to ready queue [Q B]
time 3941ms: Process B started using the CPU for 33ms burst [Q <empty>]
time 3974ms: Process B completed a CPU burst; 3 bursts to go [Q <empty>]
time 3974ms: Process B switching out of CPU; will block on I/O until time 4050ms [Q <empty>]
time 4050ms: Process B completed I/O; added to ready queue [Q B]
time 4052ms: Process B started using the CPU for 63ms burst [Q <empty>]
time 4115ms: Process B completed a CPU burst; 2 bursts to go [Q <empty>]
time 4115ms: Process B switching out of CPU; will block on I/O until time 4348ms [Q <empty>]
time 4348ms: Process B completed I/O; added to ready queue [Q B]
time 4350ms: Process B started using the CPU for 170ms burst [Q <empty>]
time 4478ms: Time slice expired; no preemption because ready queue is empty [Q <empty>]
time 4520ms: Process B completed a CPU burst; 1 burst to go [Q <empty>]
time 4520ms: Process B switching out of CPU; will block on I/O until time 4579ms [Q <empty>]
time 4579ms: Process B completed I/O; added to ready queue [Q B]
time 4581ms: Process B started using the CPU for 212ms burst [Q <empty>]
time 4709ms: Time slice expired; no preemption because ready queue is empty [Q <empty>]
time 4793ms: Process B terminated [Q <empty>]
time 4795ms: Simulator ended for RR [Q <empty>]
