Process A [NEW] (arrival time 9 ms) 16 CPU bursts
time 0ms: Simulator started for RR [Q <empty>]
time 9ms: Process A arrived; added to ready queue [Q A]
time 11ms: Process A started using the CPU for 56ms burst [Q <empty>]
time 67ms: Process A completed a CPU burst; 15 bursts to go [Q <empty>]
time 67ms: Process A switching out of CPU; will block on I/O until time 92ms [Q <empty>]
time 92ms: Process A completed I/O; added to ready queue [Q A]
time 94ms: Process A started using the CPU for 60ms burst [Q <empty>]
time 154ms: Process A completed a CPU burst; 14 bursts to go [Q <empty>]
time 154ms: Process A switching out of CPU; will block on I/O until time 309ms [Q <empty>]
time 309ms: Process A completed I/O; added to ready queue [Q A]
time 311ms: Process A started using the CPU for 39ms burst [Q <empty>]
time 350ms: Process A completed a CPU burst; 13 bursts to go [Q <empty>]
time 350ms: Process A switching out of CPU; will block on I/O until time 402ms [Q <empty>]
time 402ms: Process A completed I/O; added to ready queue [Q A]
time 404ms: Process A started using the CPU for 47ms burst [Q <empty>]
time 451ms: Process A completed a CPU burst; 12 bursts to go [Q <empty>]
time 451ms: Process A switching out of CPU; will block on I/O until time 455ms [Q <empty>]
time 455ms: Process A completed I/O; added to ready queue [Q A]
time 457ms: Process A started using the CPU for 137ms burst [Q <empty>]
time 585ms: Time slice expired; no preemption because ready queue is empty [Q <empty>]
time 594ms: Process A completed a CPU burst; 11 bursts to go [Q <empty>]
time 594ms: Process A switching out of CPU; will block on I/O until time 620ms [Q <empty>]
time 620ms: Process A completed I/O; added to ready queue [Q A]
time 622ms: Process A started using the CPU for 64ms burst [Q <empty>]
time 686ms: Process A completed a CPU burst; 10 bursts to go [Q <empty>]
time 686ms: Process A switching out of CPU; will block on I/O until time 703ms [Q <empty>]
time 703ms: Process A completed I/O; added to ready queue [Q A]
time 705ms: Process A started using the CPU for 68ms burst [Q <empty>]
time 773ms: Process A completed a CPU burst; 9 bursts to go [Q <empty>]
time 773ms: Process A switching out of CPU; will block on I/O until time 839ms [Q <empty>]
time 839ms: Process A completed I/O; added to ready queue [Q A]
time 841ms: Process A started using the CPU for 113ms burst [Q <empty>]
time 954ms: Process A completed a CPU burst; 8 bursts to go [Q <empty>]
time 954ms: Process A switching out of CPU; will block on I/O until time 972ms [Q <empty>]
time 972ms: Process A completed I/O; added to ready queue [Q A]
time 974ms: Process A started using the CPU for 11ms burst [Q <empty>]
time 985ms: Process A completed a CPU burst; 7 bursts to go [Q <empty>]
time 985ms: Process A switching out of CPU; will block on I/O until time 1149ms [Q <empty>]
time 1149ms: Process A completed I/O; added to ready queue [Q A]
time 1151ms: Process A started using the CPU for 24ms burst [Q <empty>]
time 1175ms: Process A completed a CPU burst; 6 bursts to go [Q <empty>]
time 1175ms: Process A switching out of CPU; will block on I/O until time 1294ms [Q <empty>]
time 1294ms: Process A completed I/O; added to ready queue [Q A]
time 1296ms: Process A started using the CPU for 76ms burst [Q <empty>]
time 1372ms: Process A completed a CPU burst; 5 bursts to go [Q <empty>]
time 1372ms: Process A switching out of CPU; will block on I/O until time 1402ms [Q <empty>]
time 1402ms: Process A completed I/O; added to ready queue [Q A]
time 1404ms: Process A started using the CPU for 122ms burst [Q <empty>]
time 1526ms: Process A completed a CPU burst; 4 bursts to go [Q <empty>]
time 1526ms: Process A switching out of CPU; will block on I/O until time 1561ms [Q <empty>]
time 1561ms: Process A completed I/O; added to ready queue [Q A]
time 1563ms: Process A started using the CPU for 9ms burst [Q <empty>]
time 1572ms: Process A completed a CPU burst; 3 bursts to go [Q <empty>]
time 1572ms: Process A switching out of CPU; will block on I/O until time 1642ms [Q <empty>]
time 1642ms: Process A completed I/O; added to ready queue [Q A]
time 1644ms: Process A started using the CPU for 62ms burst [Q <empty>]
time 1706ms: Process A completed a CPU burst; 2 bursts to go [Q <empty>]
time 1706ms: Process A switching out of CPU; will block on I/O until time 1785ms [Q <empty>]
time 1785ms: Process A completed I/O; added to ready queue [Q A]
time 1787ms: Process A started using the CPU for 200ms burst [Q <empty>]
time 1915ms: Time slice expired; no preemption because ready queue is empty [Q <empty>]
time 1987ms: Process A completed a CPU burst; 1 burst to go [Q <empty>]
time 1987ms: Process A switching out of CPU; will block on I/O until time 2000ms [Q <empty>]
time 2000ms: Process A completed I/O; added to ready queue [Q A]
time 2002ms: Process A started using the CPU for 197ms burst [Q <empty>]
time 2130ms: Time slice expired; no preemption because ready queue is empty [Q <empty>]
time 2199ms: Process A terminated [Q <empty>]
time 2201ms: Simulator ended for RR [Q <empty>]
