Process A [NEW] (arrival time 9 ms) 16 CPU bursts (tau 100ms)
Process B [NEW] (arrival time 18 ms) 21 CPU bursts (tau 100ms)
time 0ms: Simulator started for SJF [Q <empty>]
time 9ms: Process A (tau 100ms) arrived; added to ready queue [Q A]
time 11ms: Process A (tau 100ms) started using the CPU for 56ms burst [Q <empty>]
time 18ms: Process B (tau 100ms) arrived; added to ready queue [Q B]
time 67ms: Process A (tau 100ms) completed a CPU burst; 15 bursts to go [Q B]
time 67ms: Recalculated tau = 78ms for process A [Q B]
time 67ms: Process A switching out of CPU; will block on I/O until time 92ms [Q B]
time 71ms: Process B (tau 100ms) started using the CPU for 106ms burst [Q <empty>]
time 92ms: Process A (tau 78ms) completed I/O; added to ready queue [Q A]
time 177ms: Process B (tau 100ms) completed a CPU burst; 20 bursts to go [Q A]
time 177ms: Recalculated tau = 103ms for process B [Q A]
time 177ms: Process B switching out of CPU; will block on I/O until time 335ms [Q A]
time 181ms: Process A (tau 78ms) started using the CPU for 60ms burst [Q <empty>]
time 241ms: Process A (tau 78ms) completed a CPU burst; 14 bursts to go [Q <empty>]
time 241ms: Recalculated tau = 69ms for process A [Q <empty>]
time 241ms: Process A switching out of CPU; will block on I/O until time 396ms [Q <empty>]
time 335ms: Process B (tau 103ms) completed I/O; added to ready queue [Q B]
time 337ms: Process B (tau 103ms) started using the CPU for 198ms burst [Q <empty>]
time 396ms: Process A (tau 69ms) completed I/O; added to ready queue [Q A]
time 535ms: Process B (tau 103ms) completed a CPU burst; 19 bursts to go [Q A]
time 535ms: Recalculated tau = 151ms for process B [Q A]
time 535ms: Process B switching out of CPU; will block on I/O until time 650ms [Q A]
time 539ms: Process A (tau 69ms) started using the CPU for 39ms burst [Q <empty>]
time 578ms: Process A (tau 69ms) completed a CPU burst; 13 bursts to go [Q <empty>]
time 578ms: Recalculated tau = 54ms for process A [Q <empty>]
time 578ms: Process A switching out of CPU; will block on I/O until time 630ms [Q <empty>]
time 630ms: Process A (tau 54ms) completed I/O; added to ready queue [Q A]
time 632ms: Process A (tau 54ms) started using the CPU for 47ms burst [Q <empty>]
time 650ms: Process B (tau 151ms) completed I/O; added to ready queue [Q B]
time 679ms: Process A (tau 54ms) completed a CPU burst; 12 bursts to go [Q B]
time 679ms: Recalculated tau = 51ms for process A [Q B]
time 679ms: Process A switching out of CPU; will block on I/O until time 683ms [Q B]
time 683ms: Process B (tau 151ms) started using the CPU for 208ms burst [Q <empty>]
time 683ms: Process A (tau 51ms) completed I/O; added to ready queue [Q A]
time 891ms: Process B (tau 151ms) completed a CPU burst; 18 bursts to go [Q A]
time 891ms: Recalculated tau = 180ms for process B [Q A]
time 891ms: Process B switching out of CPU; will block on I/O until time 1055ms [Q A]
time 895ms: Process A (tau 51ms) started using the CPU for 137ms burst [Q <empty>]
time 1032ms: Process A (tau 51ms) completed a CPU burst; 11 bursts to go [Q <empty>]
time 1032ms: Recalculated tau = 94ms for process A [Q <empty>]
time 1032ms: Process A switching out of CPU; will block on I/O until time 1058ms [Q <empty>]
time 1055ms: Process B (tau 180ms) completed I/O; added to ready queue [Q B]
time 1057ms: Process B (tau 180ms) started using the CPU for 50ms burst [Q <empty>]
time 1058ms: Process A (tau 94ms) completed I/O; added to ready queue [Q A]
time 1107ms: Process B (tau 180ms) completed a CPU burst; 17 bursts to go [Q A]
time 1107ms: Recalculated tau = 115ms for process B [Q A]
time 1107ms: Process B switching out of CPU; will block on I/O until time 1155ms [Q A]
time 1111ms: Process A (tau 94ms) started using the CPU for 64ms burst [Q <empty>]
time 1155ms: Process B (tau 115ms) completed I/O; added to ready queue [Q B]
time 1175ms: Process A (tau 94ms) completed a CPU burst; 10 bursts to go [Q B]
time 1175ms: Recalculated tau = 79ms for process A [Q B]
time 1175ms: Process A switching out of CPU; will block on I/O until time 1192ms [Q B]
time 1179ms: Process B (tau 115ms) started using the CPU for 82ms burst [Q <empty>]
time 1192ms: Process A (tau 79ms) completed I/O; added to ready queue [Q A]
time 1261ms: Process B (tau 115ms) completed a CPU burst; 16 bursts to go [Q A]
time 1261ms: Recalculated tau = 99ms for process B [Q A]
time 1261ms: Process B switching out of CPU; will block on I/O until time 1279ms [Q A]
time 1265ms: Process A (tau 79ms) started using the CPU for 68ms burst [Q <empty>]
time 1279ms: Process B (tau 99ms) completed I/O; added to ready queue [Q B]
time 1333ms: Process A (tau 79ms) completed a CPU burst; 9 bursts to go [Q B]
time 1333ms: Recalculated tau = 74ms for process A [Q B]
time 1333ms: Process A switching out of CPU; will block on I/O until time 1399ms [Q B]
time 1337ms: Process B (tau 99ms) started using the CPU for 7ms burst [Q <empty>]
time 1344ms: Process B (tau 99ms) completed a CPU burst; 15 bursts to go [Q <empty>]
time 1344ms: Recalculated tau = 53ms for process B [Q <empty>]
time 1344ms: Process B switching out of CPU; will block on I/O until time 1376ms [Q <empty>]
time 1376ms: Process B (tau 53ms) completed I/O; added to ready queue [Q B]
time 1378ms: Process B (tau 53ms) started using the CPU for 52ms burst [Q <empty>]
time 1399ms: Process A (tau 74ms) completed I/O; added to ready queue [Q A]
time 1430ms: Process B (tau 53ms) completed a CPU burst; 14 bursts to go [Q A]
time 1430ms: Recalculated tau = 53ms for process B [Q A]
time 1430ms: Process B switching out of CPU; will block on I/O until time 1444ms [Q A]
time 1434ms: Process A (tau 74ms) started using the CPU for 113ms burst [Q <empty>]
time 1444ms: Process B (tau 53ms) completed I/O; added to ready queue [Q B]
time 1547ms: Process A (tau 74ms) completed a CPU burst; 8 bursts to go [Q B]
time 1547ms: Recalculated tau = 94ms for process A [Q B]
time 1547ms: Process A switching out of CPU; will block on I/O until time 1565ms [Q B]
time 1551ms: Process B (tau 53ms) started using the CPU for 228ms burst [Q <empty>]
time 1565ms: Process A (tau 94ms) completed I/O; added to ready queue [Q A]
time 1779ms: Process B (tau 53ms) completed a CPU burst; 13 bursts to go [Q A]
time 1779ms: Recalculated tau = 141ms for process B [Q A]
time 1779ms: Process B switching out of CPU; will block on I/O until time 1858ms [Q A]
time 1783ms: Process A (tau 94ms) started using the CPU for 11ms burst [Q <empty>]
time 1794ms: Process A (tau 94ms) completed a CPU burst; 7 bursts to go [Q <empty>]
time 1794ms: Recalculated tau = 53ms for process A [Q <empty>]
time 1794ms: Process A switching out of CPU; will block on I/O until time 1958ms [Q <empty>]
time 1858ms: Process B (tau 141ms) completed I/O; added to ready queue [Q B]
time 1860ms: Process B (tau 141ms) started using the CPU for 138ms burst [Q <empty>]
time 1958ms: Process A (tau 53ms) completed I/O; added to ready queue [Q A]
time 1998ms: Process B (tau 141ms) completed a CPU burst; 12 bursts to go [Q A]
time 1998ms: Recalculated tau = 140ms for process B [Q A]
time 1998ms: Process B switching out of CPU; will block on I/O until time 2082ms [Q A]
time 2002ms: Process A (tau 53ms) started using the CPU for 24ms burst [Q <empty>]
time 2026ms: Process A (tau 53ms) completed a CPU burst; 6 bursts to go [Q <empty>]
time 2026ms: Recalculated tau = 39ms for process A [Q <empty>]
time 2026ms: Process A switching out of CPU; will block on I/O until time 2145ms [Q <empty>]
time 2082ms: Process B (tau 140ms) completed I/O; added to ready queue [Q B]
time 2084ms: Process B (tau 140ms) started using the CPU for 67ms burst [Q <empty>]
time 2145ms: Process A (tau 39ms) completed I/O; added to ready queue [Q A]
time 2151ms: Process B (tau 140ms) completed a CPU burst; 11 bursts to go [Q A]
time 2151ms: Recalculated tau = 104ms for process B [Q A]
time 2151ms: Process B switching out of CPU; will block on I/O until time 2160ms [Q A]
time 2155ms: Process A (tau 39ms) started using the CPU for 76ms burst [Q <empty>]
time 2160ms: Process B (tau 104ms) completed I/O; added to ready queue [Q B]
time 2231ms: Process A (tau 39ms) completed a CPU burst; 5 bursts to go [Q B]
time 2231ms: Recalculated tau = 58ms for process A [Q B]
time 2231ms: Process A switching out of CPU; will block on I/O until time 2261ms [Q B]
time 2235ms: Process B (tau 104ms) started using the CPU for 120ms burst [Q <empty>]
time 2261ms: Process A (tau 58ms) completed I/O; added to ready queue [Q A]
time 2355ms: Process B (tau 104ms) completed a CPU burst; 10 bursts to go [Q A]
time 2355ms: Recalculated tau = 112ms for process B [Q A]
time 2355ms: Process B switching out of CPU; will block on I/O until time 2370ms [Q A]
time 2359ms: Process A (tau 58ms) started using the CPU for 122ms burst [Q <empty>]
time 2370ms: Process B (tau 112ms) completed I/O; added to ready queue [Q B]
time 2481ms: Process A (tau 58ms) completed a CPU burst; 4 bursts to go [Q B]
time 2481ms: Recalculated tau = 90ms for process A [Q B]
time 2481ms: Process A switching out of CPU; will block on I/O until time 2516ms [Q B]
time 2485ms: Process B (tau 112ms) started using the CPU for 49ms burst [Q <empty>]
time 2516ms: Process A (tau 90ms) completed I/O; added to ready queue [Q A]
time 2534ms: Process B (tau 112ms) completed a CPU burst; 9 bursts to go [Q A]
time 2534ms: Recalculated tau = 81ms for process B [Q A]
time 2534ms: Process B switching out of CPU; will block on I/O until time 2578ms [Q A]
time 2538ms: Process A (tau 90ms) started using the CPU for 9ms burst [Q <empty>]
time 2547ms: Process A (tau 90ms) completed a CPU burst; 3 bursts to go [Q <empty>]
time 2547ms: Recalculated tau = 50ms for process A [Q <empty>]
time 2547ms: Process A switching out of CPU; will block on I/O until time 2617ms [Q <empty>]
time 2578ms: Process B (tau 81ms) completed I/O; added to ready queue [Q B]
time 2580ms: Process B (tau 81ms) started using the CPU for 134ms burst [Q <empty>]
time 2617ms: Process A (tau 50ms) completed I/O; added to ready queue [Q A]
time 2714ms: Process B (tau 81ms) completed a CPU burst; 8 bursts to go [Q A]
time 2714ms: Recalculated tau = 108ms for process B [Q A]
time 2714ms: Process B switching out of CPU; will block on I/O until time 2748ms [Q A]
time 2718ms: Process A (tau 50ms) started using the CPU for 62ms burst [Q <empty>]
time 2748ms: Process B (tau 108ms) completed I/O; added to ready queue [Q B]
time 2780ms: Process A (tau 50ms) completed a CPU burst; 2 bursts to go [Q B]
time 2780ms: Recalculated tau = 56ms for process A [Q B]
time 2780ms: Process A switching out of CPU; will block on I/O until time 2859ms [Q B]
time 2784ms: Process B (tau 108ms) started using the CPU for 144ms burst [Q <empty>]
time 2859ms: Process A (tau 56ms) completed I/O; added to ready queue [Q A]
time 2928ms: Process B (tau 108ms) completed a CPU burst; 7 bursts to go [Q A]
time 2928ms: Recalculated tau = 126ms for process B [Q A]
time 2928ms: Process B switching out of CPU; will block on I/O until time 3009ms [Q A]
time 2932ms: Process A (tau 56ms) started using the CPU for 200ms burst [Q <empty>]
time 3009ms: Process B (tau 126ms) completed I/O; added to ready queue [Q B]
time 3132ms: Process A (tau 56ms) completed a CPU burst; 1 burst to go [Q B]
time 3132ms: Recalculated tau = 128ms for process A [Q B]
time 3132ms: Process A switching out of CPU; will block on I/O until time 3145ms [Q B]
time 3136ms: Process B (tau 126ms) started using the CPU for 183ms burst [Q <empty>]
time 3145ms: Process A (tau 128ms) completed I/O; added to ready queue [Q A]
time 3319ms: Process B (tau 126ms) completed a CPU burst; 6 bursts to go [Q A]
time 3319ms: Recalculated tau = 155ms for process B [Q A]
time 3319ms: Process B switching out of CPU; will block on I/O until time 3327ms [Q A]
time 3323ms: Process A (tau 128ms) started using the CPU for 197ms burst [Q <empty>]
time 3327ms: Process B (tau 155ms) completed I/O; added to ready queue [Q B]
time 3520ms: Process A terminated [Q B]
time 3524ms: Process B (tau 155ms) started using the CPU for 219ms burst [Q <empty>]
time 3743ms: Process B (tau 155ms) completed a CPU burst; 5 bursts to go [Q <empty>]
time 3743ms: Recalculated tau = 187ms for process B [Q <empty>]
time 3743ms: Process B switching out of CPU; will block on I/O until time 3768ms [Q <empty>]
time 3768ms: Process B (tau 187ms) completed I/O; added to ready queue [Q B]
time 3770ms: Process B (tau 187ms) started using the CPU for 64ms burst [Q <empty>]
time 3834ms: Process B (tau 187ms) completed a CPU burst; 4 bursts to go [Q <empty>]
time 3834ms: Recalculated tau = 126ms for process B [Q <empty>]
time 3834ms: Process B switching out of CPU; will block on I/O until time 3916ms [Q <empty>]
time 3916ms: Process B (tau 126ms) completed I/O; added to ready queue [Q B]
time 3918ms: Process B (tau 126ms) started using the CPU for 33ms burst [Q <empty>]
time 3951ms: Process B (tau 126ms) completed a CPU burst; 3 bursts to go [Q <empty>]
time 3951ms: Recalculated tau = 80ms for process B [Q <empty>]
time 3951ms: Process B switching out of CPU; will block on I/O until time 4027ms [Q <empty>]
time 4027ms: Process B (tau 80ms) completed I/O; added to ready queue [Q B]
time 4029ms: Process B (tau 80ms) started using the CPU for 63ms burst [Q <empty>]
time 4092ms: Process B (tau 80ms) completed a CPU burst; 2 bursts to go [Q <empty>]
time 4092ms: Recalculated tau = 72ms for process B [Q <empty>]
time 4092ms: Process B switching out of CPU; will block on I/O until time 4325ms [Q <empty>]
time 4325ms: Process B (tau 72ms) completed I/O; added to ready queue [Q B]
time 4327ms: Process B (tau 72ms) started using the CPU for 170ms burst [Q <empty>]
time 4497ms: Process B (tau 72ms) completed a CPU burst; 1 burst to go [Q <empty>]
time 4497ms: Recalculated tau = 121ms for process B [Q <empty>]
time 4497ms: Process B switching out of CPU; will block on I/O until time 4556ms [Q <empty>]
time 4556ms: Process B (tau 121ms) completed I/O; added to ready queue [Q B]
time 4558ms: Process B (tau 121ms) started using the CPU for 212ms burst [Q <empty>]
time 4770ms: Process B terminated [Q <empty>]
time 4772ms: Simulator ended for SJF [Q <empty>]
