Process A [NEW] (arrival time 9 ms) 16 CPU bursts
Process B [NEW] (arrival time 18 ms) 21 CPU bursts
Process C [NEW] (arrival time 42 ms) 4 CPU bursts
Process D [NEW] (arrival time 156 ms) 11 CPU bursts
Process E [NEW] (arrival time 134 ms) 55 CPU bursts
Process F [NEW] (arrival time 106 ms) 34 CPU bursts
Process G [NEW] (arrival time 65 ms) 80 CPU bursts
Process H [NEW] (arrival time 11 ms) 83 CPU bursts
Process I [NEW] (arrival time 68 ms) 77 CPU bursts
Process J [NEW] (arrival time 0 ms) 10 CPU bursts
Process K [NEW] (arrival time 7 ms) 13 CPU bursts
Process L [NEW] (arrival time 189 ms) 7 CPU bursts
Process M [NEW] (arrival time 16 ms) 48 CPU bursts
Process N [NEW] (arrival time 122 ms) 31 CPU bursts
Process O [NEW] (arrival time 29 ms) 31 CPU bursts
Process P [NEW] (arrival time 159 ms) 16 CPU bursts
time 0ms: Simulator started for FCFS [Q <empty>]
time 0ms: Process J arrived; added to ready queue [Q J]
time 2ms: Process J started using the CPU for 40ms burst [Q <empty>]
time 7ms: Process K arrived; added to ready queue [Q K]
time 9ms: Process A arrived; added to ready queue [Q K A]
time 11ms: Process H arrived; added to ready queue [Q K A H]
time 16ms: Process M arrived; added to ready queue [Q K A H M]
time 18ms: Process B arrived; added to ready queue [Q K A H M B]
time 29ms: Process O arrived; added to ready queue [Q K A H M B O]
time 42ms: Process J completed a CPU burst; 9 bursts to go [Q K A H M B O]
time 42ms: Process J switching out of CPU; will block on I/O until time 47ms [Q K A H M B O]
time 42ms: Process C arrived; added to ready queue [Q K A H M B O C]
time 46ms: Process K started using the CPU for 64ms burst [Q A H M B O C]
time 47ms: Process J completed I/O; added to ready queue [Q A H M B O C J]
time 65ms: Process G arrived; added to ready queue [Q A H M B O C J G]
time 68ms: Process I arrived; added to ready queue [Q A H M B O C J G I]
time 106ms: Process F arrived; added to ready queue [Q A H M B O C J G I F]
time 110ms: Process K completed a CPU burst; 12 bursts to go [Q A H M B O C J G I F]
time 110ms: Process K switching out of CPU; will block on I/O until time 208ms [Q A H M B O C J G I F]
time 114ms: Process A started using the CPU for 56ms burst [Q H M B O C J G I F]
time 122ms: Process N arrived; added to ready queue [Q H M B O C J G I F N]
time 134ms: Process E arrived; added to ready queue [Q H M B O C J G I F N E]
time 156ms: Process D arrived; added to ready queue [Q H M B O C J G I F N E D]
time 159ms: Process P arrived; added to ready queue [Q H M B O C J G I F N E D P]
time 170ms: Process A completed a CPU burst; 15 bursts to go [Q H M B O C J G I F N E D P]
time 170ms: Process A switching out of CPU; will block on I/O until time 195ms [Q H M B O C J G I F N E D P]
time 174ms: Process H started using the CPU for 96ms burst [Q M B O C J G I F N E D P]
time 189ms: Process L arrived; added to ready queue [Q M B O C J G I F N E D P L]
time 195ms: Process A completed I/O; added to ready queue [Q M B O C J G I F N E D P L A]
time 208ms: Process K completed I/O; added to ready queue [Q M B O C J G I F N E D P L A K]
time 270ms: Process H completed a CPU burst; 82 bursts to go [Q M B O C J G I F N E D P L A K]
time 270ms: Process H switching out of CPU; will block on I/O until time 339ms [Q M B O C J G I F N E D P L A K]
time 274ms: Process M started using the CPU for 22ms burst [Q B O C J G I F N E D P L A K]
time 296ms: Process M completed a CPU burst; 47 bursts to go [Q B O C J G I F N E D P L A K]
time 296ms: Process M switching out of CPU; will block on I/O until time 315ms [Q B O C J G I F N E D P L A K]
time 300ms: Process B started using the CPU for 106ms burst [Q O C J G I F N E D P L A K]
time 315ms: Process M completed I/O; added to ready queue [Q O C J G I F N E D P L A K M]
time 339ms: Process H completed I/O; added to ready queue [Q O C J G I F N E D P L A K M H]
time 406ms: Process B completed a CPU burst; 20 bursts to go [Q O C J G I F N E D P L A K M H]
time 406ms: Process B switching out of CPU; will block on I/O until time 564ms [Q O C J G I F N E D P L A K M H]
time 410ms: Process O started using the CPU for 156ms burst [Q C J G I F N E D P L A K M H]
time 564ms: Process B completed I/O; added to ready queue [Q C J G I F N E D P L A K M H B]
time 566ms: Process O completed a CPU burst; 30 bursts to go [Q C J G I F N E D P L A K M H B]
time 566ms: Process O switching out of CPU; will block on I/O until time 635ms [Q C J G I F N E D P L A K M H B]
time 570ms: Process C started using the CPU for 94ms burst [Q J G I F N E D P L A K M H B]
time 635ms: Process O completed I/O; added to ready queue [Q J G I F N E D P L A K M H B O]
time 664ms: Process C completed a CPU burst; 3 bursts to go [Q J G I F N E D P L A K M H B O]
time 664ms: Process C switching out of CPU; will block on I/O until time 824ms [Q J G I F N E D P L A K M H B O]
time 668ms: Process J started using the CPU for 204ms burst [Q G I F N E D P L A K M H B O]
time 824ms: Process C completed I/O; added to ready queue [Q G I F N E D P L A K M H B O C]
time 872ms: Process J completed a CPU burst; 8 bursts to go [Q G I F N E D P L A K M H B O C]
time 872ms: Process J switching out of CPU; will block on I/O until time 944ms [Q G I F N E D P L A K M H B O C]
time 876ms: Process G started using the CPU for 70ms burst [Q I F N E D P L A K M H B O C]
time 944ms: Process J completed I/O; added to ready queue [Q I F N E D P L A K M H B O C J]
time 946ms: Process G completed a CPU burst; 79 bursts to go [Q I F N E D P L A K M H B O C J]
time 946ms: Process G switching out of CPU; will block on I/O until time 979ms [Q I F N E D P L A K M H B O C J]
time 950ms: Process I started using the CPU for 220ms burst [Q F N E D P L A K M H B O C J]
time 979ms: Process G completed I/O; added to ready queue [Q F N E D P L A K M H B O C J G]
time 4634ms: Process C terminated [Q B J G O F E I N K L A D H P]
time 8845ms: Process L terminated [Q A K D B H M J P F E G N O I]
time 10611ms: Process J terminated [Q P F E G N O K D A I B H]
time 13604ms: Process D terminated [Q K A O B I M H F E G]
time 14739ms: Process K terminated [Q A I B M H O F G E]
time 17915ms: Process A terminated [Q I B M F O G N P E H]
time 19250ms: Process P terminated [Q E H I B F O M]
time 21901ms: Process B terminated [Q M O H E F G N I]
time 29646ms: Process O terminated [Q N I F M]
time 29716ms: Process N terminated [Q I F M H G]
time 31078ms: Process F terminated [Q I H M G E]
time 37417ms: Process M terminated [Q E G H]
time 39678ms: Process E terminated [Q H G I]
time 46801ms: Process I terminated [Q <empty>]
time 47484ms: Process G terminated [Q <empty>]
time 47921ms: Process H terminated [Q <empty>]
time 47923ms: Simulator ended for FCFS [Q <empty>]

Process A [NEW] (arrival time 9 ms) 16 CPU bursts (tau 100ms)
Process B [NEW] (arrival time 18 ms) 21 CPU bursts (tau 100ms)
Process C [NEW] (arrival time 42 ms) 4 CPU bursts (tau 100ms)
Process D [NEW] (arrival time 156 ms) 11 CPU bursts (tau 100ms)
Process E [NEW] (arrival time 134 ms) 55 CPU bursts (tau 100ms)
Process F [NEW] (arrival time 106 ms) 34 CPU bursts (tau 100ms)
Process G [NEW] (arrival time 65 ms) 80 CPU bursts (tau 100ms)
Process H [NEW] (arrival time 11 ms) 83 CPU bursts (tau 100ms)
Process I [NEW] (arrival time 68 ms) 77 CPU bursts (tau 100ms)
Process J [NEW] (arrival time 0 ms) 10 CPU bursts (tau 100ms)
Process K [NEW] (arrival time 7 ms) 13 CPU bursts (tau 100ms)
Process L [NEW] (arrival time 189 ms) 7 CPU bursts (tau 100ms)
Process M [NEW] (arrival time 16 ms) 48 CPU bursts (tau 100ms)
Process N [NEW] (arrival time 122 ms) 31 CPU bursts (tau 100ms)
Process O [NEW] (arrival time 29 ms) 31 CPU bursts (tau 100ms)
Process P [NEW] (arrival time 159 ms) 16 CPU bursts (tau 100ms)
time 0ms: Simulator started for SJF [Q <empty>]
time 0ms: Process J (tau 100ms) arrived; added to ready queue [Q J]
time 2ms: Process J (tau 100ms) started using the CPU for 40ms burst [Q <empty>]
time 7ms: Process K (tau 100ms) arrived; added to ready queue [Q K]
time 9ms: Process A (tau 100ms) arrived; added to ready queue [Q A K]
time 11ms: Process H (tau 100ms) arrived; added to ready queue [Q A H K]
time 16ms: Process M (tau 100ms) arrived; added to ready queue [Q A H K M]
time 18ms: Process B (tau 100ms) arrived; added to ready queue [Q A B H K M]
time 29ms: Process O (tau 100ms) arrived; added to ready queue [Q A B H K M O]
time 42ms: Process J (tau 100ms) completed a CPU burst; 9 bursts to go [Q A B H K M O]
time 42ms: Recalculated tau = 70ms for process J [Q A B H K M O]
time 42ms: Process J switching out of CPU; will block on I/O until time 47ms [Q A B H K M O]
time 42ms: Process C (tau 100ms) arrived; added to ready queue [Q A B C H K M O]
time 46ms: Process A (tau 100ms) started using the CPU for 56ms burst [Q B C H K M O]
time 47ms: Process J (tau 70ms) completed I/O; added to ready queue [Q J B C H K M O]
time 65ms: Process G (tau 100ms) arrived; added to ready queue [Q J B C G H K M O]
time 68ms: Process I (tau 100ms) arrived; added to ready queue [Q J B C G H I K M O]
time 102ms: Process A (tau 100ms) completed a CPU burst; 15 bursts to go [Q J B C G H I K M O]
time 102ms: Recalculated tau = 78ms for process A [Q J B C G H I K M O]
time 102ms: Process A switching out of CPU; will block on I/O until time 127ms [Q J B C G H I K M O]
time 106ms: Process J (tau 70ms) started using the CPU for 204ms burst [Q B C G H I K M O]
time 106ms: Process F (tau 100ms) arrived; added to ready queue [Q B C F G H I K M O]
time 122ms: Process N (tau 100ms) arrived; added to ready queue [Q B C F G H I K M N O]
time 127ms: Process A (tau 78ms) completed I/O; added to ready queue [Q A B C F G H I K M N O]
time 134ms: Process E (tau 100ms) arrived; added to ready queue [Q A B C E F G H I K M N O]
time 156ms: Process D (tau 100ms) arrived; added to ready queue [Q A B C D E F G H I K M N O]
time 159ms: Process P (tau 100ms) arrived; added to ready queue [Q A B C D E F G H I K M N O P]
time 189ms: Process L (tau 100ms) arrived; added to ready queue [Q A B C D E F G H I K L M N O P]
time 310ms: Process J (tau 70ms) completed a CPU burst; 8 bursts to go [Q A B C D E F G H I K L M N O P]
time 310ms: Recalculated tau = 137ms for process J [Q A B C D E F G H I K L M N O P]
time 310ms: Process J switching out of CPU; will block on I/O until time 382ms [Q A B C D E F G H I K L M N O P]
time 314ms: Process A (tau 78ms) started using the CPU for 60ms burst [Q B C D E F G H I K L M N O P]
time 374ms: Process A (tau 78ms) completed a CPU burst; 14 bursts to go [Q B C D E F G H I K L M N O P]
time 374ms: Recalculated tau = 69ms for process A [Q B C D E F G H I K L M N O P]
time 374ms: Process A switching out of CPU; will block on I/O until time 529ms [Q B C D E F G H I K L M N O P]
time 378ms: Process B (tau 100ms) started using the CPU for 106ms burst [Q C D E F G H I K L M N O P]
time 382ms: Process J (tau 137ms) completed I/O; added to ready queue [Q C D E F G H I K L M N O P J]
time 484ms: Process B (tau 100ms) completed a CPU burst; 20 bursts to go [Q C D E F G H I K L M N O P J]
time 484ms: Recalculated tau = 103ms for process B [Q C D E F G H I K L M N O P J]
time 484ms: Process B switching out of CPU; will block on I/O until time 642ms [Q C D E F G H I K L M N O P J]
time 488ms: Process C (tau 100ms) started using the CPU for 94ms burst [Q D E F G H I K L M N O P J]
time 529ms: Process A (tau 69ms) completed I/O; added to ready queue [Q A D E F G H I K L M N O P J]
time 582ms: Process C (tau 100ms) completed a CPU burst; 3 bursts to go [Q A D E F G H I K L M N O P J]
time 582ms: Recalculated tau = 97ms for process C [Q A D E F G H I K L M N O P J]
time 582ms: Process C switching out of CPU; will block on I/O until time 742ms [Q A D E F G H I K L M N O P J]
time 586ms: Process A (tau 69ms) started using the CPU for 39ms burst [Q D E F G H I K L M N O P J]
time 625ms: Process A (tau 69ms) completed a CPU burst; 13 bursts to go [Q D E F G H I K L M N O P J]
time 625ms: Recalculated tau = 54ms for process A [Q D E F G H I K L M N O P J]
time 625ms: Process A switching out of CPU; will block on I/O until time 677ms [Q D E F G H I K L M N O P J]
time 629ms: Process D (tau 100ms) started using the CPU for 148ms burst [Q E F G H I K L M N O P J]
time 642ms: Process B (tau 103ms) completed I/O; added to ready queue [Q E F G H I K L M N O P B J]
time 677ms: Process A (tau 54ms) completed I/O; added to ready queue [Q A E F G H I K L M N O P B J]
time 742ms: Process C (tau 97ms) completed I/O; added to ready queue [Q A C E F G H I K L M N O P B J]
time 777ms: Process D (tau 100ms) completed a CPU burst; 10 bursts to go [Q A C E F G H I K L M N O P B J]
time 777ms: Recalculated tau = 124ms for process D [Q A C E F G H I K L M N O P B J]
time 777ms: Process D switching out of CPU; will block on I/O until time 781ms [Q A C E F G H I K L M N O P B J]
time 781ms: Process A (tau 54ms) started using the CPU for 47ms burst [Q C E F G H I K L M N O P B J]
time 781ms: Process D (tau 124ms) completed I/O; added to ready queue [Q C E F G H I K L M N O P B D J]
time 828ms: Process A (tau 54ms) completed a CPU burst; 12 bursts to go [Q C E F G H I K L M N O P B D J]
time 828ms: Recalculated tau = 51ms for process A [Q C E F G H I K L M N O P B D J]
time 828ms: Process A switching out of CPU; will block on I/O until time 832ms [Q C E F G H I K L M N O P B D J]
time 832ms: Process C (tau 97ms) started using the CPU for 117ms burst [Q E F G H I K L M N O P B D J]
time 832ms: Process A (tau 51ms) completed I/O; added to ready queue [Q A E F G H I K L M N O P B D J]
time 949ms: Process C (tau 97ms) completed a CPU burst; 2 bursts to go [Q A E F G H I K L M N O P B D J]
time 949ms: Recalculated tau = 107ms for process C [Q A E F G H I K L M N O P B D J]
time 949ms: Process C switching out of CPU; will block on I/O until time 968ms [Q A E F G H I K L M N O P B D J]
time 953ms: Process A (tau 51ms) started using the CPU for 137ms burst [Q E F G H I K L M N O P B D J]
time 968ms: Process C (tau 107ms) completed I/O; added to ready queue [Q E F G H I K L M N O P B C D J]
time 6998ms: Process C terminated [Q P G F H L D E M A O J K B N I]
time 9072ms: Process L terminated [Q E G A O P F J K H B N I M D]
time 9396ms: Process A terminated [Q G E O P F J K H B N I M D]
time 11997ms: Process K terminated [Q E F P H B N I M D]
time 13746ms: Process J terminated [Q F P H B N I M D]
time 17928ms: Process P terminated [Q F H B N I M D E]
time 31125ms: Process N terminated [Q H I M O F D B E G]
time 34534ms: Process O terminated [Q H M F D B E G]
time 35998ms: Process F terminated [Q M D B E G]
time 38433ms: Process D terminated [Q B H E G I]
time 38879ms: Process M terminated [Q B H E G I]
time 42200ms: Process B terminated [Q H G E I]
time 43221ms: Process H terminated [Q G I]
time 44197ms: Process G terminated [Q I E]
time 46908ms: Process E terminated [Q I]
time 47911ms: Process I terminated [Q <empty>]
time 47913ms: Simulator ended for SJF [Q <empty>]

Process A [NEW] (arrival time 9 ms) 16 CPU bursts (tau 100ms)
Process B [NEW] (arrival time 18 ms) 21 CPU bursts (tau 100ms)
Process C [NEW] (arrival time 42 ms) 4 CPU bursts (tau 100ms)
Process D [NEW] (arrival time 156 ms) 11 CPU bursts (tau 100ms)
Process E [NEW] (arrival time 134 ms) 55 CPU bursts (tau 100ms)
Process F [NEW] (arrival time 106 ms) 34 CPU bursts (tau 100ms)
Process G [NEW] (arrival time 65 ms) 80 CPU bursts (tau 100ms)
Process H [NEW] (arrival time 11 ms) 83 CPU bursts (tau 100ms)
Process I [NEW] (arrival time 68 ms) 77 CPU bursts (tau 100ms)
Process J [NEW] (arrival time 0 ms) 10 CPU bursts (tau 100ms)
Process K [NEW] (arrival time 7 ms) 13 CPU bursts (tau 100ms)
Process L [NEW] (arrival time 189 ms) 7 CPU bursts (tau 100ms)
Process M [NEW] (arrival time 16 ms) 48 CPU bursts (tau 100ms)
Process N [NEW] (arrival time 122 ms) 31 CPU bursts (tau 100ms)
Process O [NEW] (arrival time 29 ms) 31 CPU bursts (tau 100ms)
Process P [NEW] (arrival time 159 ms) 16 CPU bursts (tau 100ms)
time 0ms: Simulator started for SRT [Q <empty>]
time 0ms: Process J (tau 100ms) arrived; added to ready queue [Q J]
time 2ms: Process J (tau 100ms) started using the CPU with 40ms burst remaining [Q <empty>]
time 7ms: Process K (tau 100ms) arrived; added to ready queue [Q K]
time 9ms: Process A (tau 100ms) arrived; added to ready queue [Q A K]
time 11ms: Process H (tau 100ms) arrived; added to ready queue [Q A H K]
time 16ms: Process M (tau 100ms) arrived; added to ready queue [Q A H K M]
time 18ms: Process B (tau 100ms) arrived; added to ready queue [Q A B H K M]
time 29ms: Process O (tau 100ms) arrived; added to ready queue [Q A B H K M O]
time 42ms: Process J (tau 100ms) completed a CPU burst; 9 bursts to go [Q A B H K M O]
time 42ms: Recalculated tau = 70ms for process J [Q A B H K M O]
time 42ms: Process J switching out of CPU; will block on I/O until time 47ms [Q A B H K M O]
time 42ms: Process C (tau 100ms) arrived; added to ready queue [Q A B C H K M O]
time 46ms: Process A (tau 100ms) started using the CPU with 56ms burst remaining [Q B C H K M O]
time 47ms: Process J (tau 70ms) completed I/O; preempting A [Q J B C H K M O]
time 51ms: Process J (tau 70ms) started using the CPU with 204ms burst remaining [Q A B C H K M O]
time 65ms: Process G (tau 100ms) arrived; added to ready queue [Q A B C G H K M O]
time 68ms: Process I (tau 100ms) arrived; added to ready queue [Q A B C G H I K M O]
time 106ms: Process F (tau 100ms) arrived; added to ready queue [Q A B C F G H I K M O]
time 122ms: Process N (tau 100ms) arrived; added to ready queue [Q A B C F G H I K M N O]
time 134ms: Process E (tau 100ms) arrived; added to ready queue [Q A B C E F G H I K M N O]
time 156ms: Process D (tau 100ms) arrived; added to ready queue [Q A B C D E F G H I K M N O]
time 159ms: Process P (tau 100ms) arrived; added to ready queue [Q A B C D E F G H I K M N O P]
time 189ms: Process L (tau 100ms) arrived; added to ready queue [Q A B C D E F G H I K L M N O P]
time 255ms: Process J (tau 70ms) completed a CPU burst; 8 bursts to go [Q A B C D E F G H I K L M N O P]
time 255ms: Recalculated tau = 137ms for process J [Q A B C D E F G H I K L M N O P]
time 255ms: Process J switching out of CPU; will block on I/O until time 327ms [Q A B C D E F G H I K L M N O P]
time 259ms: Process A (tau 100ms) started using the CPU with 55ms burst remaining [Q B C D E F G H I K L M N O P]
time 314ms: Process A (tau 100ms) completed a CPU burst; 15 bursts to go [Q B C D E F G H I K L M N O P]
time 314ms: Recalculated tau = 78ms for process A [Q B C D E F G H I K L M N O P]
time 314ms: Process A switching out of CPU; will block on I/O until time 339ms [Q B C D E F G H I K L M N O P]
time 318ms: Process B (tau 100ms) started using the CPU with 106ms burst remaining [Q C D E F G H I K L M N O P]
time 327ms: Process J (tau 137ms) completed I/O; added to ready queue [Q C D E F G H I K L M N O P J]
time 339ms: Process A (tau 78ms) completed I/O; preempting B [Q A C D E F G H I K L M N O P J]
time 343ms: Process A (tau 78ms) started using the CPU with 60ms burst remaining [Q B C D E F G H I K L M N O P J]
time 403ms: Process A (tau 78ms) completed a CPU burst; 14 bursts to go [Q B C D E F G H I K L M N O P J]
time 403ms: Recalculated tau = 69ms for process A [Q B C D E F G H I K L M N O P J]
time 403ms: Process A switching out of CPU; will block on I/O until time 558ms [Q B C D E F G H I K L M N O P J]
time 407ms: Process B (tau 100ms) started using the CPU with 85ms burst remaining [Q C D E F G H I K L M N O P J]
time 492ms: Process B (tau 100ms) completed a CPU burst; 20 bursts to go [Q C D E F G H I K L M N O P J]
time 492ms: Recalculated tau = 103ms for process B [Q C D E F G H I K L M N O P J]
time 492ms: Process B switching out of CPU; will block on I/O until time 650ms [Q C D E F G H I K L M N O P J]
time 496ms: Process C (tau 100ms) started using the CPU with 94ms burst remaining [Q D E F G H I K L M N O P J]
time 558ms: Process A (tau 69ms) completed I/O; added to ready queue [Q A D E F G H I K L M N O P J]
time 590ms: Process C (tau 100ms) completed a CPU burst; 3 bursts to go [Q A D E F G H I K L M N O P J]
time 590ms: Recalculated tau = 97ms for process C [Q A D E F G H I K L M N O P J]
time 590ms: Process C switching out of CPU; will block on I/O until time 750ms [Q A D E F G H I K L M N O P J]
time 594ms: Process A (tau 69ms) started using the CPU with 39ms burst remaining [Q D E F G H I K L M N O P J]
time 633ms: Process A (tau 69ms) completed a CPU burst; 13 bursts to go [Q D E F G H I K L M N O P J]
time 633ms: Recalculated tau = 54ms for process A [Q D E F G H I K L M N O P J]
time 633ms: Process A switching out of CPU; will block on I/O until time 685ms [Q D E F G H I K L M N O P J]
time 637ms: Process D (tau 100ms) started using the CPU with 148ms burst remaining [Q E F G H I K L M N O P J]
time 650ms: Process B (tau 103ms) completed I/O; added to ready queue [Q E F G H I K L M N O P B J]
time 685ms: Process A (tau 54ms) completed I/O; added to ready queue [Q A E F G H I K L M N O P B J]
time 750ms: Process C (tau 97ms) completed I/O; added to ready queue [Q A C E F G H I K L M N O P B J]
time 785ms: Process D (tau 100ms) completed a CPU burst; 10 bursts to go [Q A C E F G H I K L M N O P B J]
time 785ms: Recalculated tau = 124ms for process D [Q A C E F G H I K L M N O P B J]
time 785ms: Process D switching out of CPU; will block on I/O until time 789ms [Q A C E F G H I K L M N O P B J]
time 789ms: Process A (tau 54ms) started using the CPU with 47ms burst remaining [Q C E F G H I K L M N O P B J]
time 789ms: Process D (tau 124ms) completed I/O; added to ready queue [Q C E F G H I K L M N O P B D J]
time 836ms: Process A (tau 54ms) completed a CPU burst; 12 bursts to go [Q C E F G H I K L M N O P B D J]
time 836ms: Recalculated tau = 51ms for process A [Q C E F G H I K L M N O P B D J]
time 836ms: Process A switching out of CPU; will block on I/O until time 840ms [Q C E F G H I K L M N O P B D J]
time 840ms: Process C (tau 97ms) started using the CPU with 117ms burst remaining [Q E F G H I K L M N O P B D J]
time 840ms: Process A (tau 51ms) completed I/O; preempting C [Q A E F G H I K L M N O P B D J]
time 844ms: Process A (tau 51ms) started using the CPU with 137ms burst remaining [Q C E F G H I K L M N O P B D J]
time 981ms: Process A (tau 51ms) completed a CPU burst; 11 bursts to go [Q C E F G H I K L M N O P B D J]
time 981ms: Recalculated tau = 94ms for process A [Q C E F G H I K L M N O P B D J]
time 981ms: Process A switching out of CPU; will block on I/O until time 1007ms [Q C E F G H I K L M N O P B D J]
time 985ms: Process C (tau 97ms) started using the CPU with 117ms burst remaining [Q E F G H I K L M N O P B D J]
time 6984ms: Process C terminated [Q P F H L D E M A O J K B N I]
time 9479ms: Process L terminated [Q E A O P F J K H B N I M D]
time 9965ms: Process A terminated [Q E G O P F J K H B N I M D]
time 13493ms: Process K terminated [Q O E F P H B N I M D]
time 14093ms: Process J terminated [Q E F P H B N I M D]
time 20918ms: Process P terminated [Q F G B N I M O D E]
time 33079ms: Process F terminated [Q M O I D B E G]
time 33975ms: Process O terminated [Q H I M D B E G]
time 37598ms: Process M terminated [Q N H B E G]
time 37911ms: Process D terminated [Q I N H B E G]
time 38401ms: Process N terminated [Q I B E G H]
time 44685ms: Process B terminated [Q G H E I]
time 44967ms: Process G terminated [Q E I]
time 45270ms: Process H terminated [Q E I]
time 46557ms: Process E terminated [Q <empty>]
time 48963ms: Process I terminated [Q <empty>]
time 48965ms: Simulator ended for SRT [Q <empty>]

Process A [NEW] (arrival time 9 ms) 16 CPU bursts
Process B [NEW] (arrival time 18 ms) 21 CPU bursts
Process C [NEW] (arrival time 42 ms) 4 CPU bursts
Process D [NEW] (arrival time 156 ms) 11 CPU bursts
Process E [NEW] (arrival time 134 ms) 55 CPU bursts
Process F [NEW] (arrival time 106 ms) 34 CPU bursts
Process G [NEW] (arrival time 65 ms) 80 CPU bursts
Process H [NEW] (arrival time 11 ms) 83 CPU bursts
Process I [NEW] (arrival time 68 ms) 77 CPU bursts
Process J [NEW] (arrival time 0 ms) 10 CPU bursts
Process K [NEW] (arrival time 7 ms) 13 CPU bursts
Process L [NEW] (arrival time 189 ms) 7 CPU bursts
Process M [NEW] (arrival time 16 ms) 48 CPU bursts
Process N [NEW] (arrival time 122 ms) 31 CPU bursts
Process O [NEW] (arrival time 29 ms) 31 CPU bursts
Process P [NEW] (arrival time 159 ms) 16 CPU bursts
time 0ms: Simulator started for RR [Q <empty>]
time 0ms: Process J arrived; added to ready queue [Q J]
time 2ms: Process J started using the CPU for 40ms burst [Q <empty>]
time 7ms: Process K arrived; added to ready queue [Q K]
time 9ms: Process A arrived; added to ready queue [Q K A]
time 11ms: Process H arrived; added to ready queue [Q K A H]
time 16ms: Process M arrived; added to ready queue [Q K A H M]
time 18ms: Process B arrived; added to ready queue [Q K A H M B]
time 29ms: Process O arrived; added to ready queue [Q K A H M B O]
time 42ms: Process J completed a CPU burst; 9 bursts to go [Q K A H M B O]
time 42ms: Process J switching out of CPU; will block on I/O until time 47ms [Q K A H M B O]
time 42ms: Process C arrived; added to ready queue [Q K A H M B O C]
time 46ms: Process K started using the CPU for 64ms burst [Q A H M B O C]
time 47ms: Process J completed I/O; added to ready queue [Q A H M B O C J]
time 65ms: Process G arrived; added to ready queue [Q A H M B O C J G]
time 68ms: Process I arrived; added to ready queue [Q A H M B O C J G I]
time 106ms: Process F arrived; added to ready queue [Q A H M B O C J G I F]
time 110ms: Process K completed a CPU burst; 12 bursts to go [Q A H M B O C J G I F]
time 110ms: Process K switching out of CPU; will block on I/O until time 208ms [Q A H M B O C J G I F]
time 114ms: Process A started using the CPU for 56ms burst [Q H M B O C J G I F]
time 122ms: Process N arrived; added to ready queue [Q H M B O C J G I F N]
time 134ms: Process E arrived; added to ready queue [Q H M B O C J G I F N E]
time 156ms: Process D arrived; added to ready queue [Q H M B O C J G I F N E D]
time 159ms: Process P arrived; added to ready queue [Q H M B O C J G I F N E D P]
time 170ms: Process A completed a CPU burst; 15 bursts to go [Q H M B O C J G I F N E D P]
time 170ms: Process A switching out of CPU; will block on I/O until time 195ms [Q H M B O C J G I F N E D P]
time 174ms: Process H started using the CPU for 96ms burst [Q M B O C J G I F N E D P]
time 189ms: Process L arrived; added to ready queue [Q M B O C J G I F N E D P L]
time 195ms: Process A completed I/O; added to ready queue [Q M B O C J G I F N E D P L A]
time 208ms: Process K completed I/O; added to ready queue [Q M B O C J G I F N E D P L A K]
time 270ms: Process H completed a CPU burst; 82 bursts to go [Q M B O C J G I F N E D P L A K]
time 270ms: Process H switching out of CPU; will block on I/O until time 339ms [Q M B O C J G I F N E D P L A K]
time 274ms: Process M started using the CPU for 22ms burst [Q B O C J G I F N E D P L A K]
time 296ms: Process M completed a CPU burst; 47 bursts to go [Q B O C J G I F N E D P L A K]
time 296ms: Process M switching out of CPU; will block on I/O until time 315ms [Q B O C J G I F N E D P L A K]
time 300ms: Process B started using the CPU for 106ms burst [Q O C J G I F N E D P L A K]
time 315ms: Process M completed I/O; added to ready queue [Q O C J G I F N E D P L A K M]
time 339ms: Process H completed I/O; added to ready queue [Q O C J G I F N E D P L A K M H]
time 406ms: Process B completed a CPU burst; 20 bursts to go [Q O C J G I F N E D P L A K M H]
time 406ms: Process B switching out of CPU; will block on I/O until time 564ms [Q O C J G I F N E D P L A K M H]
time 410ms: Process O started using the CPU for 156ms burst [Q C J G I F N E D P L A K M H]
time 538ms: Time slice expired; process O preempted with 28ms to go [Q C J G I F N E D P L A K M H]
time 542ms: Process C started using the CPU for 94ms burst [Q J G I F N E D P L A K M H O]
time 564ms: Process B completed I/O; added to ready queue [Q J G I F N E D P L A K M H O B]
time 636ms: Process C completed a CPU burst; 3 bursts to go [Q J G I F N E D P L A K M H O B]
time 636ms: Process C switching out of CPU; will block on I/O until time 796ms [Q J G I F N E D P L A K M H O B]
time 640ms: Process J started using the CPU for 204ms burst [Q G I F N E D P L A K M H O B]
time 768ms: Time slice expired; process J preempted with 76ms to go [Q G I F N E D P L A K M H O B]
time 772ms: Process G started using the CPU for 70ms burst [Q I F N E D P L A K M H O B J]
time 796ms: Process C completed I/O; added to ready queue [Q I F N E D P L A K M H O B J C]
time 842ms: Process G completed a CPU burst; 79 bursts to go [Q I F N E D P L A K M H O B J C]
time 842ms: Process G switching out of CPU; will block on I/O until time 875ms [Q I F N E D P L A K M H O B J C]
time 846ms: Process I started using the CPU for 220ms burst [Q F N E D P L A K M H O B J C]
time 875ms: Process G completed I/O; added to ready queue [Q F N E D P L A K M H O B J C G]
time 974ms: Time slice expired; process I preempted with 92ms to go [Q F N E D P L A K M H O B J C G]
time 978ms: Process F started using the CPU for 129ms burst [Q N E D P L A K M H O B J C G I]
time 4100ms: Process C terminated [Q O G F N I D L E A K H P J M B]
time 9548ms: Process L terminated [Q J H K M P B O F E N A I D G]
time 10422ms: Process J terminated [Q H K M P B F O E N A]
time 14484ms: Process D terminated [Q M G K B N F P A O]
time 14563ms: Process K terminated [Q B N F P A O H M I]
time 17454ms: Process A terminated [Q N P M O G I H F B E]
time 19319ms: Process P terminated [Q M F G O B I H N]
time 25541ms: Process B terminated [Q E G O F I H N M]
time 30600ms: Process O terminated [Q G I H M E F N]
time 31921ms: Process N terminated [Q I G H M F E]
time 32705ms: Process F terminated [Q E I G H M]
time 38737ms: Process M terminated [Q E I H G]
time 40873ms: Process E terminated [Q H G I]
time 47731ms: Process G terminated [Q <empty>]
time 47834ms: Process I terminated [Q <empty>]
time 48734ms: Process H terminated [Q <empty>]
time 48736ms: Simulator ended for RR [Q <empty>]
