Process A [NEW] (arrival time 9 ms) 16 CPU bursts (tau 100ms)
Process B [NEW] (arrival time 18 ms) 21 CPU bursts (tau 100ms)
Process C [NEW] (arrival time 42 ms) 4 CPU bursts (tau 100ms)
Process D [NEW] (arrival time 156 ms) 11 CPU bursts (tau 100ms)
Process E [NEW] (arrival time 134 ms) 55 CPU bursts (tau 100ms)
Process F [NEW] (arrival time 106 ms) 34 CPU bursts (tau 100ms)
Process G [NEW] (arrival time 65 ms) 80 CPU bursts (tau 100ms)
Process H [NEW] (arrival time 11 ms) 83 CPU bursts (tau 100ms)
Process I [NEW] (arrival time 68 ms) 77 CPU bursts (tau 100ms)
Process J [NEW] (arrival time 0 ms) 10 CPU bursts (tau 100ms)
Process K [NEW] (arrival time 7 ms) 13 CPU bursts (tau 100ms)
Process L [NEW] (arrival time 189 ms) 7 CPU bursts (tau 100ms)
Process M [NEW] (arrival time 16 ms) 48 CPU bursts (tau 100ms)
Process N [NEW] (arrival time 122 ms) 31 CPU bursts (tau 100ms)
Process O [NEW] (arrival time 29 ms) 31 CPU bursts (tau 100ms)
Process P [NEW] (arrival time 159 ms) 16 CPU bursts (tau 100ms)
time 0ms: Simulator started for SJF [Q <empty>]
time 0ms: Process J (tau 100ms) arrived; added to ready queue [Q J]
time 2ms: Process J (tau 100ms) started using the CPU for 40ms burst [Q <empty>]
time 7ms: Process K (tau 100ms) arrived; added to ready queue [Q K]
time 9ms: Process A (tau 100ms) arrived; added to ready queue [Q A K]
time 11ms: Process H (tau 100ms) arrived; added to ready queue [Q A H K]
time 16ms: Process M (tau 100ms) arrived; added to ready queue [Q A H K M]
time 18ms: Process B (tau 100ms) arrived; added to ready queue [Q A B H K M]
time 29ms: Process O (tau 100ms) arrived; added to ready queue [Q A B H K M O]
time 42ms: Process J (tau 100ms) completed a CPU burst; 9 bursts to go [Q A B H K M O]
time 42ms: Recalculated tau = 70ms for process J [Q A B H K M O]
time 42ms: Process J switching out of CPU; will block on I/O until time 47ms [Q A B H K M O]
time 42ms: Process C (tau 100ms) arrived; added to ready queue [Q A B C H K M O]
time 46ms: Process A (tau 100ms) started using the CPU for 56ms burst [Q B C H K M O]
time 47ms: Process J (tau 70ms) completed I/O; added to ready queue [Q J B C H K M O]
time 65ms: Process G (tau 100ms) arrived; added to ready queue [Q J B C G H K M O]
time 68ms: Process I (tau 100ms) arrived; added to ready queue [Q J B C G H I K M O]
time 102ms: Process A (tau 100ms) completed a CPU burst; 15 bursts to go [Q J B C G H I K M O]
time 102ms: Recalculated tau = 78ms for process A [Q J B C G H I K M O]
time 102ms: Process A switching out of CPU; will block on I/O until time 127ms [Q J B C G H I K M O]
time 106ms: Process J (tau 70ms) started using the CPU for 204ms burst [Q B C G H I K M O]
time 106ms: Process F (tau 100ms) arrived; added to ready queue [Q B C F G H I K M O]
time 122ms: Process N (tau 100ms) arrived; added to ready queue [Q B C F G H I K M N O]
time 127ms: Process A (tau 78ms) completed I/O; added to ready queue [Q A B C F G H I K M N O]
time 134ms: Process E (tau 100ms) arrived; added to ready queue [Q A B C E F G H I K M N O]
time 156ms: Process D (tau 100ms) arrived; added to ready queue [Q A B C D E F G H I K M N O]
time 159ms: Process P (tau 100ms) arrived; added to ready queue [Q A B C D E F G H I K M N O P]
time 189ms: Process L (tau 100ms) arrived; added to ready queue [Q A B C D E F G H I K L M N O P]
time 310ms: Process J (tau 70ms) completed a CPU burst; 8 bursts to go [Q A B C D E F G H I K L M N O P]
time 310ms: Recalculated tau = 137ms for process J [Q A B C D E F G H I K L M N O P]
time 310ms: Process J switching out of CPU; will block on I/O until time 382ms [Q A B C D E F G H I K L M N O P]
time 314ms: Process A (tau 78ms) started using the CPU for 60ms burst [Q B C D E F G H I K L M N O P]
time 374ms: Process A (tau 78ms) completed a CPU burst; 14 bursts to go [Q B C D E F G H I K L M N O P]
time 374ms: Recalculated tau = 69ms for process A [Q B C D E F G H I K L M N O P]
time 374ms: Process A switching out of CPU; will block on I/O until time 529ms [Q B C D E F G H I K L M N O P]
time 378ms: Process B (tau 100ms) started using the CPU for 106ms burst [Q C D E F G H I K L M N O P]
time 382ms: Process J (tau 137ms) completed I/O; added to ready queue [Q C D E F G H I K L M N O P J]
time 484ms: Process B (tau 100ms) completed a CPU burst; 20 bursts to go [Q C D E F G H I K L M N O P J]
time 484ms: Recalculated tau = 103ms for process B [Q C D E F G H I K L M N O P J]
time 484ms: Process B switching out of CPU; will block on I/O until time 642ms [Q C D E F G H I K L M N O P J]
time 488ms: Process C (tau 100ms) started using the CPU for 94ms burst [Q D E F G H I K L M N O P J]
time 529ms: Process A (tau 69ms) completed I/O; added to ready queue [Q A D E F G H I K L M N O P J]
time 582ms: Process C (tau 100ms) completed a CPU burst; 3 bursts to go [Q A D E F G H I K L M N O P J]
time 582ms: Recalculated tau = 97ms for process C [Q A D E F G H I K L M N O P J]
time 582ms: Process C switching out of CPU; will block on I/O until time 742ms [Q A D E F G H I K L M N O P J]
time 586ms: Process A (tau 69ms) started using the CPU for 39ms burst [Q D E F G H I K L M N O P J]
time 625ms: Process A (tau 69ms) completed a CPU burst; 13 bursts to go [Q D E F G H I K L M N O P J]
time 625ms: Recalculated tau = 54ms for process A [Q D E F G H I K L M N O P J]
time 625ms: Process A switching out of CPU; will block on I/O until time 677ms [Q D E F G H I K L M N O P J]
time 629ms: Process D (tau 100ms) started using the CPU for 148ms burst [Q E F G H I K L M N O P J]
time 642ms: Process B (tau 103ms) completed I/O; added to ready queue [Q E F G H I K L M N O P B J]
time 677ms: Process A (tau 54ms) completed I/O; added to ready queue [Q A E F G H I K L M N O P B J]
time 742ms: Process C (tau 97ms) completed I/O; added to ready queue [Q A C E F G H I K L M N O P B J]
time 777ms: Process D (tau 100ms) completed a CPU burst; 10 bursts to go [Q A C E F G H I K L M N O P B J]
time 777ms: Recalculated tau = 124ms for process D [Q A C E F G H I K L M N O P B J]
time 777ms: Process D switching out of CPU; will block on I/O until time 781ms [Q A C E F G H I K L M N O P B J]
time 781ms: Process A (tau 54ms) started using the CPU for 47ms burst [Q C E F G H I K L M N O P B J]
time 781ms: Process D (tau 124ms) completed I/O; added to ready queue [Q C E F G H I K L M N O P B D J]
time 828ms: Process A (tau 54ms) completed a CPU burst; 12 bursts to go [Q C E F G H I K L M N O P B D J]
time 828ms: Recalculated tau = 51ms for process A [Q C E F G H I K L M N O P B D J]
time 828ms: Process A switching out of CPU; will block on I/O until time 832ms [Q C E F G H I K L M N O P B D J]
time 832ms: Process C (tau 97ms) started using the CPU for 117ms burst [Q E F G H I K L M N O P B D J]
time 832ms: Process A (tau 51ms) completed I/O; added to ready queue [Q A E F G H I K L M N O P B D J]
time 949ms: Process C (tau 97ms) completed a CPU burst; 2 bursts to go [Q A E F G H I K L M N O P B D J]
time 949ms: Recalculated tau = 107ms for process C [Q A E F G H I K L M N O P B D J]
time 949ms: Process C switching out of CPU; will block on I/O until time 968ms [Q A E F G H I K L M N O P B D J]
time 953ms: Process A (tau 51ms) started using the CPU for 137ms burst [Q E F G H I K L M N O P B D J]
time 968ms: Process C (tau 107ms) completed I/O; added to ready queue [Q E F G H I K L M N O P B C D J]
time 1090ms: Process A (tau 51ms) completed a CPU burst; 11 bursts to go [Q E F G H I K L M N O P B C D J]
time 1090ms: Recalculated tau = 94ms for process A [Q E F G H I K L M N O P B C D J]
time 1090ms: Process A switching out of CPU; will block on I/O until time 1116ms [Q E F G H I K L M N O P B C D J]
time 1094ms: Process E (tau 100ms) started using the CPU for 152ms burst [Q F G H I K L M N O P B C D J]
time 1116ms: Process A (tau 94ms) completed I/O; added to ready queue [Q A F G H I K L M N O P B C D J]
time 1246ms: Process E (tau 100ms) completed a CPU burst; 54 bursts to go [Q A F G H I K L M N O P B C D J]
time 1246ms: Recalculated tau = 126ms for process E [Q A F G H I K L M N O P B C D J]
time 1246ms: Process E switching out of CPU; will block on I/O until time 1294ms [Q A F G H I K L M N O P B C D J]
time 1250ms: Process A (tau 94ms) started using the CPU for 64ms burst [Q F G H I K L M N O P B C D J]
time 1294ms: Process E (tau 126ms) completed I/O; added to ready queue [Q F G H I K L M N O P B C D E J]
time 1314ms: Process A (tau 94ms) completed a CPU burst; 10 bursts to go [Q F G H I K L M N O P B C D E J]
time 1314ms: Recalculated tau = 79ms for process A [Q F G H I K L M N O P B C D E J]
time 1314ms: Process A switching out of CPU; will block on I/O until time 1331ms [Q F G H I K L M N O P B C D E J]
time 1318ms: Process F (tau 100ms) started using the CPU for 129ms burst [Q G H I K L M N O P B C D E J]
time 1331ms: Process A (tau 79ms) completed I/O; added to ready queue [Q A G H I K L M N O P B C D E J]
time 1447ms: Process F (tau 100ms) completed a CPU burst; 33 bursts to go [Q A G H I K L M N O P B C D E J]
time 1447ms: Recalculated tau = 115ms for process F [Q A G H I K L M N O P B C D E J]
time 1447ms: Process F switching out of CPU; will block on I/O until time 1506ms [Q A G H I K L M N O P B C D E J]
time 1451ms: Process A (tau 79ms) started using the CPU for 68ms burst [Q G H I K L M N O P B C D E J]
time 1506ms: Process F (tau 115ms) completed I/O; added to ready queue [Q G H I K L M N O P B C F D E J]
time 1519ms: Process A (tau 79ms) completed a CPU burst; 9 bursts to go [Q G H I K L M N O P B C F D E J]
time 1519ms: Recalculated tau = 74ms for process A [Q G H I K L M N O P B C F D E J]
time 1519ms: Process A switching out of CPU; will block on I/O until time 1585ms [Q G H I K L M N O P B C F D E J]
time 1523ms: Process G (tau 100ms) started using the CPU for 70ms burst [Q H I K L M N O P B C F D E J]
time 1585ms: Process A (tau 74ms) completed I/O; added to ready queue [Q A H I K L M N O P B C F D E J]
time 1593ms: Process G (tau 100ms) completed a CPU burst; 79 bursts to go [Q A H I K L M N O P B C F D E J]
time 1593ms: Recalculated tau = 85ms for process G [Q A H I K L M N O P B C F D E J]
time 1593ms: Process G switching out of CPU; will block on I/O until time 1626ms [Q A H I K L M N O P B C F D E J]
time 1597ms: Process A (tau 74ms) started using the CPU for 113ms burst [Q H I K L M N O P B C F D E J]
time 1626ms: Process G (tau 85ms) completed I/O; added to ready queue [Q G H I K L M N O P B C F D E J]
time 1710ms: Process A (tau 74ms) completed a CPU burst; 8 bursts to go [Q G H I K L M N O P B C F D E J]
time 1710ms: Recalculated tau = 94ms for process A [Q G H I K L M N O P B C F D E J]
time 1710ms: Process A switching out of CPU; will block on I/O until time 1728ms [Q G H I K L M N O P B C F D E J]
time 1714ms: Process G (tau 85ms) started using the CPU for 40ms burst [Q H I K L M N O P B C F D E J]
time 1728ms: Process A (tau 94ms) completed I/O; added to ready queue [Q A H I K L M N O P B C F D E J]
time 1754ms: Process G (tau 85ms) completed a CPU burst; 78 bursts to go [Q A H I K L M N O P B C F D E J]
time 1754ms: Recalculated tau = 63ms for process G [Q A H I K L M N O P B C F D E J]
time 1754ms: Process G switching out of CPU; will block on I/O until time 1762ms [Q A H I K L M N O P B C F D E J]
time 1758ms: Process A (tau 94ms) started using the CPU for 11ms burst [Q H I K L M N O P B C F D E J]
time 1762ms: Process G (tau 63ms) completed I/O; added to ready queue [Q G H I K L M N O P B C F D E J]
time 1769ms: Process A (tau 94ms) completed a CPU burst; 7 bursts to go [Q G H I K L M N O P B C F D E J]
time 1769ms: Recalculated tau = 53ms for process A [Q G H I K L M N O P B C F D E J]
time 1769ms: Process A switching out of CPU; will block on I/O until time 1933ms [Q G H I K L M N O P B C F D E J]
time 1773ms: Process G (tau 63ms) started using the CPU for 65ms burst [Q H I K L M N O P B C F D E J]
time 1838ms: Process G (tau 63ms) completed a CPU burst; 77 bursts to go [Q H I K L M N O P B C F D E J]
time 1838ms: Recalculated tau = 64ms for process G [Q H I K L M N O P B C F D E J]
time 1838ms: Process G switching out of CPU; will block on I/O until time 1884ms [Q H I K L M N O P B C F D E J]
time 1842ms: Process H (tau 100ms) started using the CPU for 96ms burst [Q I K L M N O P B C F D E J]
time 1884ms: Process G (tau 64ms) completed I/O; added to ready queue [Q G I K L M N O P B C F D E J]
time 1933ms: Process A (tau 53ms) completed I/O; added to ready queue [Q A G I K L M N O P B C F D E J]
time 1938ms: Process H (tau 100ms) completed a CPU burst; 82 bursts to go [Q A G I K L M N O P B C F D E J]
time 1938ms: Recalculated tau = 98ms for process H [Q A G I K L M N O P B C F D E J]
time 1938ms: Process H switching out of CPU; will block on I/O until time 2007ms [Q A G I K L M N O P B C F D E J]
time 1942ms: Process A (tau 53ms) started using the CPU for 24ms burst [Q G I K L M N O P B C F D E J]
time 1966ms: Process A (tau 53ms) completed a CPU burst; 6 bursts to go [Q G I K L M N O P B C F D E J]
time 1966ms: Recalculated tau = 39ms for process A [Q G I K L M N O P B C F D E J]
time 1966ms: Process A switching out of CPU; will block on I/O until time 2085ms [Q G I K L M N O P B C F D E J]
time 1970ms: Process G (tau 64ms) started using the CPU for 13ms burst [Q I K L M N O P B C F D E J]
time 1983ms: Process G (tau 64ms) completed a CPU burst; 76 bursts to go [Q I K L M N O P B C F D E J]
time 1983ms: Recalculated tau = 39ms for process G [Q I K L M N O P B C F D E J]
time 1983ms: Process G switching out of CPU; will block on I/O until time 2023ms [Q I K L M N O P B C F D E J]
time 1987ms: Process I (tau 100ms) started using the CPU for 220ms burst [Q K L M N O P B C F D E J]
time 2007ms: Process H (tau 98ms) completed I/O; added to ready queue [Q H K L M N O P B C F D E J]
time 2023ms: Process G (tau 39ms) completed I/O; added to ready queue [Q G H K L M N O P B C F D E J]
time 2085ms: Process A (tau 39ms) completed I/O; added to ready queue [Q A G H K L M N O P B C F D E J]
time 2207ms: Process I (tau 100ms) completed a CPU burst; 76 bursts to go [Q A G H K L M N O P B C F D E J]
time 2207ms: Recalculated tau = 160ms for process I [Q A G H K L M N O P B C F D E J]
time 2207ms: Process I switching out of CPU; will block on I/O until time 2228ms [Q A G H K L M N O P B C F D E J]
time 2211ms: Process A (tau 39ms) started using the CPU for 76ms burst [Q G H K L M N O P B C F D E J]
time 2228ms: Process I (tau 160ms) completed I/O; added to ready queue [Q G H K L M N O P B C F D E J I]
time 2287ms: Process A (tau 39ms) completed a CPU burst; 5 bursts to go [Q G H K L M N O P B C F D E J I]
time 2287ms: Recalculated tau = 58ms for process A [Q G H K L M N O P B C F D E J I]
time 2287ms: Process A switching out of CPU; will block on I/O until time 2317ms [Q G H K L M N O P B C F D E J I]
time 2291ms: Process G (tau 39ms) started using the CPU for 128ms burst [Q H K L M N O P B C F D E J I]
time 2317ms: Process A (tau 58ms) completed I/O; added to ready queue [Q A H K L M N O P B C F D E J I]
time 2419ms: Process G (tau 39ms) completed a CPU burst; 75 bursts to go [Q A H K L M N O P B C F D E J I]
time 2419ms: Recalculated tau = 84ms for process G [Q A H K L M N O P B C F D E J I]
time 2419ms: Process G switching out of CPU; will block on I/O until time 2643ms [Q A H K L M N O P B C F D E J I]
time 2423ms: Process A (tau 58ms) started using the CPU for 122ms burst [Q H K L M N O P B C F D E J I]
time 2545ms: Process A (tau 58ms) completed a CPU burst; 4 bursts to go [Q H K L M N O P B C F D E J I]
time 2545ms: Recalculated tau = 90ms for process A [Q H K L M N O P B C F D E J I]
time 2545ms: Process A switching out of CPU; will block on I/O until time 2580ms [Q H K L M N O P B C F D E J I]
time 2549ms: Process H (tau 98ms) started using the CPU for 48ms burst [Q K L M N O P B C F D E J I]
time 2580ms: Process A (tau 90ms) completed I/O; added to ready queue [Q A K L M N O P B C F D E J I]
time 2597ms: Process H (tau 98ms) completed a CPU burst; 81 bursts to go [Q A K L M N O P B C F D E J I]
time 2597ms: Recalculated tau = 73ms for process H [Q A K L M N O P B C F D E J I]
time 2597ms: Process H switching out of CPU; will block on I/O until time 2621ms [Q A K L M N O P B C F D E J I]
time 2601ms: Process A (tau 90ms) started using the CPU for 9ms burst [Q K L M N O P B C F D E J I]
time 2610ms: Process A (tau 90ms) completed a CPU burst; 3 bursts to go [Q K L M N O P B C F D E J I]
time 2610ms: Recalculated tau = 50ms for process A [Q K L M N O P B C F D E J I]
time 2610ms: Process A switching out of CPU; will block on I/O until time 2680ms [Q K L M N O P B C F D E J I]
time 2614ms: Process K (tau 100ms) started using the CPU for 64ms burst [Q L M N O P B C F D E J I]
time 2621ms: Process H (tau 73ms) completed I/O; added to ready queue [Q H L M N O P B C F D E J I]
time 2643ms: Process G (tau 84ms) completed I/O; added to ready queue [Q H G L M N O P B C F D E J I]
time 2678ms: Process K (tau 100ms) completed a CPU burst; 12 bursts to go [Q H G L M N O P B C F D E J I]
time 2678ms: Recalculated tau = 82ms for process K [Q H G L M N O P B C F D E J I]
time 2678ms: Process K switching out of CPU; will block on I/O until time 2776ms [Q H G L M N O P B C F D E J I]
time 2680ms: Process A (tau 50ms) completed I/O; added to ready queue [Q A H G L M N O P B C F D E J I]
time 2682ms: Process A (tau 50ms) started using the CPU for 62ms burst [Q H G L M N O P B C F D E J I]
time 2744ms: Process A (tau 50ms) completed a CPU burst; 2 bursts to go [Q H G L M N O P B C F D E J I]
time 2744ms: Recalculated tau = 56ms for process A [Q H G L M N O P B C F D E J I]
time 2744ms: Process A switching out of CPU; will block on I/O until time 2823ms [Q H G L M N O P B C F D E J I]
time 2748ms: Process H (tau 73ms) started using the CPU for 72ms burst [Q G L M N O P B C F D E J I]
time 2776ms: Process K (tau 82ms) completed I/O; added to ready queue [Q K G L M N O P B C F D E J I]
time 2820ms: Process H (tau 73ms) completed a CPU burst; 80 bursts to go [Q K G L M N O P B C F D E J I]
time 2820ms: Recalculated tau = 73ms for process H [Q K G L M N O P B C F D E J I]
time 2820ms: Process H switching out of CPU; will block on I/O until time 2864ms [Q K G L M N O P B C F D E J I]
time 2823ms: Process A (tau 56ms) completed I/O; added to ready queue [Q A G L M N O P B C F D E J I]
time 2824ms: Process K (tau 82ms) started using the CPU for 56ms burst [Q A G L M N O P B C F D E J I]
time 2864ms: Process H (tau 73ms) completed I/O; added to ready queue [Q A H G L M N O P B C F D E J I]
time 2880ms: Process K (tau 82ms) completed a CPU burst; 11 bursts to go [Q A H G L M N O P B C F D E J I]
time 2880ms: Recalculated tau = 69ms for process K [Q A H G L M N O P B C F D E J I]
time 2880ms: Process K switching out of CPU; will block on I/O until time 2955ms [Q A H G L M N O P B C F D E J I]
time 2884ms: Process A (tau 56ms) started using the CPU for 200ms burst [Q H G L M N O P B C F D E J I]
time 2955ms: Process K (tau 69ms) completed I/O; added to ready queue [Q K H G L M N O P B C F D E J I]
time 3084ms: Process A (tau 56ms) completed a CPU burst; 1 burst to go [Q K H G L M N O P B C F D E J I]
time 3084ms: Recalculated tau = 128ms for process A [Q K H G L M N O P B C F D E J I]
time 3084ms: Process A switching out of CPU; will block on I/O until time 3097ms [Q K H G L M N O P B C F D E J I]
time 3088ms: Process K (tau 69ms) started using the CPU for 6ms burst [Q H G L M N O P B C F D E J I]
time 3094ms: Process K (tau 69ms) completed a CPU burst; 10 bursts to go [Q H G L M N O P B C F D E J I]
time 3094ms: Recalculated tau = 38ms for process K [Q H G L M N O P B C F D E J I]
time 3094ms: Process K switching out of CPU; will block on I/O until time 3166ms [Q H G L M N O P B C F D E J I]
time 3097ms: Process A (tau 128ms) completed I/O; added to ready queue [Q G L M N O P B C F D E A J I]
time 3098ms: Process H (tau 73ms) started using the CPU for 12ms burst [Q G L M N O P B C F D E A J I]
time 3110ms: Process H (tau 73ms) completed a CPU burst; 79 bursts to go [Q G L M N O P B C F D E A J I]
time 3110ms: Recalculated tau = 43ms for process H [Q G L M N O P B C F D E A J I]
time 3110ms: Process H switching out of CPU; will block on I/O until time 3125ms [Q G L M N O P B C F D E A J I]
time 3114ms: Process G (tau 84ms) started using the CPU for 15ms burst [Q L M N O P B C F D E A J I]
time 3125ms: Process H (tau 43ms) completed I/O; added to ready queue [Q H L M N O P B C F D E A J I]
time 3129ms: Process G (tau 84ms) completed a CPU burst; 74 bursts to go [Q H L M N O P B C F D E A J I]
time 3129ms: Recalculated tau = 50ms for process G [Q H L M N O P B C F D E A J I]
time 3129ms: Process G switching out of CPU; will block on I/O until time 3225ms [Q H L M N O P B C F D E A J I]
time 3133ms: Process H (tau 43ms) started using the CPU for 41ms burst [Q L M N O P B C F D E A J I]
time 3166ms: Process K (tau 38ms) completed I/O; added to ready queue [Q K L M N O P B C F D E A J I]
time 3174ms: Process H (tau 43ms) completed a CPU burst; 78 bursts to go [Q K L M N O P B C F D E A J I]
time 3174ms: Recalculated tau = 42ms for process H [Q K L M N O P B C F D E A J I]
time 3174ms: Process H switching out of CPU; will block on I/O until time 3197ms [Q K L M N O P B C F D E A J I]
time 3178ms: Process K (tau 38ms) started using the CPU for 6ms burst [Q L M N O P B C F D E A J I]
time 3184ms: Process K (tau 38ms) completed a CPU burst; 9 bursts to go [Q L M N O P B C F D E A J I]
time 3184ms: Recalculated tau = 22ms for process K [Q L M N O P B C F D E A J I]
time 3184ms: Process K switching out of CPU; will block on I/O until time 3261ms [Q L M N O P B C F D E A J I]
time 3188ms: Process L (tau 100ms) started using the CPU for 135ms burst [Q M N O P B C F D E A J I]
time 3197ms: Process H (tau 42ms) completed I/O; added to ready queue [Q H M N O P B C F D E A J I]
time 3225ms: Process G (tau 50ms) completed I/O; added to ready queue [Q H G M N O P B C F D E A J I]
time 3261ms: Process K (tau 22ms) completed I/O; added to ready queue [Q K H G M N O P B C F D E A J I]
time 3323ms: Process L (tau 100ms) completed a CPU burst; 6 bursts to go [Q K H G M N O P B C F D E A J I]
time 3323ms: Recalculated tau = 118ms for process L [Q K H G M N O P B C F D E A J I]
time 3323ms: Process L switching out of CPU; will block on I/O until time 3399ms [Q K H G M N O P B C F D E A J I]
time 3327ms: Process K (tau 22ms) started using the CPU for 157ms burst [Q H G M N O P B C F D E A J I]
time 3399ms: Process L (tau 118ms) completed I/O; added to ready queue [Q H G M N O P B C F L D E A J I]
time 3484ms: Process K (tau 22ms) completed a CPU burst; 8 bursts to go [Q H G M N O P B C F L D E A J I]
time 3484ms: Recalculated tau = 90ms for process K [Q H G M N O P B C F L D E A J I]
time 3484ms: Process K switching out of CPU; will block on I/O until time 3502ms [Q H G M N O P B C F L D E A J I]
time 3488ms: Process H (tau 42ms) started using the CPU for 160ms burst [Q G M N O P B C F L D E A J I]
time 3502ms: Process K (tau 90ms) completed I/O; added to ready queue [Q G K M N O P B C F L D E A J I]
time 3648ms: Process H (tau 42ms) completed a CPU burst; 77 bursts to go [Q G K M N O P B C F L D E A J I]
time 3648ms: Recalculated tau = 101ms for process H [Q G K M N O P B C F L D E A J I]
time 3648ms: Process H switching out of CPU; will block on I/O until time 3710ms [Q G K M N O P B C F L D E A J I]
time 3652ms: Process G (tau 50ms) started using the CPU for 112ms burst [Q K M N O P B C F L D E A J I]
time 3710ms: Process H (tau 101ms) completed I/O; added to ready queue [Q K M N O P H B C F L D E A J I]
time 3764ms: Process G (tau 50ms) completed a CPU burst; 73 bursts to go [Q K M N O P H B C F L D E A J I]
time 3764ms: Recalculated tau = 81ms for process G [Q K M N O P H B C F L D E A J I]
time 3764ms: Process G switching out of CPU; will block on I/O until time 3809ms [Q K M N O P H B C F L D E A J I]
time 3768ms: Process K (tau 90ms) started using the CPU for 104ms burst [Q M N O P H B C F L D E A J I]
time 3809ms: Process G (tau 81ms) completed I/O; added to ready queue [Q G M N O P H B C F L D E A J I]
time 3872ms: Process K (tau 90ms) completed a CPU burst; 7 bursts to go [Q G M N O P H B C F L D E A J I]
time 3872ms: Recalculated tau = 97ms for process K [Q G M N O P H B C F L D E A J I]
time 3872ms: Process K switching out of CPU; will block on I/O until time 4019ms [Q G M N O P H B C F L D E A J I]
time 3876ms: Process G (tau 81ms) started using the CPU for 30ms burst [Q M N O P H B C F L D E A J I]
time 3906ms: Process G (tau 81ms) completed a CPU burst; 72 bursts to go [Q M N O P H B C F L D E A J I]
time 3906ms: Recalculated tau = 56ms for process G [Q M N O P H B C F L D E A J I]
time 3906ms: Process G switching out of CPU; will block on I/O until time 3955ms [Q M N O P H B C F L D E A J I]
time 3910ms: Process M (tau 100ms) started using the CPU for 22ms burst [Q N O P H B C F L D E A J I]
time 3932ms: Process M (tau 100ms) completed a CPU burst; 47 bursts to go [Q N O P H B C F L D E A J I]
time 3932ms: Recalculated tau = 61ms for process M [Q N O P H B C F L D E A J I]
time 3932ms: Process M switching out of CPU; will block on I/O until time 3951ms [Q N O P H B C F L D E A J I]
time 3936ms: Process N (tau 100ms) started using the CPU for 213ms burst [Q O P H B C F L D E A J I]
time 3951ms: Process M (tau 61ms) completed I/O; added to ready queue [Q M O P H B C F L D E A J I]
time 3955ms: Process G (tau 56ms) completed I/O; added to ready queue [Q G M O P H B C F L D E A J I]
time 4019ms: Process K (tau 97ms) completed I/O; added to ready queue [Q G M K O P H B C F L D E A J I]
time 4149ms: Process N (tau 100ms) completed a CPU burst; 30 bursts to go [Q G M K O P H B C F L D E A J I]
time 4149ms: Recalculated tau = 157ms for process N [Q G M K O P H B C F L D E A J I]
time 4149ms: Process N switching out of CPU; will block on I/O until time 4166ms [Q G M K O P H B C F L D E A J I]
time 4153ms: Process G (tau 56ms) started using the CPU for 50ms burst [Q M K O P H B C F L D E A J I]
time 4166ms: Process N (tau 157ms) completed I/O; added to ready queue [Q M K O P H B C F L D E A J N I]
time 4203ms: Process G (tau 56ms) completed a CPU burst; 71 bursts to go [Q M K O P H B C F L D E A J N I]
time 4203ms: Recalculated tau = 53ms for process G [Q M K O P H B C F L D E A J N I]
time 4203ms: Process G switching out of CPU; will block on I/O until time 4425ms [Q M K O P H B C F L D E A J N I]
time 4207ms: Process M (tau 61ms) started using the CPU for 93ms burst [Q K O P H B C F L D E A J N I]
time 4300ms: Process M (tau 61ms) completed a CPU burst; 46 bursts to go [Q K O P H B C F L D E A J N I]
time 4300ms: Recalculated tau = 77ms for process M [Q K O P H B C F L D E A J N I]
time 4300ms: Process M switching out of CPU; will block on I/O until time 4344ms [Q K O P H B C F L D E A J N I]
time 4304ms: Process K (tau 97ms) started using the CPU for 86ms burst [Q O P H B C F L D E A J N I]
time 4344ms: Process M (tau 77ms) completed I/O; added to ready queue [Q M O P H B C F L D E A J N I]
time 4390ms: Process K (tau 97ms) completed a CPU burst; 6 bursts to go [Q M O P H B C F L D E A J N I]
time 4390ms: Recalculated tau = 92ms for process K [Q M O P H B C F L D E A J N I]
time 4390ms: Process K switching out of CPU; will block on I/O until time 4420ms [Q M O P H B C F L D E A J N I]
time 4394ms: Process M (tau 77ms) started using the CPU for 79ms burst [Q O P H B C F L D E A J N I]
time 4420ms: Process K (tau 92ms) completed I/O; added to ready queue [Q K O P H B C F L D E A J N I]
time 4425ms: Process G (tau 53ms) completed I/O; added to ready queue [Q G K O P H B C F L D E A J N I]
time 4473ms: Process M (tau 77ms) completed a CPU burst; 45 bursts to go [Q G K O P H B C F L D E A J N I]
time 4473ms: Recalculated tau = 78ms for process M [Q G K O P H B C F L D E A J N I]
time 4473ms: Process M switching out of CPU; will block on I/O until time 4589ms [Q G K O P H B C F L D E A J N I]
time 4477ms: Process G (tau 53ms) started using the CPU for 5ms burst [Q K O P H B C F L D E A J N I]
time 4482ms: Process G (tau 53ms) completed a CPU burst; 70 bursts to go [Q K O P H B C F L D E A J N I]
time 4482ms: Recalculated tau = 29ms for process G [Q K O P H B C F L D E A J N I]
time 4482ms: Process G switching out of CPU; will block on I/O until time 4682ms [Q K O P H B C F L D E A J N I]
time 4486ms: Process K (tau 92ms) started using the CPU for 50ms burst [Q O P H B C F L D E A J N I]
time 4536ms: Process K (tau 92ms) completed a CPU burst; 5 bursts to go [Q O P H B C F L D E A J N I]
time 4536ms: Recalculated tau = 71ms for process K [Q O P H B C F L D E A J N I]
time 4536ms: Process K switching out of CPU; will block on I/O until time 4588ms [Q O P H B C F L D E A J N I]
time 4540ms: Process O (tau 100ms) started using the CPU for 156ms burst [Q P H B C F L D E A J N I]
time 4588ms: Process K (tau 71ms) completed I/O; added to ready queue [Q K P H B C F L D E A J N I]
time 4589ms: Process M (tau 78ms) completed I/O; added to ready queue [Q K M P H B C F L D E A J N I]
time 4682ms: Process G (tau 29ms) completed I/O; added to ready queue [Q G K M P H B C F L D E A J N I]
time 4696ms: Process O (tau 100ms) completed a CPU burst; 30 bursts to go [Q G K M P H B C F L D E A J N I]
time 4696ms: Recalculated tau = 128ms for process O [Q G K M P H B C F L D E A J N I]
time 4696ms: Process O switching out of CPU; will block on I/O until time 4765ms [Q G K M P H B C F L D E A J N I]
time 4700ms: Process G (tau 29ms) started using the CPU for 122ms burst [Q K M P H B C F L D E A J N I]
time 4765ms: Process O (tau 128ms) completed I/O; added to ready queue [Q K M P H B C F L D E A O J N I]
time 4822ms: Process G (tau 29ms) completed a CPU burst; 69 bursts to go [Q K M P H B C F L D E A O J N I]
time 4822ms: Recalculated tau = 76ms for process G [Q K M P H B C F L D E A O J N I]
time 4822ms: Process G switching out of CPU; will block on I/O until time 4859ms [Q K M P H B C F L D E A O J N I]
time 4826ms: Process K (tau 71ms) started using the CPU for 4ms burst [Q M P H B C F L D E A O J N I]
time 4830ms: Process K (tau 71ms) completed a CPU burst; 4 bursts to go [Q M P H B C F L D E A O J N I]
time 4830ms: Recalculated tau = 38ms for process K [Q M P H B C F L D E A O J N I]
time 4830ms: Process K switching out of CPU; will block on I/O until time 4892ms [Q M P H B C F L D E A O J N I]
time 4834ms: Process M (tau 78ms) started using the CPU for 18ms burst [Q P H B C F L D E A O J N I]
time 4852ms: Process M (tau 78ms) completed a CPU burst; 44 bursts to go [Q P H B C F L D E A O J N I]
time 4852ms: Recalculated tau = 48ms for process M [Q P H B C F L D E A O J N I]
time 4852ms: Process M switching out of CPU; will block on I/O until time 5051ms [Q P H B C F L D E A O J N I]
time 4856ms: Process P (tau 100ms) started using the CPU for 4ms burst [Q H B C F L D E A O J N I]
time 4859ms: Process G (tau 76ms) completed I/O; added to ready queue [Q G H B C F L D E A O J N I]
time 4860ms: Process P (tau 100ms) completed a CPU burst; 15 bursts to go [Q G H B C F L D E A O J N I]
time 4860ms: Recalculated tau = 52ms for process P [Q G H B C F L D E A O J N I]
time 4860ms: Process P switching out of CPU; will block on I/O until time 5047ms [Q G H B C F L D E A O J N I]
time 4864ms: Process G (tau 76ms) started using the CPU for 31ms burst [Q H B C F L D E A O J N I]
time 4892ms: Process K (tau 38ms) completed I/O; added to ready queue [Q K H B C F L D E A O J N I]
time 4895ms: Process G (tau 76ms) completed a CPU burst; 68 bursts to go [Q K H B C F L D E A O J N I]
time 4895ms: Recalculated tau = 54ms for process G [Q K H B C F L D E A O J N I]
time 4895ms: Process G switching out of CPU; will block on I/O until time 4904ms [Q K H B C F L D E A O J N I]
time 4899ms: Process K (tau 38ms) started using the CPU for 21ms burst [Q H B C F L D E A O J N I]
time 4904ms: Process G (tau 54ms) completed I/O; added to ready queue [Q G H B C F L D E A O J N I]
time 4920ms: Process K (tau 38ms) completed a CPU burst; 3 bursts to go [Q G H B C F L D E A O J N I]
time 4920ms: Recalculated tau = 30ms for process K [Q G H B C F L D E A O J N I]
time 4920ms: Process K switching out of CPU; will block on I/O until time 4987ms [Q G H B C F L D E A O J N I]
time 4924ms: Process G (tau 54ms) started using the CPU for 61ms burst [Q H B C F L D E A O J N I]
time 4985ms: Process G (tau 54ms) completed a CPU burst; 67 bursts to go [Q H B C F L D E A O J N I]
time 4985ms: Recalculated tau = 58ms for process G [Q H B C F L D E A O J N I]
time 4985ms: Process G switching out of CPU; will block on I/O until time 5061ms [Q H B C F L D E A O J N I]
time 4987ms: Process K (tau 30ms) completed I/O; added to ready queue [Q K H B C F L D E A O J N I]
time 4989ms: Process K (tau 30ms) started using the CPU for 120ms burst [Q H B C F L D E A O J N I]
time 5047ms: Process P (tau 52ms) completed I/O; added to ready queue [Q P H B C F L D E A O J N I]
time 5051ms: Process M (tau 48ms) completed I/O; added to ready queue [Q M P H B C F L D E A O J N I]
time 5061ms: Process G (tau 58ms) completed I/O; added to ready queue [Q M P G H B C F L D E A O J N I]
time 5109ms: Process K (tau 30ms) completed a CPU burst; 2 bursts to go [Q M P G H B C F L D E A O J N I]
time 5109ms: Recalculated tau = 75ms for process K [Q M P G H B C F L D E A O J N I]
time 5109ms: Process K switching out of CPU; will block on I/O until time 5180ms [Q M P G H B C F L D E A O J N I]
time 5113ms: Process M (tau 48ms) started using the CPU for 66ms burst [Q P G H B C F L D E A O J N I]
time 5179ms: Process M (tau 48ms) completed a CPU burst; 43 bursts to go [Q P G H B C F L D E A O J N I]
time 5179ms: Recalculated tau = 57ms for process M [Q P G H B C F L D E A O J N I]
time 5179ms: Process M switching out of CPU; will block on I/O until time 5362ms [Q P G H B C F L D E A O J N I]
time 5180ms: Process K (tau 75ms) completed I/O; added to ready queue [Q P G K H B C F L D E A O J N I]
time 5183ms: Process P (tau 52ms) started using the CPU for 52ms burst [Q G K H B C F L D E A O J N I]
time 5235ms: Process P (tau 52ms) completed a CPU burst; 14 bursts to go [Q G K H B C F L D E A O J N I]
time 5235ms: Recalculated tau = 52ms for process P [Q G K H B C F L D E A O J N I]
time 5235ms: Process P switching out of CPU; will block on I/O until time 5346ms [Q G K H B C F L D E A O J N I]
time 5239ms: Process G (tau 58ms) started using the CPU for 7ms burst [Q K H B C F L D E A O J N I]
time 5246ms: Process G (tau 58ms) completed a CPU burst; 66 bursts to go [Q K H B C F L D E A O J N I]
time 5246ms: Recalculated tau = 33ms for process G [Q K H B C F L D E A O J N I]
time 5246ms: Process G switching out of CPU; will block on I/O until time 5412ms [Q K H B C F L D E A O J N I]
time 5250ms: Process K (tau 75ms) started using the CPU for 199ms burst [Q H B C F L D E A O J N I]
time 5346ms: Process P (tau 52ms) completed I/O; added to ready queue [Q P H B C F L D E A O J N I]
time 5362ms: Process M (tau 57ms) completed I/O; added to ready queue [Q P M H B C F L D E A O J N I]
time 5412ms: Process G (tau 33ms) completed I/O; added to ready queue [Q G P M H B C F L D E A O J N I]
time 5449ms: Process K (tau 75ms) completed a CPU burst; 1 burst to go [Q G P M H B C F L D E A O J N I]
time 5449ms: Recalculated tau = 137ms for process K [Q G P M H B C F L D E A O J N I]
time 5449ms: Process K switching out of CPU; will block on I/O until time 5516ms [Q G P M H B C F L D E A O J N I]
time 5453ms: Process G (tau 33ms) started using the CPU for 2ms burst [Q P M H B C F L D E A O J N I]
time 5455ms: Process G (tau 33ms) completed a CPU burst; 65 bursts to go [Q P M H B C F L D E A O J N I]
time 5455ms: Recalculated tau = 18ms for process G [Q P M H B C F L D E A O J N I]
time 5455ms: Process G switching out of CPU; will block on I/O until time 5468ms [Q P M H B C F L D E A O J N I]
time 5459ms: Process P (tau 52ms) started using the CPU for 56ms burst [Q M H B C F L D E A O J N I]
time 5468ms: Process G (tau 18ms) completed I/O; added to ready queue [Q G M H B C F L D E A O J N I]
time 5515ms: Process P (tau 52ms) completed a CPU burst; 13 bursts to go [Q G M H B C F L D E A O J N I]
time 5515ms: Recalculated tau = 54ms for process P [Q G M H B C F L D E A O J N I]
time 5515ms: Process P switching out of CPU; will block on I/O until time 5638ms [Q G M H B C F L D E A O J N I]
time 5516ms: Process K (tau 137ms) completed I/O; added to ready queue [Q G M H B C F L D E A O J K N I]
time 5519ms: Process G (tau 18ms) started using the CPU for 209ms burst [Q M H B C F L D E A O J K N I]
time 5638ms: Process P (tau 54ms) completed I/O; added to ready queue [Q P M H B C F L D E A O J K N I]
time 5728ms: Process G (tau 18ms) completed a CPU burst; 64 bursts to go [Q P M H B C F L D E A O J K N I]
time 5728ms: Recalculated tau = 114ms for process G [Q P M H B C F L D E A O J K N I]
time 5728ms: Process G switching out of CPU; will block on I/O until time 5778ms [Q P M H B C F L D E A O J K N I]
time 5732ms: Process P (tau 54ms) started using the CPU for 155ms burst [Q M H B C F L D E A O J K N I]
time 5778ms: Process G (tau 114ms) completed I/O; added to ready queue [Q M H B C G F L D E A O J K N I]
time 5887ms: Process P (tau 54ms) completed a CPU burst; 12 bursts to go [Q M H B C G F L D E A O J K N I]
time 5887ms: Recalculated tau = 105ms for process P [Q M H B C G F L D E A O J K N I]
time 5887ms: Process P switching out of CPU; will block on I/O until time 6007ms [Q M H B C G F L D E A O J K N I]
time 5891ms: Process M (tau 57ms) started using the CPU for 103ms burst [Q H B C G F L D E A O J K N I]
time 5994ms: Process M (tau 57ms) completed a CPU burst; 42 bursts to go [Q H B C G F L D E A O J K N I]
time 5994ms: Recalculated tau = 80ms for process M [Q H B C G F L D E A O J K N I]
time 5994ms: Process M switching out of CPU; will block on I/O until time 6036ms [Q H B C G F L D E A O J K N I]
time 5998ms: Process H (tau 101ms) started using the CPU for 28ms burst [Q B C G F L D E A O J K N I]
time 6007ms: Process P (tau 105ms) completed I/O; added to ready queue [Q B P C G F L D E A O J K N I]
time 6026ms: Process H (tau 101ms) completed a CPU burst; 76 bursts to go [Q B P C G F L D E A O J K N I]
time 6026ms: Recalculated tau = 65ms for process H [Q B P C G F L D E A O J K N I]
time 6026ms: Process H switching out of CPU; will block on I/O until time 6124ms [Q B P C G F L D E A O J K N I]
time 6030ms: Process B (tau 103ms) started using the CPU for 198ms burst [Q P C G F L D E A O J K N I]
time 6036ms: Process M (tau 80ms) completed I/O; added to ready queue [Q M P C G F L D E A O J K N I]
time 6124ms: Process H (tau 65ms) completed I/O; added to ready queue [Q H M P C G F L D E A O J K N I]
time 6228ms: Process B (tau 103ms) completed a CPU burst; 19 bursts to go [Q H M P C G F L D E A O J K N I]
time 6228ms: Recalculated tau = 151ms for process B [Q H M P C G F L D E A O J K N I]
time 6228ms: Process B switching out of CPU; will block on I/O until time 6343ms [Q H M P C G F L D E A O J K N I]
time 6232ms: Process H (tau 65ms) started using the CPU for 51ms burst [Q M P C G F L D E A O J K N I]
time 6283ms: Process H (tau 65ms) completed a CPU burst; 75 bursts to go [Q M P C G F L D E A O J K N I]
time 6283ms: Recalculated tau = 58ms for process H [Q M P C G F L D E A O J K N I]
time 6283ms: Process H switching out of CPU; will block on I/O until time 6308ms [Q M P C G F L D E A O J K N I]
time 6287ms: Process M (tau 80ms) started using the CPU for 171ms burst [Q P C G F L D E A O J K N I]
time 6308ms: Process H (tau 58ms) completed I/O; added to ready queue [Q H P C G F L D E A O J K N I]
time 6343ms: Process B (tau 151ms) completed I/O; added to ready queue [Q H P C G F L D E A O J K B N I]
time 6458ms: Process M (tau 80ms) completed a CPU burst; 41 bursts to go [Q H P C G F L D E A O J K B N I]
time 6458ms: Recalculated tau = 126ms for process M [Q H P C G F L D E A O J K B N I]
time 6458ms: Process M switching out of CPU; will block on I/O until time 6481ms [Q H P C G F L D E A O J K B N I]
time 6462ms: Process H (tau 58ms) started using the CPU for 87ms burst [Q P C G F L D E A O J K B N I]
time 6481ms: Process M (tau 126ms) completed I/O; added to ready queue [Q P C G F L D E M A O J K B N I]
time 6549ms: Process H (tau 58ms) completed a CPU burst; 74 bursts to go [Q P C G F L D E M A O J K B N I]
time 6549ms: Recalculated tau = 73ms for process H [Q P C G F L D E M A O J K B N I]
time 6549ms: Process H switching out of CPU; will block on I/O until time 6608ms [Q P C G F L D E M A O J K B N I]
time 6553ms: Process P (tau 105ms) started using the CPU for 4ms burst [Q C G F L D E M A O J K B N I]
time 6557ms: Process P (tau 105ms) completed a CPU burst; 11 bursts to go [Q C G F L D E M A O J K B N I]
time 6557ms: Recalculated tau = 55ms for process P [Q C G F L D E M A O J K B N I]
time 6557ms: Process P switching out of CPU; will block on I/O until time 6738ms [Q C G F L D E M A O J K B N I]
time 6561ms: Process C (tau 107ms) started using the CPU for 85ms burst [Q G F L D E M A O J K B N I]
time 6608ms: Process H (tau 73ms) completed I/O; added to ready queue [Q H G F L D E M A O J K B N I]
time 6646ms: Process C (tau 107ms) completed a CPU burst; 1 burst to go [Q H G F L D E M A O J K B N I]
time 6646ms: Recalculated tau = 96ms for process C [Q H G F L D E M A O J K B N I]
time 6646ms: Process C switching out of CPU; will block on I/O until time 6669ms [Q H G F L D E M A O J K B N I]
time 6650ms: Process H (tau 73ms) started using the CPU for 156ms burst [Q G F L D E M A O J K B N I]
time 6669ms: Process C (tau 96ms) completed I/O; added to ready queue [Q C G F L D E M A O J K B N I]
time 6738ms: Process P (tau 55ms) completed I/O; added to ready queue [Q P C G F L D E M A O J K B N I]
time 6806ms: Process H (tau 73ms) completed a CPU burst; 73 bursts to go [Q P C G F L D E M A O J K B N I]
time 6806ms: Recalculated tau = 115ms for process H [Q P C G F L D E M A O J K B N I]
time 6806ms: Process H switching out of CPU; will block on I/O until time 6864ms [Q P C G F L D E M A O J K B N I]
time 6810ms: Process P (tau 55ms) started using the CPU for 105ms burst [Q C G F L D E M A O J K B N I]
time 6864ms: Process H (tau 115ms) completed I/O; added to ready queue [Q C G F H L D E M A O J K B N I]
time 6915ms: Process P (tau 55ms) completed a CPU burst; 10 bursts to go [Q C G F H L D E M A O J K B N I]
time 6915ms: Recalculated tau = 80ms for process P [Q C G F H L D E M A O J K B N I]
time 6915ms: Process P switching out of CPU; will block on I/O until time 6976ms [Q C G F H L D E M A O J K B N I]
time 6919ms: Process C (tau 96ms) started using the CPU for 79ms burst [Q G F H L D E M A O J K B N I]
time 6976ms: Process P (tau 80ms) completed I/O; added to ready queue [Q P G F H L D E M A O J K B N I]
time 6998ms: Process C terminated [Q P G F H L D E M A O J K B N I]
time 7002ms: Process P (tau 80ms) started using the CPU for 16ms burst [Q G F H L D E M A O J K B N I]
time 7018ms: Process P (tau 80ms) completed a CPU burst; 9 bursts to go [Q G F H L D E M A O J K B N I]
time 7018ms: Recalculated tau = 48ms for process P [Q G F H L D E M A O J K B N I]
time 7018ms: Process P switching out of CPU; will block on I/O until time 7085ms [Q G F H L D E M A O J K B N I]
time 7022ms: Process G (tau 114ms) started using the CPU for 6ms burst [Q F H L D E M A O J K B N I]
time 7028ms: Process G (tau 114ms) completed a CPU burst; 63 bursts to go [Q F H L D E M A O J K B N I]
time 7028ms: Recalculated tau = 60ms for process G [Q F H L D E M A O J K B N I]
time 7028ms: Process G switching out of CPU; will block on I/O until time 7178ms [Q F H L D E M A O J K B N I]
time 7032ms: Process F (tau 115ms) started using the CPU for 39ms burst [Q H L D E M A O J K B N I]
time 7071ms: Process F (tau 115ms) completed a CPU burst; 32 bursts to go [Q H L D E M A O J K B N I]
time 7071ms: Recalculated tau = 77ms for process F [Q H L D E M A O J K B N I]
time 7071ms: Process F switching out of CPU; will block on I/O until time 7138ms [Q H L D E M A O J K B N I]
time 7075ms: Process H (tau 115ms) started using the CPU for 184ms burst [Q L D E M A O J K B N I]
time 7085ms: Process P (tau 48ms) completed I/O; added to ready queue [Q P L D E M A O J K B N I]
time 7138ms: Process F (tau 77ms) completed I/O; added to ready queue [Q P F L D E M A O J K B N I]
time 7178ms: Process G (tau 60ms) completed I/O; added to ready queue [Q P G F L D E M A O J K B N I]
time 7259ms: Process H (tau 115ms) completed a CPU burst; 72 bursts to go [Q P G F L D E M A O J K B N I]
time 7259ms: Recalculated tau = 150ms for process H [Q P G F L D E M A O J K B N I]
time 7259ms: Process H switching out of CPU; will block on I/O until time 7287ms [Q P G F L D E M A O J K B N I]
time 7263ms: Process P (tau 48ms) started using the CPU for 219ms burst [Q G F L D E M A O J K B N I]
time 7287ms: Process H (tau 150ms) completed I/O; added to ready queue [Q G F L D E M A O J K H B N I]
time 7482ms: Process P (tau 48ms) completed a CPU burst; 8 bursts to go [Q G F L D E M A O J K H B N I]
time 7482ms: Recalculated tau = 134ms for process P [Q G F L D E M A O J K H B N I]
time 7482ms: Process P switching out of CPU; will block on I/O until time 7689ms [Q G F L D E M A O J K H B N I]
time 7486ms: Process G (tau 60ms) started using the CPU for 37ms burst [Q F L D E M A O J K H B N I]
time 7523ms: Process G (tau 60ms) completed a CPU burst; 62 bursts to go [Q F L D E M A O J K H B N I]
time 7523ms: Recalculated tau = 49ms for process G [Q F L D E M A O J K H B N I]
time 7523ms: Process G switching out of CPU; will block on I/O until time 7656ms [Q F L D E M A O J K H B N I]
time 7527ms: Process F (tau 77ms) started using the CPU for 195ms burst [Q L D E M A O J K H B N I]
time 7656ms: Process G (tau 49ms) completed I/O; added to ready queue [Q G L D E M A O J K H B N I]
time 7689ms: Process P (tau 134ms) completed I/O; added to ready queue [Q G L D E M A O P J K H B N I]
time 7722ms: Process F (tau 77ms) completed a CPU burst; 31 bursts to go [Q G L D E M A O P J K H B N I]
time 7722ms: Recalculated tau = 136ms for process F [Q G L D E M A O P J K H B N I]
time 7722ms: Process F switching out of CPU; will block on I/O until time 7725ms [Q G L D E M A O P J K H B N I]
time 7725ms: Process F (tau 136ms) completed I/O; added to ready queue [Q L D E M A O P F J K H B N I]
time 7726ms: Process G (tau 49ms) started using the CPU for 15ms burst [Q L D E M A O P F J K H B N I]
time 7741ms: Process G (tau 49ms) completed a CPU burst; 61 bursts to go [Q L D E M A O P F J K H B N I]
time 7741ms: Recalculated tau = 32ms for process G [Q L D E M A O P F J K H B N I]
time 7741ms: Process G switching out of CPU; will block on I/O until time 7765ms [Q L D E M A O P F J K H B N I]
time 7745ms: Process L (tau 118ms) started using the CPU for 4ms burst [Q D E M A O P F J K H B N I]
time 7749ms: Process L (tau 118ms) completed a CPU burst; 5 bursts to go [Q D E M A O P F J K H B N I]
time 7749ms: Recalculated tau = 61ms for process L [Q D E M A O P F J K H B N I]
time 7749ms: Process L switching out of CPU; will block on I/O until time 7793ms [Q D E M A O P F J K H B N I]
time 7753ms: Process D (tau 124ms) started using the CPU for 211ms burst [Q E M A O P F J K H B N I]
time 7765ms: Process G (tau 32ms) completed I/O; added to ready queue [Q G E M A O P F J K H B N I]
time 7793ms: Process L (tau 61ms) completed I/O; added to ready queue [Q G L E M A O P F J K H B N I]
time 7964ms: Process D (tau 124ms) completed a CPU burst; 9 bursts to go [Q G L E M A O P F J K H B N I]
time 7964ms: Recalculated tau = 168ms for process D [Q G L E M A O P F J K H B N I]
time 7964ms: Process D switching out of CPU; will block on I/O until time 8180ms [Q G L E M A O P F J K H B N I]
time 7968ms: Process G (tau 32ms) started using the CPU for 47ms burst [Q L E M A O P F J K H B N I]
time 8015ms: Process G (tau 32ms) completed a CPU burst; 60 bursts to go [Q L E M A O P F J K H B N I]
time 8015ms: Recalculated tau = 40ms for process G [Q L E M A O P F J K H B N I]
time 8015ms: Process G switching out of CPU; will block on I/O until time 8093ms [Q L E M A O P F J K H B N I]
time 8019ms: Process L (tau 61ms) started using the CPU for 69ms burst [Q E M A O P F J K H B N I]
time 8088ms: Process L (tau 61ms) completed a CPU burst; 4 bursts to go [Q E M A O P F J K H B N I]
time 8088ms: Recalculated tau = 65ms for process L [Q E M A O P F J K H B N I]
time 8088ms: Process L switching out of CPU; will block on I/O until time 8185ms [Q E M A O P F J K H B N I]
time 8092ms: Process E (tau 126ms) started using the CPU for 44ms burst [Q M A O P F J K H B N I]
time 8093ms: Process G (tau 40ms) completed I/O; added to ready queue [Q G M A O P F J K H B N I]
time 8136ms: Process E (tau 126ms) completed a CPU burst; 53 bursts to go [Q G M A O P F J K H B N I]
time 8136ms: Recalculated tau = 85ms for process E [Q G M A O P F J K H B N I]
time 8136ms: Process E switching out of CPU; will block on I/O until time 8194ms [Q G M A O P F J K H B N I]
time 8140ms: Process G (tau 40ms) started using the CPU for 82ms burst [Q M A O P F J K H B N I]
time 8180ms: Process D (tau 168ms) completed I/O; added to ready queue [Q M A O P F J K H B N I D]
time 8185ms: Process L (tau 65ms) completed I/O; added to ready queue [Q L M A O P F J K H B N I D]
time 8194ms: Process E (tau 85ms) completed I/O; added to ready queue [Q L E M A O P F J K H B N I D]
time 8222ms: Process G (tau 40ms) completed a CPU burst; 59 bursts to go [Q L E M A O P F J K H B N I D]
time 8222ms: Recalculated tau = 61ms for process G [Q L E M A O P F J K H B N I D]
time 8222ms: Process G switching out of CPU; will block on I/O until time 8227ms [Q L E M A O P F J K H B N I D]
time 8226ms: Process L (tau 65ms) started using the CPU for 25ms burst [Q E M A O P F J K H B N I D]
time 8227ms: Process G (tau 61ms) completed I/O; added to ready queue [Q G E M A O P F J K H B N I D]
time 8251ms: Process L (tau 65ms) completed a CPU burst; 3 bursts to go [Q G E M A O P F J K H B N I D]
time 8251ms: Recalculated tau = 45ms for process L [Q G E M A O P F J K H B N I D]
time 8251ms: Process L switching out of CPU; will block on I/O until time 8372ms [Q G E M A O P F J K H B N I D]
time 8255ms: Process G (tau 61ms) started using the CPU for 57ms burst [Q E M A O P F J K H B N I D]
time 8312ms: Process G (tau 61ms) completed a CPU burst; 58 bursts to go [Q E M A O P F J K H B N I D]
time 8312ms: Recalculated tau = 59ms for process G [Q E M A O P F J K H B N I D]
time 8312ms: Process G switching out of CPU; will block on I/O until time 8335ms [Q E M A O P F J K H B N I D]
time 8316ms: Process E (tau 85ms) started using the CPU for 2ms burst [Q M A O P F J K H B N I D]
time 8318ms: Process E (tau 85ms) completed a CPU burst; 52 bursts to go [Q M A O P F J K H B N I D]
time 8318ms: Recalculated tau = 44ms for process E [Q M A O P F J K H B N I D]
time 8318ms: Process E switching out of CPU; will block on I/O until time 8345ms [Q M A O P F J K H B N I D]
time 8322ms: Process M (tau 126ms) started using the CPU for 200ms burst [Q A O P F J K H B N I D]
time 8335ms: Process G (tau 59ms) completed I/O; added to ready queue [Q G A O P F J K H B N I D]
time 8345ms: Process E (tau 44ms) completed I/O; added to ready queue [Q E G A O P F J K H B N I D]
time 8372ms: Process L (tau 45ms) completed I/O; added to ready queue [Q E L G A O P F J K H B N I D]
time 8522ms: Process M (tau 126ms) completed a CPU burst; 40 bursts to go [Q E L G A O P F J K H B N I D]
time 8522ms: Recalculated tau = 163ms for process M [Q E L G A O P F J K H B N I D]
time 8522ms: Process M switching out of CPU; will block on I/O until time 8655ms [Q E L G A O P F J K H B N I D]
time 8526ms: Process E (tau 44ms) started using the CPU for 42ms burst [Q L G A O P F J K H B N I D]
time 8568ms: Process E (tau 44ms) completed a CPU burst; 51 bursts to go [Q L G A O P F J K H B N I D]
time 8568ms: Recalculated tau = 43ms for process E [Q L G A O P F J K H B N I D]
time 8568ms: Process E switching out of CPU; will block on I/O until time 8575ms [Q L G A O P F J K H B N I D]
time 8572ms: Process L (tau 45ms) started using the CPU for 2ms burst [Q G A O P F J K H B N I D]
time 8574ms: Process L (tau 45ms) completed a CPU burst; 2 bursts to go [Q G A O P F J K H B N I D]
time 8574ms: Recalculated tau = 24ms for process L [Q G A O P F J K H B N I D]
time 8574ms: Process L switching out of CPU; will block on I/O until time 8613ms [Q G A O P F J K H B N I D]
time 8575ms: Process E (tau 43ms) completed I/O; added to ready queue [Q E G A O P F J K H B N I D]
time 8578ms: Process E (tau 43ms) started using the CPU for 108ms burst [Q G A O P F J K H B N I D]
time 8613ms: Process L (tau 24ms) completed I/O; added to ready queue [Q L G A O P F J K H B N I D]
time 8655ms: Process M (tau 163ms) completed I/O; added to ready queue [Q L G A O P F J K H B N I M D]
time 8686ms: Process E (tau 43ms) completed a CPU burst; 50 bursts to go [Q L G A O P F J K H B N I M D]
time 8686ms: Recalculated tau = 76ms for process E [Q L G A O P F J K H B N I M D]
time 8686ms: Process E switching out of CPU; will block on I/O until time 8697ms [Q L G A O P F J K H B N I M D]
time 8690ms: Process L (tau 24ms) started using the CPU for 164ms burst [Q G A O P F J K H B N I M D]
time 8697ms: Process E (tau 76ms) completed I/O; added to ready queue [Q G E A O P F J K H B N I M D]
time 8854ms: Process L (tau 24ms) completed a CPU burst; 1 burst to go [Q G E A O P F J K H B N I M D]
time 8854ms: Recalculated tau = 94ms for process L [Q G E A O P F J K H B N I M D]
time 8854ms: Process L switching out of CPU; will block on I/O until time 8906ms [Q G E A O P F J K H B N I M D]
time 8858ms: Process G (tau 59ms) started using the CPU for 89ms burst [Q E A O P F J K H B N I M D]
time 8906ms: Process L (tau 94ms) completed I/O; added to ready queue [Q E L A O P F J K H B N I M D]
time 8947ms: Process G (tau 59ms) completed a CPU burst; 57 bursts to go [Q E L A O P F J K H B N I M D]
time 8947ms: Recalculated tau = 74ms for process G [Q E L A O P F J K H B N I M D]
time 8947ms: Process G switching out of CPU; will block on I/O until time 9041ms [Q E L A O P F J K H B N I M D]
time 8951ms: Process E (tau 76ms) started using the CPU for 6ms burst [Q L A O P F J K H B N I M D]
time 8957ms: Process E (tau 76ms) completed a CPU burst; 49 bursts to go [Q L A O P F J K H B N I M D]
time 8957ms: Recalculated tau = 41ms for process E [Q L A O P F J K H B N I M D]
time 8957ms: Process E switching out of CPU; will block on I/O until time 8991ms [Q L A O P F J K H B N I M D]
time 8961ms: Process L (tau 94ms) started using the CPU for 111ms burst [Q A O P F J K H B N I M D]
time 8991ms: Process E (tau 41ms) completed I/O; added to ready queue [Q E A O P F J K H B N I M D]
time 9041ms: Process G (tau 74ms) completed I/O; added to ready queue [Q E G A O P F J K H B N I M D]
time 9072ms: Process L terminated [Q E G A O P F J K H B N I M D]
time 9076ms: Process E (tau 41ms) started using the CPU for 112ms burst [Q G A O P F J K H B N I M D]
time 9188ms: Process E (tau 41ms) completed a CPU burst; 48 bursts to go [Q G A O P F J K H B N I M D]
time 9188ms: Recalculated tau = 77ms for process E [Q G A O P F J K H B N I M D]
time 9188ms: Process E switching out of CPU; will block on I/O until time 9301ms [Q G A O P F J K H B N I M D]
time 9192ms: Process G (tau 74ms) started using the CPU for 3ms burst [Q A O P F J K H B N I M D]
time 9195ms: Process G (tau 74ms) completed a CPU burst; 56 bursts to go [Q A O P F J K H B N I M D]
time 9195ms: Recalculated tau = 39ms for process G [Q A O P F J K H B N I M D]
time 9195ms: Process G switching out of CPU; will block on I/O until time 9333ms [Q A O P F J K H B N I M D]
time 9199ms: Process A (tau 128ms) started using the CPU for 197ms burst [Q O P F J K H B N I M D]
time 9301ms: Process E (tau 77ms) completed I/O; added to ready queue [Q E O P F J K H B N I M D]
time 9333ms: Process G (tau 39ms) completed I/O; added to ready queue [Q G E O P F J K H B N I M D]
time 9396ms: Process A terminated [Q G E O P F J K H B N I M D]
time 9400ms: Process G (tau 39ms) started using the CPU for 11ms burst [Q E O P F J K H B N I M D]
time 9411ms: Process G (tau 39ms) completed a CPU burst; 55 bursts to go [Q E O P F J K H B N I M D]
time 9411ms: Recalculated tau = 25ms for process G [Q E O P F J K H B N I M D]
time 9411ms: Process G switching out of CPU; will block on I/O until time 9658ms [Q E O P F J K H B N I M D]
time 9415ms: Process E (tau 77ms) started using the CPU for 12ms burst [Q O P F J K H B N I M D]
time 9427ms: Process E (tau 77ms) completed a CPU burst; 47 bursts to go [Q O P F J K H B N I M D]
time 9427ms: Recalculated tau = 45ms for process E [Q O P F J K H B N I M D]
time 9427ms: Process E switching out of CPU; will block on I/O until time 9474ms [Q O P F J K H B N I M D]
time 9431ms: Process O (tau 128ms) started using the CPU for 106ms burst [Q P F J K H B N I M D]
time 9474ms: Process E (tau 45ms) completed I/O; added to ready queue [Q E P F J K H B N I M D]
time 9537ms: Process O (tau 128ms) completed a CPU burst; 29 bursts to go [Q E P F J K H B N I M D]
time 9537ms: Recalculated tau = 117ms for process O [Q E P F J K H B N I M D]
time 9537ms: Process O switching out of CPU; will block on I/O until time 9788ms [Q E P F J K H B N I M D]
time 9541ms: Process E (tau 45ms) started using the CPU for 9ms burst [Q P F J K H B N I M D]
time 9550ms: Process E (tau 45ms) completed a CPU burst; 46 bursts to go [Q P F J K H B N I M D]
time 9550ms: Recalculated tau = 27ms for process E [Q P F J K H B N I M D]
time 9550ms: Process E switching out of CPU; will block on I/O until time 9619ms [Q P F J K H B N I M D]
time 9554ms: Process P (tau 134ms) started using the CPU for 70ms burst [Q F J K H B N I M D]
time 9619ms: Process E (tau 27ms) completed I/O; added to ready queue [Q E F J K H B N I M D]
time 9624ms: Process P (tau 134ms) completed a CPU burst; 7 bursts to go [Q E F J K H B N I M D]
time 9624ms: Recalculated tau = 102ms for process P [Q E F J K H B N I M D]
time 9624ms: Process P switching out of CPU; will block on I/O until time 9753ms [Q E F J K H B N I M D]
time 9628ms: Process E (tau 27ms) started using the CPU for 62ms burst [Q F J K H B N I M D]
time 9658ms: Process G (tau 25ms) completed I/O; added to ready queue [Q G F J K H B N I M D]
time 9690ms: Process E (tau 27ms) completed a CPU burst; 45 bursts to go [Q G F J K H B N I M D]
time 9690ms: Recalculated tau = 45ms for process E [Q G F J K H B N I M D]
time 9690ms: Process E switching out of CPU; will block on I/O until time 9752ms [Q G F J K H B N I M D]
time 9694ms: Process G (tau 25ms) started using the CPU for 17ms burst [Q F J K H B N I M D]
time 9711ms: Process G (tau 25ms) completed a CPU burst; 54 bursts to go [Q F J K H B N I M D]
time 9711ms: Recalculated tau = 21ms for process G [Q F J K H B N I M D]
time 9711ms: Process G switching out of CPU; will block on I/O until time 9778ms [Q F J K H B N I M D]
time 9715ms: Process F (tau 136ms) started using the CPU for 72ms burst [Q J K H B N I M D]
time 9752ms: Process E (tau 45ms) completed I/O; added to ready queue [Q E J K H B N I M D]
time 9753ms: Process P (tau 102ms) completed I/O; added to ready queue [Q E P J K H B N I M D]
time 9778ms: Process G (tau 21ms) completed I/O; added to ready queue [Q G E P J K H B N I M D]
time 9787ms: Process F (tau 136ms) completed a CPU burst; 30 bursts to go [Q G E P J K H B N I M D]
time 9787ms: Recalculated tau = 104ms for process F [Q G E P J K H B N I M D]
time 9787ms: Process F switching out of CPU; will block on I/O until time 9815ms [Q G E P J K H B N I M D]
time 9788ms: Process O (tau 117ms) completed I/O; added to ready queue [Q G E P O J K H B N I M D]
time 9791ms: Process G (tau 21ms) started using the CPU for 55ms burst [Q E P O J K H B N I M D]
time 9815ms: Process F (tau 104ms) completed I/O; added to ready queue [Q E P F O J K H B N I M D]
time 9846ms: Process G (tau 21ms) completed a CPU burst; 53 bursts to go [Q E P F O J K H B N I M D]
time 9846ms: Recalculated tau = 38ms for process G [Q E P F O J K H B N I M D]
time 9846ms: Process G switching out of CPU; will block on I/O until time 10052ms [Q E P F O J K H B N I M D]
time 9850ms: Process E (tau 45ms) started using the CPU for 213ms burst [Q P F O J K H B N I M D]
time 10052ms: Process G (tau 38ms) completed I/O; added to ready queue [Q G P F O J K H B N I M D]
time 10063ms: Process E (tau 45ms) completed a CPU burst; 44 bursts to go [Q G P F O J K H B N I M D]
time 10063ms: Recalculated tau = 129ms for process E [Q G P F O J K H B N I M D]
time 10063ms: Process E switching out of CPU; will block on I/O until time 10258ms [Q G P F O J K H B N I M D]
time 10067ms: Process G (tau 38ms) started using the CPU for 52ms burst [Q P F O J K H B N I M D]
time 10119ms: Process G (tau 38ms) completed a CPU burst; 52 bursts to go [Q P F O J K H B N I M D]
time 10119ms: Recalculated tau = 45ms for process G [Q P F O J K H B N I M D]
time 10119ms: Process G switching out of CPU; will block on I/O until time 10217ms [Q P F O J K H B N I M D]
time 10123ms: Process P (tau 102ms) started using the CPU for 55ms burst [Q F O J K H B N I M D]
time 10178ms: Process P (tau 102ms) completed a CPU burst; 6 bursts to go [Q F O J K H B N I M D]
time 10178ms: Recalculated tau = 79ms for process P [Q F O J K H B N I M D]
time 10178ms: Process P switching out of CPU; will block on I/O until time 10425ms [Q F O J K H B N I M D]
time 10182ms: Process F (tau 104ms) started using the CPU for 8ms burst [Q O J K H B N I M D]
time 10190ms: Process F (tau 104ms) completed a CPU burst; 29 bursts to go [Q O J K H B N I M D]
time 10190ms: Recalculated tau = 56ms for process F [Q O J K H B N I M D]
time 10190ms: Process F switching out of CPU; will block on I/O until time 10225ms [Q O J K H B N I M D]
time 10194ms: Process O (tau 117ms) started using the CPU for 57ms burst [Q J K H B N I M D]
time 10217ms: Process G (tau 45ms) completed I/O; added to ready queue [Q G J K H B N I M D]
time 10225ms: Process F (tau 56ms) completed I/O; added to ready queue [Q G F J K H B N I M D]
time 10251ms: Process O (tau 117ms) completed a CPU burst; 28 bursts to go [Q G F J K H B N I M D]
time 10251ms: Recalculated tau = 87ms for process O [Q G F J K H B N I M D]
time 10251ms: Process O switching out of CPU; will block on I/O until time 10290ms [Q G F J K H B N I M D]
time 10255ms: Process G (tau 45ms) started using the CPU for 199ms burst [Q F J K H B N I M D]
time 10258ms: Process E (tau 129ms) completed I/O; added to ready queue [Q F E J K H B N I M D]
time 10290ms: Process O (tau 87ms) completed I/O; added to ready queue [Q F O E J K H B N I M D]
time 10425ms: Process P (tau 79ms) completed I/O; added to ready queue [Q F P O E J K H B N I M D]
time 10454ms: Process G (tau 45ms) completed a CPU burst; 51 bursts to go [Q F P O E J K H B N I M D]
time 10454ms: Recalculated tau = 122ms for process G [Q F P O E J K H B N I M D]
time 10454ms: Process G switching out of CPU; will block on I/O until time 10466ms [Q F P O E J K H B N I M D]
time 10458ms: Process F (tau 56ms) started using the CPU for 230ms burst [Q P O E J K H B N I M D]
time 10466ms: Process G (tau 122ms) completed I/O; added to ready queue [Q P O G E J K H B N I M D]
time 10688ms: Process F (tau 56ms) completed a CPU burst; 28 bursts to go [Q P O G E J K H B N I M D]
time 10688ms: Recalculated tau = 143ms for process F [Q P O G E J K H B N I M D]
time 10688ms: Process F switching out of CPU; will block on I/O until time 10693ms [Q P O G E J K H B N I M D]
time 10692ms: Process P (tau 79ms) started using the CPU for 212ms burst [Q O G E J K H B N I M D]
time 10693ms: Process F (tau 143ms) completed I/O; added to ready queue [Q O G E J K F H B N I M D]
time 10904ms: Process P (tau 79ms) completed a CPU burst; 5 bursts to go [Q O G E J K F H B N I M D]
time 10904ms: Recalculated tau = 146ms for process P [Q O G E J K F H B N I M D]
time 10904ms: Process P switching out of CPU; will block on I/O until time 11123ms [Q O G E J K F H B N I M D]
time 10908ms: Process O (tau 87ms) started using the CPU for 13ms burst [Q G E J K F H B N I M D]
time 10921ms: Process O (tau 87ms) completed a CPU burst; 27 bursts to go [Q G E J K F H B N I M D]
time 10921ms: Recalculated tau = 50ms for process O [Q G E J K F H B N I M D]
time 10921ms: Process O switching out of CPU; will block on I/O until time 11056ms [Q G E J K F H B N I M D]
time 10925ms: Process G (tau 122ms) started using the CPU for 35ms burst [Q E J K F H B N I M D]
time 10960ms: Process G (tau 122ms) completed a CPU burst; 50 bursts to go [Q E J K F H B N I M D]
time 10960ms: Recalculated tau = 79ms for process G [Q E J K F H B N I M D]
time 10960ms: Process G switching out of CPU; will block on I/O until time 11033ms [Q E J K F H B N I M D]
time 10964ms: Process E (tau 129ms) started using the CPU for 54ms burst [Q J K F H B N I M D]
time 11018ms: Process E (tau 129ms) completed a CPU burst; 43 bursts to go [Q J K F H B N I M D]
time 11018ms: Recalculated tau = 92ms for process E [Q J K F H B N I M D]
time 11018ms: Process E switching out of CPU; will block on I/O until time 11115ms [Q J K F H B N I M D]
time 11022ms: Process J (tau 137ms) started using the CPU for 28ms burst [Q K F H B N I M D]
time 11033ms: Process G (tau 79ms) completed I/O; added to ready queue [Q G K F H B N I M D]
time 11050ms: Process J (tau 137ms) completed a CPU burst; 7 bursts to go [Q G K F H B N I M D]
time 11050ms: Recalculated tau = 83ms for process J [Q G K F H B N I M D]
time 11050ms: Process J switching out of CPU; will block on I/O until time 11074ms [Q G K F H B N I M D]
time 11054ms: Process G (tau 79ms) started using the CPU for 44ms burst [Q K F H B N I M D]
time 11056ms: Process O (tau 50ms) completed I/O; added to ready queue [Q O K F H B N I M D]
time 11074ms: Process J (tau 83ms) completed I/O; added to ready queue [Q O J K F H B N I M D]
time 11098ms: Process G (tau 79ms) completed a CPU burst; 49 bursts to go [Q O J K F H B N I M D]
time 11098ms: Recalculated tau = 62ms for process G [Q O J K F H B N I M D]
time 11098ms: Process G switching out of CPU; will block on I/O until time 11124ms [Q O J K F H B N I M D]
time 11102ms: Process O (tau 50ms) started using the CPU for 130ms burst [Q J K F H B N I M D]
time 11115ms: Process E (tau 92ms) completed I/O; added to ready queue [Q J E K F H B N I M D]
time 11123ms: Process P (tau 146ms) completed I/O; added to ready queue [Q J E K F P H B N I M D]
time 11124ms: Process G (tau 62ms) completed I/O; added to ready queue [Q G J E K F P H B N I M D]
time 11232ms: Process O (tau 50ms) completed a CPU burst; 26 bursts to go [Q G J E K F P H B N I M D]
time 11232ms: Recalculated tau = 90ms for process O [Q G J E K F P H B N I M D]
time 11232ms: Process O switching out of CPU; will block on I/O until time 11305ms [Q G J E K F P H B N I M D]
time 11236ms: Process G (tau 62ms) started using the CPU for 27ms burst [Q J E K F P H B N I M D]
time 11263ms: Process G (tau 62ms) completed a CPU burst; 48 bursts to go [Q J E K F P H B N I M D]
time 11263ms: Recalculated tau = 45ms for process G [Q J E K F P H B N I M D]
time 11263ms: Process G switching out of CPU; will block on I/O until time 11388ms [Q J E K F P H B N I M D]
time 11267ms: Process J (tau 83ms) started using the CPU for 120ms burst [Q E K F P H B N I M D]
time 11305ms: Process O (tau 90ms) completed I/O; added to ready queue [Q O E K F P H B N I M D]
time 11387ms: Process J (tau 83ms) completed a CPU burst; 6 bursts to go [Q O E K F P H B N I M D]
time 11387ms: Recalculated tau = 102ms for process J [Q O E K F P H B N I M D]
time 11387ms: Process J switching out of CPU; will block on I/O until time 11445ms [Q O E K F P H B N I M D]
time 11388ms: Process G (tau 45ms) completed I/O; added to ready queue [Q G O E K F P H B N I M D]
time 11391ms: Process G (tau 45ms) started using the CPU for 171ms burst [Q O E K F P H B N I M D]
time 11445ms: Process J (tau 102ms) completed I/O; added to ready queue [Q O E J K F P H B N I M D]
time 11562ms: Process G (tau 45ms) completed a CPU burst; 47 bursts to go [Q O E J K F P H B N I M D]
time 11562ms: Recalculated tau = 108ms for process G [Q O E J K F P H B N I M D]
time 11562ms: Process G switching out of CPU; will block on I/O until time 11593ms [Q O E J K F P H B N I M D]
time 11566ms: Process O (tau 90ms) started using the CPU for 68ms burst [Q E J K F P H B N I M D]
time 11593ms: Process G (tau 108ms) completed I/O; added to ready queue [Q E J G K F P H B N I M D]
time 11634ms: Process O (tau 90ms) completed a CPU burst; 25 bursts to go [Q E J G K F P H B N I M D]
time 11634ms: Recalculated tau = 79ms for process O [Q E J G K F P H B N I M D]
time 11634ms: Process O switching out of CPU; will block on I/O until time 11753ms [Q E J G K F P H B N I M D]
time 11638ms: Process E (tau 92ms) started using the CPU for 126ms burst [Q J G K F P H B N I M D]
time 11753ms: Process O (tau 79ms) completed I/O; added to ready queue [Q O J G K F P H B N I M D]
time 11764ms: Process E (tau 92ms) completed a CPU burst; 42 bursts to go [Q O J G K F P H B N I M D]
time 11764ms: Recalculated tau = 109ms for process E [Q O J G K F P H B N I M D]
time 11764ms: Process E switching out of CPU; will block on I/O until time 11964ms [Q O J G K F P H B N I M D]
time 11768ms: Process O (tau 79ms) started using the CPU for 136ms burst [Q J G K F P H B N I M D]
time 11904ms: Process O (tau 79ms) completed a CPU burst; 24 bursts to go [Q J G K F P H B N I M D]
time 11904ms: Recalculated tau = 108ms for process O [Q J G K F P H B N I M D]
time 11904ms: Process O switching out of CPU; will block on I/O until time 12011ms [Q J G K F P H B N I M D]
time 11908ms: Process J (tau 102ms) started using the CPU for 31ms burst [Q G K F P H B N I M D]
time 11939ms: Process J (tau 102ms) completed a CPU burst; 5 bursts to go [Q G K F P H B N I M D]
time 11939ms: Recalculated tau = 67ms for process J [Q G K F P H B N I M D]
time 11939ms: Process J switching out of CPU; will block on I/O until time 12027ms [Q G K F P H B N I M D]
time 11943ms: Process G (tau 108ms) started using the CPU for 3ms burst [Q K F P H B N I M D]
time 11946ms: Process G (tau 108ms) completed a CPU burst; 46 bursts to go [Q K F P H B N I M D]
time 11946ms: Recalculated tau = 56ms for process G [Q K F P H B N I M D]
time 11946ms: Process G switching out of CPU; will block on I/O until time 12078ms [Q K F P H B N I M D]
time 11950ms: Process K (tau 137ms) started using the CPU for 47ms burst [Q F P H B N I M D]
time 11964ms: Process E (tau 109ms) completed I/O; added to ready queue [Q E F P H B N I M D]
time 11997ms: Process K terminated [Q E F P H B N I M D]
time 12001ms: Process E (tau 109ms) started using the CPU for 168ms burst [Q F P H B N I M D]
time 12011ms: Process O (tau 108ms) completed I/O; added to ready queue [Q O F P H B N I M D]
time 12027ms: Process J (tau 67ms) completed I/O; added to ready queue [Q J O F P H B N I M D]
time 12078ms: Process G (tau 56ms) completed I/O; added to ready queue [Q G J O F P H B N I M D]
time 12169ms: Process E (tau 109ms) completed a CPU burst; 41 bursts to go [Q G J O F P H B N I M D]
time 12169ms: Recalculated tau = 139ms for process E [Q G J O F P H B N I M D]
time 12169ms: Process E switching out of CPU; will block on I/O until time 12221ms [Q G J O F P H B N I M D]
time 12173ms: Process G (tau 56ms) started using the CPU for 107ms burst [Q J O F P H B N I M D]
time 12221ms: Process E (tau 139ms) completed I/O; added to ready queue [Q J O E F P H B N I M D]
time 12280ms: Process G (tau 56ms) completed a CPU burst; 45 bursts to go [Q J O E F P H B N I M D]
time 12280ms: Recalculated tau = 82ms for process G [Q J O E F P H B N I M D]
time 12280ms: Process G switching out of CPU; will block on I/O until time 12299ms [Q J O E F P H B N I M D]
time 12284ms: Process J (tau 67ms) started using the CPU for 32ms burst [Q O E F P H B N I M D]
time 12299ms: Process G (tau 82ms) completed I/O; added to ready queue [Q G O E F P H B N I M D]
time 12316ms: Process J (tau 67ms) completed a CPU burst; 4 bursts to go [Q G O E F P H B N I M D]
time 12316ms: Recalculated tau = 50ms for process J [Q G O E F P H B N I M D]
time 12316ms: Process J switching out of CPU; will block on I/O until time 12331ms [Q G O E F P H B N I M D]
time 12320ms: Process G (tau 82ms) started using the CPU for 111ms burst [Q O E F P H B N I M D]
time 12331ms: Process J (tau 50ms) completed I/O; added to ready queue [Q J O E F P H B N I M D]
time 12431ms: Process G (tau 82ms) completed a CPU burst; 44 bursts to go [Q J O E F P H B N I M D]
time 12431ms: Recalculated tau = 97ms for process G [Q J O E F P H B N I M D]
time 12431ms: Process G switching out of CPU; will block on I/O until time 12464ms [Q J O E F P H B N I M D]
time 12435ms: Process J (tau 50ms) started using the CPU for 23ms burst [Q O E F P H B N I M D]
time 12458ms: Process J (tau 50ms) completed a CPU burst; 3 bursts to go [Q O E F P H B N I M D]
time 12458ms: Recalculated tau = 37ms for process J [Q O E F P H B N I M D]
time 12458ms: Process J switching out of CPU; will block on I/O until time 12476ms [Q O E F P H B N I M D]
time 12462ms: Process O (tau 108ms) started using the CPU for 69ms burst [Q E F P H B N I M D]
time 12464ms: Process G (tau 97ms) completed I/O; added to ready queue [Q G E F P H B N I M D]
time 12476ms: Process J (tau 37ms) completed I/O; added to ready queue [Q J G E F P H B N I M D]
time 12531ms: Process O (tau 108ms) completed a CPU burst; 23 bursts to go [Q J G E F P H B N I M D]
time 12531ms: Recalculated tau = 89ms for process O [Q J G E F P H B N I M D]
time 12531ms: Process O switching out of CPU; will block on I/O until time 12608ms [Q J G E F P H B N I M D]
time 12535ms: Process J (tau 37ms) started using the CPU for 51ms burst [Q G E F P H B N I M D]
time 12586ms: Process J (tau 37ms) completed a CPU burst; 2 bursts to go [Q G E F P H B N I M D]
time 12586ms: Recalculated tau = 44ms for process J [Q G E F P H B N I M D]
time 12586ms: Process J switching out of CPU; will block on I/O until time 12685ms [Q G E F P H B N I M D]
time 12590ms: Process G (tau 97ms) started using the CPU for 11ms burst [Q E F P H B N I M D]
time 12601ms: Process G (tau 97ms) completed a CPU burst; 43 bursts to go [Q E F P H B N I M D]
time 12601ms: Recalculated tau = 54ms for process G [Q E F P H B N I M D]
time 12601ms: Process G switching out of CPU; will block on I/O until time 12681ms [Q E F P H B N I M D]
time 12605ms: Process E (tau 139ms) started using the CPU for 23ms burst [Q F P H B N I M D]
time 12608ms: Process O (tau 89ms) completed I/O; added to ready queue [Q O F P H B N I M D]
time 12628ms: Process E (tau 139ms) completed a CPU burst; 40 bursts to go [Q O F P H B N I M D]
time 12628ms: Recalculated tau = 81ms for process E [Q O F P H B N I M D]
time 12628ms: Process E switching out of CPU; will block on I/O until time 12639ms [Q O F P H B N I M D]
time 12632ms: Process O (tau 89ms) started using the CPU for 6ms burst [Q F P H B N I M D]
time 12638ms: Process O (tau 89ms) completed a CPU burst; 22 bursts to go [Q F P H B N I M D]
time 12638ms: Recalculated tau = 48ms for process O [Q F P H B N I M D]
time 12638ms: Process O switching out of CPU; will block on I/O until time 12804ms [Q F P H B N I M D]
time 12639ms: Process E (tau 81ms) completed I/O; added to ready queue [Q E F P H B N I M D]
time 12642ms: Process E (tau 81ms) started using the CPU for 68ms burst [Q F P H B N I M D]
time 12681ms: Process G (tau 54ms) completed I/O; added to ready queue [Q G F P H B N I M D]
time 12685ms: Process J (tau 44ms) completed I/O; added to ready queue [Q J G F P H B N I M D]
time 12710ms: Process E (tau 81ms) completed a CPU burst; 39 bursts to go [Q J G F P H B N I M D]
time 12710ms: Recalculated tau = 75ms for process E [Q J G F P H B N I M D]
time 12710ms: Process E switching out of CPU; will block on I/O until time 12770ms [Q J G F P H B N I M D]
time 12714ms: Process J (tau 44ms) started using the CPU for 216ms burst [Q G F P H B N I M D]
time 12770ms: Process E (tau 75ms) completed I/O; added to ready queue [Q G E F P H B N I M D]
time 12804ms: Process O (tau 48ms) completed I/O; added to ready queue [Q O G E F P H B N I M D]
time 12930ms: Process J (tau 44ms) completed a CPU burst; 1 burst to go [Q O G E F P H B N I M D]
time 12930ms: Recalculated tau = 130ms for process J [Q O G E F P H B N I M D]
time 12930ms: Process J switching out of CPU; will block on I/O until time 12940ms [Q O G E F P H B N I M D]
time 12934ms: Process O (tau 48ms) started using the CPU for 187ms burst [Q G E F P H B N I M D]
time 12940ms: Process J (tau 130ms) completed I/O; added to ready queue [Q G E J F P H B N I M D]
time 13121ms: Process O (tau 48ms) completed a CPU burst; 21 bursts to go [Q G E J F P H B N I M D]
time 13121ms: Recalculated tau = 118ms for process O [Q G E J F P H B N I M D]
time 13121ms: Process O switching out of CPU; will block on I/O until time 13290ms [Q G E J F P H B N I M D]
time 13125ms: Process G (tau 54ms) started using the CPU for 28ms burst [Q E J F P H B N I M D]
time 13153ms: Process G (tau 54ms) completed a CPU burst; 42 bursts to go [Q E J F P H B N I M D]
time 13153ms: Recalculated tau = 41ms for process G [Q E J F P H B N I M D]
time 13153ms: Process G switching out of CPU; will block on I/O until time 13161ms [Q E J F P H B N I M D]
time 13157ms: Process E (tau 75ms) started using the CPU for 41ms burst [Q J F P H B N I M D]
time 13161ms: Process G (tau 41ms) completed I/O; added to ready queue [Q G J F P H B N I M D]
time 13198ms: Process E (tau 75ms) completed a CPU burst; 38 bursts to go [Q G J F P H B N I M D]
time 13198ms: Recalculated tau = 58ms for process E [Q G J F P H B N I M D]
time 13198ms: Process E switching out of CPU; will block on I/O until time 13220ms [Q G J F P H B N I M D]
time 13202ms: Process G (tau 41ms) started using the CPU for 137ms burst [Q J F P H B N I M D]
time 13220ms: Process E (tau 58ms) completed I/O; added to ready queue [Q E J F P H B N I M D]
time 13290ms: Process O (tau 118ms) completed I/O; added to ready queue [Q E O J F P H B N I M D]
time 13339ms: Process G (tau 41ms) completed a CPU burst; 41 bursts to go [Q E O J F P H B N I M D]
time 13339ms: Recalculated tau = 89ms for process G [Q E O J F P H B N I M D]
time 13339ms: Process G switching out of CPU; will block on I/O until time 13396ms [Q E O J F P H B N I M D]
time 13343ms: Process E (tau 58ms) started using the CPU for 44ms burst [Q O J F P H B N I M D]
time 13387ms: Process E (tau 58ms) completed a CPU burst; 37 bursts to go [Q O J F P H B N I M D]
time 13387ms: Recalculated tau = 51ms for process E [Q O J F P H B N I M D]
time 13387ms: Process E switching out of CPU; will block on I/O until time 13450ms [Q O J F P H B N I M D]
time 13391ms: Process O (tau 118ms) started using the CPU for 89ms burst [Q J F P H B N I M D]
time 13396ms: Process G (tau 89ms) completed I/O; added to ready queue [Q G J F P H B N I M D]
time 13450ms: Process E (tau 51ms) completed I/O; added to ready queue [Q E G J F P H B N I M D]
time 13480ms: Process O (tau 118ms) completed a CPU burst; 20 bursts to go [Q E G J F P H B N I M D]
time 13480ms: Recalculated tau = 104ms for process O [Q E G J F P H B N I M D]
time 13480ms: Process O switching out of CPU; will block on I/O until time 13622ms [Q E G J F P H B N I M D]
time 13484ms: Process E (tau 51ms) started using the CPU for 74ms burst [Q G J F P H B N I M D]
time 13558ms: Process E (tau 51ms) completed a CPU burst; 36 bursts to go [Q G J F P H B N I M D]
time 13558ms: Recalculated tau = 63ms for process E [Q G J F P H B N I M D]
time 13558ms: Process E switching out of CPU; will block on I/O until time 13746ms [Q G J F P H B N I M D]
time 13562ms: Process G (tau 89ms) started using the CPU for 124ms burst [Q J F P H B N I M D]
time 13622ms: Process O (tau 104ms) completed I/O; added to ready queue [Q O J F P H B N I M D]
time 13686ms: Process G (tau 89ms) completed a CPU burst; 40 bursts to go [Q O J F P H B N I M D]
time 13686ms: Recalculated tau = 107ms for process G [Q O J F P H B N I M D]
time 13686ms: Process G switching out of CPU; will block on I/O until time 13763ms [Q O J F P H B N I M D]
time 13690ms: Process O (tau 104ms) started using the CPU for 45ms burst [Q J F P H B N I M D]
time 13735ms: Process O (tau 104ms) completed a CPU burst; 19 bursts to go [Q J F P H B N I M D]
time 13735ms: Recalculated tau = 75ms for process O [Q J F P H B N I M D]
time 13735ms: Process O switching out of CPU; will block on I/O until time 13783ms [Q J F P H B N I M D]
time 13739ms: Process J (tau 130ms) started using the CPU for 7ms burst [Q F P H B N I M D]
time 13746ms: Process J terminated [Q F P H B N I M D]
time 13746ms: Process E (tau 63ms) completed I/O; added to ready queue [Q E F P H B N I M D]
time 13750ms: Process E (tau 63ms) started using the CPU for 117ms burst [Q F P H B N I M D]
time 13763ms: Process G (tau 107ms) completed I/O; added to ready queue [Q G F P H B N I M D]
time 13783ms: Process O (tau 75ms) completed I/O; added to ready queue [Q O G F P H B N I M D]
time 13867ms: Process E (tau 63ms) completed a CPU burst; 35 bursts to go [Q O G F P H B N I M D]
time 13867ms: Recalculated tau = 90ms for process E [Q O G F P H B N I M D]
time 13867ms: Process E switching out of CPU; will block on I/O until time 13969ms [Q O G F P H B N I M D]
time 13871ms: Process O (tau 75ms) started using the CPU for 50ms burst [Q G F P H B N I M D]
time 13921ms: Process O (tau 75ms) completed a CPU burst; 18 bursts to go [Q G F P H B N I M D]
time 13921ms: Recalculated tau = 63ms for process O [Q G F P H B N I M D]
time 13921ms: Process O switching out of CPU; will block on I/O until time 14034ms [Q G F P H B N I M D]
time 13925ms: Process G (tau 107ms) started using the CPU for 108ms burst [Q F P H B N I M D]
time 13969ms: Process E (tau 90ms) completed I/O; added to ready queue [Q E F P H B N I M D]
time 14033ms: Process G (tau 107ms) completed a CPU burst; 39 bursts to go [Q E F P H B N I M D]
time 14033ms: Recalculated tau = 108ms for process G [Q E F P H B N I M D]
time 14033ms: Process G switching out of CPU; will block on I/O until time 14152ms [Q E F P H B N I M D]
time 14034ms: Process O (tau 63ms) completed I/O; added to ready queue [Q O E F P H B N I M D]
time 14037ms: Process O (tau 63ms) started using the CPU for 133ms burst [Q E F P H B N I M D]
time 14152ms: Process G (tau 108ms) completed I/O; added to ready queue [Q E G F P H B N I M D]
time 14170ms: Process O (tau 63ms) completed a CPU burst; 17 bursts to go [Q E G F P H B N I M D]
time 14170ms: Recalculated tau = 98ms for process O [Q E G F P H B N I M D]
time 14170ms: Process O switching out of CPU; will block on I/O until time 14300ms [Q E G F P H B N I M D]
time 14174ms: Process E (tau 90ms) started using the CPU for 14ms burst [Q G F P H B N I M D]
time 14188ms: Process E (tau 90ms) completed a CPU burst; 34 bursts to go [Q G F P H B N I M D]
time 14188ms: Recalculated tau = 52ms for process E [Q G F P H B N I M D]
time 14188ms: Process E switching out of CPU; will block on I/O until time 14192ms [Q G F P H B N I M D]
time 14192ms: Process G (tau 108ms) started using the CPU for 110ms burst [Q F P H B N I M D]
time 14192ms: Process E (tau 52ms) completed I/O; added to ready queue [Q E F P H B N I M D]
time 14300ms: Process O (tau 98ms) completed I/O; added to ready queue [Q E O F P H B N I M D]
time 14302ms: Process G (tau 108ms) completed a CPU burst; 38 bursts to go [Q E O F P H B N I M D]
time 14302ms: Recalculated tau = 109ms for process G [Q E O F P H B N I M D]
time 14302ms: Process G switching out of CPU; will block on I/O until time 14461ms [Q E O F P H B N I M D]
time 14306ms: Process E (tau 52ms) started using the CPU for 156ms burst [Q O F P H B N I M D]
time 14461ms: Process G (tau 109ms) completed I/O; added to ready queue [Q O G F P H B N I M D]
time 14462ms: Process E (tau 52ms) completed a CPU burst; 33 bursts to go [Q O G F P H B N I M D]
time 14462ms: Recalculated tau = 104ms for process E [Q O G F P H B N I M D]
time 14462ms: Process E switching out of CPU; will block on I/O until time 14564ms [Q O G F P H B N I M D]
time 14466ms: Process O (tau 98ms) started using the CPU for 74ms burst [Q G F P H B N I M D]
time 14540ms: Process O (tau 98ms) completed a CPU burst; 16 bursts to go [Q G F P H B N I M D]
time 14540ms: Recalculated tau = 86ms for process O [Q G F P H B N I M D]
time 14540ms: Process O switching out of CPU; will block on I/O until time 14631ms [Q G F P H B N I M D]
time 14544ms: Process G (tau 109ms) started using the CPU for 77ms burst [Q F P H B N I M D]
time 14564ms: Process E (tau 104ms) completed I/O; added to ready queue [Q E F P H B N I M D]
time 14621ms: Process G (tau 109ms) completed a CPU burst; 37 bursts to go [Q E F P H B N I M D]
time 14621ms: Recalculated tau = 93ms for process G [Q E F P H B N I M D]
time 14621ms: Process G switching out of CPU; will block on I/O until time 14645ms [Q E F P H B N I M D]
time 14625ms: Process E (tau 104ms) started using the CPU for 18ms burst [Q F P H B N I M D]
time 14631ms: Process O (tau 86ms) completed I/O; added to ready queue [Q O F P H B N I M D]
time 14643ms: Process E (tau 104ms) completed a CPU burst; 32 bursts to go [Q O F P H B N I M D]
time 14643ms: Recalculated tau = 61ms for process E [Q O F P H B N I M D]
time 14643ms: Process E switching out of CPU; will block on I/O until time 14689ms [Q O F P H B N I M D]
time 14645ms: Process G (tau 93ms) completed I/O; added to ready queue [Q O G F P H B N I M D]
time 14647ms: Process O (tau 86ms) started using the CPU for 41ms burst [Q G F P H B N I M D]
time 14688ms: Process O (tau 86ms) completed a CPU burst; 15 bursts to go [Q G F P H B N I M D]
time 14688ms: Recalculated tau = 64ms for process O [Q G F P H B N I M D]
time 14688ms: Process O switching out of CPU; will block on I/O until time 14747ms [Q G F P H B N I M D]
time 14689ms: Process E (tau 61ms) completed I/O; added to ready queue [Q E G F P H B N I M D]
time 14692ms: Process E (tau 61ms) started using the CPU for 215ms burst [Q G F P H B N I M D]
time 14747ms: Process O (tau 64ms) completed I/O; added to ready queue [Q O G F P H B N I M D]
time 14907ms: Process E (tau 61ms) completed a CPU burst; 31 bursts to go [Q O G F P H B N I M D]
time 14907ms: Recalculated tau = 138ms for process E [Q O G F P H B N I M D]
time 14907ms: Process E switching out of CPU; will block on I/O until time 14918ms [Q O G F P H B N I M D]
time 14911ms: Process O (tau 64ms) started using the CPU for 57ms burst [Q G F P H B N I M D]
time 14918ms: Process E (tau 138ms) completed I/O; added to ready queue [Q G E F P H B N I M D]
time 14968ms: Process O (tau 64ms) completed a CPU burst; 14 bursts to go [Q G E F P H B N I M D]
time 14968ms: Recalculated tau = 61ms for process O [Q G E F P H B N I M D]
time 14968ms: Process O switching out of CPU; will block on I/O until time 14998ms [Q G E F P H B N I M D]
time 14972ms: Process G (tau 93ms) started using the CPU for 187ms burst [Q E F P H B N I M D]
time 14998ms: Process O (tau 61ms) completed I/O; added to ready queue [Q O E F P H B N I M D]
time 15159ms: Process G (tau 93ms) completed a CPU burst; 36 bursts to go [Q O E F P H B N I M D]
time 15159ms: Recalculated tau = 140ms for process G [Q O E F P H B N I M D]
time 15159ms: Process G switching out of CPU; will block on I/O until time 15367ms [Q O E F P H B N I M D]
time 15163ms: Process O (tau 61ms) started using the CPU for 159ms burst [Q E F P H B N I M D]
time 15322ms: Process O (tau 61ms) completed a CPU burst; 13 bursts to go [Q E F P H B N I M D]
time 15322ms: Recalculated tau = 110ms for process O [Q E F P H B N I M D]
time 15322ms: Process O switching out of CPU; will block on I/O until time 15425ms [Q E F P H B N I M D]
time 15326ms: Process E (tau 138ms) started using the CPU for 224ms burst [Q F P H B N I M D]
time 15367ms: Process G (tau 140ms) completed I/O; added to ready queue [Q G F P H B N I M D]
time 15425ms: Process O (tau 110ms) completed I/O; added to ready queue [Q O G F P H B N I M D]
time 15550ms: Process E (tau 138ms) completed a CPU burst; 30 bursts to go [Q O G F P H B N I M D]
time 15550ms: Recalculated tau = 181ms for process E [Q O G F P H B N I M D]
time 15550ms: Process E switching out of CPU; will block on I/O until time 15660ms [Q O G F P H B N I M D]
time 15554ms: Process O (tau 110ms) started using the CPU for 87ms burst [Q G F P H B N I M D]
time 15641ms: Process O (tau 110ms) completed a CPU burst; 12 bursts to go [Q G F P H B N I M D]
time 15641ms: Recalculated tau = 99ms for process O [Q G F P H B N I M D]
time 15641ms: Process O switching out of CPU; will block on I/O until time 15804ms [Q G F P H B N I M D]
time 15645ms: Process G (tau 140ms) started using the CPU for 62ms burst [Q F P H B N I M D]
time 15660ms: Process E (tau 181ms) completed I/O; added to ready queue [Q F P H B N I M D E]
time 15707ms: Process G (tau 140ms) completed a CPU burst; 35 bursts to go [Q F P H B N I M D E]
time 15707ms: Recalculated tau = 101ms for process G [Q F P H B N I M D E]
time 15707ms: Process G switching out of CPU; will block on I/O until time 15731ms [Q F P H B N I M D E]
time 15711ms: Process F (tau 143ms) started using the CPU for 33ms burst [Q P H B N I M D E]
time 15731ms: Process G (tau 101ms) completed I/O; added to ready queue [Q G P H B N I M D E]
time 15744ms: Process F (tau 143ms) completed a CPU burst; 27 bursts to go [Q G P H B N I M D E]
time 15744ms: Recalculated tau = 88ms for process F [Q G P H B N I M D E]
time 15744ms: Process F switching out of CPU; will block on I/O until time 15802ms [Q G P H B N I M D E]
time 15748ms: Process G (tau 101ms) started using the CPU for 116ms burst [Q P H B N I M D E]
time 15802ms: Process F (tau 88ms) completed I/O; added to ready queue [Q F P H B N I M D E]
time 15804ms: Process O (tau 99ms) completed I/O; added to ready queue [Q F O P H B N I M D E]
time 15864ms: Process G (tau 101ms) completed a CPU burst; 34 bursts to go [Q F O P H B N I M D E]
time 15864ms: Recalculated tau = 109ms for process G [Q F O P H B N I M D E]
time 15864ms: Process G switching out of CPU; will block on I/O until time 15946ms [Q F O P H B N I M D E]
time 15868ms: Process F (tau 88ms) started using the CPU for 76ms burst [Q O P H B N I M D E]
time 15944ms: Process F (tau 88ms) completed a CPU burst; 26 bursts to go [Q O P H B N I M D E]
time 15944ms: Recalculated tau = 82ms for process F [Q O P H B N I M D E]
time 15944ms: Process F switching out of CPU; will block on I/O until time 15984ms [Q O P H B N I M D E]
time 15946ms: Process G (tau 109ms) completed I/O; added to ready queue [Q O G P H B N I M D E]
time 15948ms: Process O (tau 99ms) started using the CPU for 127ms burst [Q G P H B N I M D E]
time 15984ms: Process F (tau 82ms) completed I/O; added to ready queue [Q F G P H B N I M D E]
time 16075ms: Process O (tau 99ms) completed a CPU burst; 11 bursts to go [Q F G P H B N I M D E]
time 16075ms: Recalculated tau = 113ms for process O [Q F G P H B N I M D E]
time 16075ms: Process O switching out of CPU; will block on I/O until time 16293ms [Q F G P H B N I M D E]
time 16079ms: Process F (tau 82ms) started using the CPU for 107ms burst [Q G P H B N I M D E]
time 16186ms: Process F (tau 82ms) completed a CPU burst; 25 bursts to go [Q G P H B N I M D E]
time 16186ms: Recalculated tau = 95ms for process F [Q G P H B N I M D E]
time 16186ms: Process F switching out of CPU; will block on I/O until time 16206ms [Q G P H B N I M D E]
time 16190ms: Process G (tau 109ms) started using the CPU for 127ms burst [Q P H B N I M D E]
time 16206ms: Process F (tau 95ms) completed I/O; added to ready queue [Q F P H B N I M D E]
time 16293ms: Process O (tau 113ms) completed I/O; added to ready queue [Q F O P H B N I M D E]
time 16317ms: Process G (tau 109ms) completed a CPU burst; 33 bursts to go [Q F O P H B N I M D E]
time 16317ms: Recalculated tau = 118ms for process G [Q F O P H B N I M D E]
time 16317ms: Process G switching out of CPU; will block on I/O until time 16365ms [Q F O P H B N I M D E]
time 16321ms: Process F (tau 95ms) started using the CPU for 89ms burst [Q O P H B N I M D E]
time 16365ms: Process G (tau 118ms) completed I/O; added to ready queue [Q O G P H B N I M D E]
time 16410ms: Process F (tau 95ms) completed a CPU burst; 24 bursts to go [Q O G P H B N I M D E]
time 16410ms: Recalculated tau = 92ms for process F [Q O G P H B N I M D E]
time 16410ms: Process F switching out of CPU; will block on I/O until time 16495ms [Q O G P H B N I M D E]
time 16414ms: Process O (tau 113ms) started using the CPU for 9ms burst [Q G P H B N I M D E]
time 16423ms: Process O (tau 113ms) completed a CPU burst; 10 bursts to go [Q G P H B N I M D E]
time 16423ms: Recalculated tau = 61ms for process O [Q G P H B N I M D E]
time 16423ms: Process O switching out of CPU; will block on I/O until time 16432ms [Q G P H B N I M D E]
time 16427ms: Process G (tau 118ms) started using the CPU for 155ms burst [Q P H B N I M D E]
time 16432ms: Process O (tau 61ms) completed I/O; added to ready queue [Q O P H B N I M D E]
time 16495ms: Process F (tau 92ms) completed I/O; added to ready queue [Q O F P H B N I M D E]
time 16582ms: Process G (tau 118ms) completed a CPU burst; 32 bursts to go [Q O F P H B N I M D E]
time 16582ms: Recalculated tau = 137ms for process G [Q O F P H B N I M D E]
time 16582ms: Process G switching out of CPU; will block on I/O until time 16638ms [Q O F P H B N I M D E]
time 16586ms: Process O (tau 61ms) started using the CPU for 54ms burst [Q F P H B N I M D E]
time 16638ms: Process G (tau 137ms) completed I/O; added to ready queue [Q F G P H B N I M D E]
time 16640ms: Process O (tau 61ms) completed a CPU burst; 9 bursts to go [Q F G P H B N I M D E]
time 16640ms: Recalculated tau = 58ms for process O [Q F G P H B N I M D E]
time 16640ms: Process O switching out of CPU; will block on I/O until time 16665ms [Q F G P H B N I M D E]
time 16644ms: Process F (tau 92ms) started using the CPU for 102ms burst [Q G P H B N I M D E]
time 16665ms: Process O (tau 58ms) completed I/O; added to ready queue [Q O G P H B N I M D E]
time 16746ms: Process F (tau 92ms) completed a CPU burst; 23 bursts to go [Q O G P H B N I M D E]
time 16746ms: Recalculated tau = 97ms for process F [Q O G P H B N I M D E]
time 16746ms: Process F switching out of CPU; will block on I/O until time 16883ms [Q O G P H B N I M D E]
time 16750ms: Process O (tau 58ms) started using the CPU for 41ms burst [Q G P H B N I M D E]
time 16791ms: Process O (tau 58ms) completed a CPU burst; 8 bursts to go [Q G P H B N I M D E]
time 16791ms: Recalculated tau = 50ms for process O [Q G P H B N I M D E]
time 16791ms: Process O switching out of CPU; will block on I/O until time 16820ms [Q G P H B N I M D E]
time 16795ms: Process G (tau 137ms) started using the CPU for 6ms burst [Q P H B N I M D E]
time 16801ms: Process G (tau 137ms) completed a CPU burst; 31 bursts to go [Q P H B N I M D E]
time 16801ms: Recalculated tau = 72ms for process G [Q P H B N I M D E]
time 16801ms: Process G switching out of CPU; will block on I/O until time 16967ms [Q P H B N I M D E]
time 16805ms: Process P (tau 146ms) started using the CPU for 83ms burst [Q H B N I M D E]
time 16820ms: Process O (tau 50ms) completed I/O; added to ready queue [Q O H B N I M D E]
time 16883ms: Process F (tau 97ms) completed I/O; added to ready queue [Q O F H B N I M D E]
time 16888ms: Process P (tau 146ms) completed a CPU burst; 4 bursts to go [Q O F H B N I M D E]
time 16888ms: Recalculated tau = 115ms for process P [Q O F H B N I M D E]
time 16888ms: Process P switching out of CPU; will block on I/O until time 16917ms [Q O F H B N I M D E]
time 16892ms: Process O (tau 50ms) started using the CPU for 190ms burst [Q F H B N I M D E]
time 16917ms: Process P (tau 115ms) completed I/O; added to ready queue [Q F P H B N I M D E]
time 16967ms: Process G (tau 72ms) completed I/O; added to ready queue [Q G F P H B N I M D E]
time 17082ms: Process O (tau 50ms) completed a CPU burst; 7 bursts to go [Q G F P H B N I M D E]
time 17082ms: Recalculated tau = 120ms for process O [Q G F P H B N I M D E]
time 17082ms: Process O switching out of CPU; will block on I/O until time 17106ms [Q G F P H B N I M D E]
time 17086ms: Process G (tau 72ms) started using the CPU for 15ms burst [Q F P H B N I M D E]
time 17101ms: Process G (tau 72ms) completed a CPU burst; 30 bursts to go [Q F P H B N I M D E]
time 17101ms: Recalculated tau = 44ms for process G [Q F P H B N I M D E]
time 17101ms: Process G switching out of CPU; will block on I/O until time 17332ms [Q F P H B N I M D E]
time 17105ms: Process F (tau 97ms) started using the CPU for 147ms burst [Q P H B N I M D E]
time 17106ms: Process O (tau 120ms) completed I/O; added to ready queue [Q P O H B N I M D E]
time 17252ms: Process F (tau 97ms) completed a CPU burst; 22 bursts to go [Q P O H B N I M D E]
time 17252ms: Recalculated tau = 122ms for process F [Q P O H B N I M D E]
time 17252ms: Process F switching out of CPU; will block on I/O until time 17259ms [Q P O H B N I M D E]
time 17256ms: Process P (tau 115ms) started using the CPU for 75ms burst [Q O H B N I M D E]
time 17259ms: Process F (tau 122ms) completed I/O; added to ready queue [Q O F H B N I M D E]
time 17331ms: Process P (tau 115ms) completed a CPU burst; 3 bursts to go [Q O F H B N I M D E]
time 17331ms: Recalculated tau = 95ms for process P [Q O F H B N I M D E]
time 17331ms: Process P switching out of CPU; will block on I/O until time 17351ms [Q O F H B N I M D E]
time 17332ms: Process G (tau 44ms) completed I/O; added to ready queue [Q G O F H B N I M D E]
time 17335ms: Process G (tau 44ms) started using the CPU for 131ms burst [Q O F H B N I M D E]
time 17351ms: Process P (tau 95ms) completed I/O; added to ready queue [Q P O F H B N I M D E]
time 17466ms: Process G (tau 44ms) completed a CPU burst; 29 bursts to go [Q P O F H B N I M D E]
time 17466ms: Recalculated tau = 88ms for process G [Q P O F H B N I M D E]
time 17466ms: Process G switching out of CPU; will block on I/O until time 17476ms [Q P O F H B N I M D E]
time 17470ms: Process P (tau 95ms) started using the CPU for 1ms burst [Q O F H B N I M D E]
time 17471ms: Process P (tau 95ms) completed a CPU burst; 2 bursts to go [Q O F H B N I M D E]
time 17471ms: Recalculated tau = 48ms for process P [Q O F H B N I M D E]
time 17471ms: Process P switching out of CPU; will block on I/O until time 17491ms [Q O F H B N I M D E]
time 17475ms: Process O (tau 120ms) started using the CPU for 30ms burst [Q F H B N I M D E]
time 17476ms: Process G (tau 88ms) completed I/O; added to ready queue [Q G F H B N I M D E]
time 17491ms: Process P (tau 48ms) completed I/O; added to ready queue [Q P G F H B N I M D E]
time 17505ms: Process O (tau 120ms) completed a CPU burst; 6 bursts to go [Q P G F H B N I M D E]
time 17505ms: Recalculated tau = 75ms for process O [Q P G F H B N I M D E]
time 17505ms: Process O switching out of CPU; will block on I/O until time 17538ms [Q P G F H B N I M D E]
time 17509ms: Process P (tau 48ms) started using the CPU for 131ms burst [Q G F H B N I M D E]
time 17538ms: Process O (tau 75ms) completed I/O; added to ready queue [Q O G F H B N I M D E]
time 17640ms: Process P (tau 48ms) completed a CPU burst; 1 burst to go [Q O G F H B N I M D E]
time 17640ms: Recalculated tau = 90ms for process P [Q O G F H B N I M D E]
time 17640ms: Process P switching out of CPU; will block on I/O until time 17687ms [Q O G F H B N I M D E]
time 17644ms: Process O (tau 75ms) started using the CPU for 250ms burst [Q G F H B N I M D E]
