Process A [NEW] (arrival time 102 ms) 85 CPU bursts (tau 1000ms)
Process B [NEW] (arrival time 365 ms) 6 CPU bursts (tau 1000ms)
Process C [NEW] (arrival time 246 ms) 95 CPU bursts (tau 1000ms)
Process D [NEW] (arrival time 388 ms) 57 CPU bursts (tau 1000ms)
Process E [NEW] (arrival time 1515 ms) 83 CPU bursts (tau 1000ms)
Process F [NEW] (arrival time 1684 ms) 97 CPU bursts (tau 1000ms)
Process G [NEW] (arrival time 669 ms) 1 CPU burst (tau 1000ms)
Process H [NEW] (arrival time 376 ms) 49 CPU bursts (tau 1000ms)
time 0ms: Simulator started for SJF [Q <empty>]
time 102ms: Process A (tau 1000ms) arrived; added to ready queue [Q A]
time 104ms: Process A (tau 1000ms) started using the CPU for 1031ms burst [Q <empty>]
time 246ms: Process C (tau 1000ms) arrived; added to ready queue [Q C]
time 365ms: Process B (tau 1000ms) arrived; added to ready queue [Q B C]
time 376ms: Process H (tau 1000ms) arrived; added to ready queue [Q B C H]
time 388ms: Process D (tau 1000ms) arrived; added to ready queue [Q B C D H]
time 669ms: Process G (tau 1000ms) arrived; added to ready queue [Q B C D G H]
time 1135ms: Process A (tau 1000ms) completed a CPU burst; 84 bursts to go [Q B C D G H]
time 1135ms: Recalculated tau = 1016ms for process A [Q B C D G H]
time 1135ms: Process A switching out of CPU; will block on I/O until time 1547ms [Q B C D G H]
time 1139ms: Process B (tau 1000ms) started using the CPU for 848ms burst [Q C D G H]
time 1515ms: Process E (tau 1000ms) arrived; added to ready queue [Q C D E G H]
time 1547ms: Process A (tau 1016ms) completed I/O; added to ready queue [Q C D E G H A]
time 1684ms: Process F (tau 1000ms) arrived; added to ready queue [Q C D E F G H A]
time 1987ms: Process B (tau 1000ms) completed a CPU burst; 5 bursts to go [Q C D E F G H A]
time 1987ms: Recalculated tau = 924ms for process B [Q C D E F G H A]
time 1987ms: Process B switching out of CPU; will block on I/O until time 2935ms [Q C D E F G H A]
time 1991ms: Process C (tau 1000ms) started using the CPU for 3274ms burst [Q D E F G H A]
time 2935ms: Process B (tau 924ms) completed I/O; added to ready queue [Q B D E F G H A]
time 5265ms: Process C (tau 1000ms) completed a CPU burst; 94 bursts to go [Q B D E F G H A]
time 5265ms: Recalculated tau = 2137ms for process C [Q B D E F G H A]
time 5265ms: Process C switching out of CPU; will block on I/O until time 5357ms [Q B D E F G H A]
time 5269ms: Process B (tau 924ms) started using the CPU for 859ms burst [Q D E F G H A]
time 5357ms: Process C (tau 2137ms) completed I/O; added to ready queue [Q D E F G H A C]
time 6128ms: Process B (tau 924ms) completed a CPU burst; 4 bursts to go [Q D E F G H A C]
time 6128ms: Recalculated tau = 892ms for process B [Q D E F G H A C]
time 6128ms: Process B switching out of CPU; will block on I/O until time 6802ms [Q D E F G H A C]
time 6132ms: Process D (tau 1000ms) started using the CPU for 722ms burst [Q E F G H A C]
time 6802ms: Process B (tau 892ms) completed I/O; added to ready queue [Q B E F G H A C]
time 6854ms: Process D (tau 1000ms) completed a CPU burst; 56 bursts to go [Q B E F G H A C]
time 6854ms: Recalculated tau = 861ms for process D [Q B E F G H A C]
time 6854ms: Process D switching out of CPU; will block on I/O until time 7944ms [Q B E F G H A C]
time 6858ms: Process B (tau 892ms) started using the CPU for 2199ms burst [Q E F G H A C]
time 7944ms: Process D (tau 861ms) completed I/O; added to ready queue [Q D E F G H A C]
time 9057ms: Process B (tau 892ms) completed a CPU burst; 3 bursts to go [Q D E F G H A C]
time 9057ms: Recalculated tau = 1546ms for process B [Q D E F G H A C]
time 9057ms: Process B switching out of CPU; will block on I/O until time 9446ms [Q D E F G H A C]
time 9061ms: Process D (tau 861ms) started using the CPU for 293ms burst [Q E F G H A C]
time 9354ms: Process D (tau 861ms) completed a CPU burst; 55 bursts to go [Q E F G H A C]
time 9354ms: Recalculated tau = 577ms for process D [Q E F G H A C]
time 9354ms: Process D switching out of CPU; will block on I/O until time 9669ms [Q E F G H A C]
time 9358ms: Process E (tau 1000ms) started using the CPU for 391ms burst [Q F G H A C]
time 9446ms: Process B (tau 1546ms) completed I/O; added to ready queue [Q F G H A B C]
time 9669ms: Process D (tau 577ms) completed I/O; added to ready queue [Q D F G H A B C]
time 9749ms: Process E (tau 1000ms) completed a CPU burst; 82 bursts to go [Q D F G H A B C]
time 9749ms: Recalculated tau = 696ms for process E [Q D F G H A B C]
time 9749ms: Process E switching out of CPU; will block on I/O until time 10312ms [Q D F G H A B C]
time 9753ms: Process D (tau 577ms) started using the CPU for 375ms burst [Q F G H A B C]
time 10128ms: Process D (tau 577ms) completed a CPU burst; 54 bursts to go [Q F G H A B C]
time 10128ms: Recalculated tau = 476ms for process D [Q F G H A B C]
time 10128ms: Process D switching out of CPU; will block on I/O until time 10957ms [Q F G H A B C]
time 10132ms: Process F (tau 1000ms) started using the CPU for 18ms burst [Q G H A B C]
time 10150ms: Process F (tau 1000ms) completed a CPU burst; 96 bursts to go [Q G H A B C]
time 10150ms: Recalculated tau = 509ms for process F [Q G H A B C]
time 10150ms: Process F switching out of CPU; will block on I/O until time 11712ms [Q G H A B C]
time 10154ms: Process G (tau 1000ms) started using the CPU for 543ms burst [Q H A B C]
time 10312ms: Process E (tau 696ms) completed I/O; added to ready queue [Q E H A B C]
time 10697ms: Process G terminated [Q E H A B C]
time 10701ms: Process E (tau 696ms) started using the CPU for 1198ms burst [Q H A B C]
time 10957ms: Process D (tau 476ms) completed I/O; added to ready queue [Q D H A B C]
time 11712ms: Process F (tau 509ms) completed I/O; added to ready queue [Q D F H A B C]
time 11899ms: Process E (tau 696ms) completed a CPU burst; 81 bursts to go [Q D F H A B C]
time 11899ms: Recalculated tau = 947ms for process E [Q D F H A B C]
time 11899ms: Process E switching out of CPU; will block on I/O until time 15072ms [Q D F H A B C]
time 11903ms: Process D (tau 476ms) started using the CPU for 245ms burst [Q F H A B C]
time 12148ms: Process D (tau 476ms) completed a CPU burst; 53 bursts to go [Q F H A B C]
time 12148ms: Recalculated tau = 361ms for process D [Q F H A B C]
time 12148ms: Process D switching out of CPU; will block on I/O until time 12454ms [Q F H A B C]
time 12152ms: Process F (tau 509ms) started using the CPU for 1494ms burst [Q H A B C]
time 12454ms: Process D (tau 361ms) completed I/O; added to ready queue [Q D H A B C]
time 13646ms: Process F (tau 509ms) completed a CPU burst; 95 bursts to go [Q D H A B C]
time 13646ms: Recalculated tau = 1002ms for process F [Q D H A B C]
time 13646ms: Process F switching out of CPU; will block on I/O until time 13771ms [Q D H A B C]
time 13650ms: Process D (tau 361ms) started using the CPU for 855ms burst [Q H A B C]
time 13771ms: Process F (tau 1002ms) completed I/O; added to ready queue [Q H F A B C]
time 14505ms: Process D (tau 361ms) completed a CPU burst; 52 bursts to go [Q H F A B C]
time 14505ms: Recalculated tau = 608ms for process D [Q H F A B C]
time 14505ms: Process D switching out of CPU; will block on I/O until time 16847ms [Q H F A B C]
time 14509ms: Process H (tau 1000ms) started using the CPU for 340ms burst [Q F A B C]
time 14849ms: Process H (tau 1000ms) completed a CPU burst; 48 bursts to go [Q F A B C]
time 14849ms: Recalculated tau = 670ms for process H [Q F A B C]
time 14849ms: Process H switching out of CPU; will block on I/O until time 15467ms [Q F A B C]
time 14853ms: Process F (tau 1002ms) started using the CPU for 315ms burst [Q A B C]
time 15072ms: Process E (tau 947ms) completed I/O; added to ready queue [Q E A B C]
time 15168ms: Process F (tau 1002ms) completed a CPU burst; 94 bursts to go [Q E A B C]
time 15168ms: Recalculated tau = 659ms for process F [Q E A B C]
time 15168ms: Process F switching out of CPU; will block on I/O until time 15637ms [Q E A B C]
time 15172ms: Process E (tau 947ms) started using the CPU for 1339ms burst [Q A B C]
time 15467ms: Process H (tau 670ms) completed I/O; added to ready queue [Q H A B C]
time 15637ms: Process F (tau 659ms) completed I/O; added to ready queue [Q F H A B C]
time 16511ms: Process E (tau 947ms) completed a CPU burst; 80 bursts to go [Q F H A B C]
time 16511ms: Recalculated tau = 1143ms for process E [Q F H A B C]
time 16511ms: Process E switching out of CPU; will block on I/O until time 17583ms [Q F H A B C]
time 16515ms: Process F (tau 659ms) started using the CPU for 890ms burst [Q H A B C]
time 16847ms: Process D (tau 608ms) completed I/O; added to ready queue [Q D H A B C]
time 17405ms: Process F (tau 659ms) completed a CPU burst; 93 bursts to go [Q D H A B C]
time 17405ms: Recalculated tau = 775ms for process F [Q D H A B C]
time 17405ms: Process F switching out of CPU; will block on I/O until time 17789ms [Q D H A B C]
time 17409ms: Process D (tau 608ms) started using the CPU for 1730ms burst [Q H A B C]
time 17583ms: Process E (tau 1143ms) completed I/O; added to ready queue [Q H A E B C]
time 17789ms: Process F (tau 775ms) completed I/O; added to ready queue [Q H F A E B C]
time 19139ms: Process D (tau 608ms) completed a CPU burst; 51 bursts to go [Q H F A E B C]
time 19139ms: Recalculated tau = 1169ms for process D [Q H F A E B C]
time 19139ms: Process D switching out of CPU; will block on I/O until time 19995ms [Q H F A E B C]
time 19143ms: Process H (tau 670ms) started using the CPU for 264ms burst [Q F A E B C]
time 19407ms: Process H (tau 670ms) completed a CPU burst; 47 bursts to go [Q F A E B C]
time 19407ms: Recalculated tau = 467ms for process H [Q F A E B C]
time 19407ms: Process H switching out of CPU; will block on I/O until time 19546ms [Q F A E B C]
time 19411ms: Process F (tau 775ms) started using the CPU for 3843ms burst [Q A E B C]
time 19546ms: Process H (tau 467ms) completed I/O; added to ready queue [Q H A E B C]
time 19995ms: Process D (tau 1169ms) completed I/O; added to ready queue [Q H A E D B C]
time 23254ms: Process F (tau 775ms) completed a CPU burst; 92 bursts to go [Q H A E D B C]
time 23254ms: Recalculated tau = 2309ms for process F [Q H A E D B C]
time 23254ms: Process F switching out of CPU; will block on I/O until time 25346ms [Q H A E D B C]
time 23258ms: Process H (tau 467ms) started using the CPU for 1555ms burst [Q A E D B C]
time 24813ms: Process H (tau 467ms) completed a CPU burst; 46 bursts to go [Q A E D B C]
time 24813ms: Recalculated tau = 1011ms for process H [Q A E D B C]
time 24813ms: Process H switching out of CPU; will block on I/O until time 25279ms [Q A E D B C]
time 24817ms: Process A (tau 1016ms) started using the CPU for 197ms burst [Q E D B C]
time 25014ms: Process A (tau 1016ms) completed a CPU burst; 83 bursts to go [Q E D B C]
time 25014ms: Recalculated tau = 607ms for process A [Q E D B C]
time 25014ms: Process A switching out of CPU; will block on I/O until time 25515ms [Q E D B C]
time 25018ms: Process E (tau 1143ms) started using the CPU for 136ms burst [Q D B C]
time 25154ms: Process E (tau 1143ms) completed a CPU burst; 79 bursts to go [Q D B C]
time 25154ms: Recalculated tau = 640ms for process E [Q D B C]
time 25154ms: Process E switching out of CPU; will block on I/O until time 26321ms [Q D B C]
time 25158ms: Process D (tau 1169ms) started using the CPU for 601ms burst [Q B C]
time 25279ms: Process H (tau 1011ms) completed I/O; added to ready queue [Q H B C]
time 25346ms: Process F (tau 2309ms) completed I/O; added to ready queue [Q H B C F]
time 25515ms: Process A (tau 607ms) completed I/O; added to ready queue [Q A H B C F]
time 25759ms: Process D (tau 1169ms) completed a CPU burst; 50 bursts to go [Q A H B C F]
time 25759ms: Recalculated tau = 885ms for process D [Q A H B C F]
time 25759ms: Process D switching out of CPU; will block on I/O until time 25997ms [Q A H B C F]
time 25763ms: Process A (tau 607ms) started using the CPU for 923ms burst [Q H B C F]
time 25997ms: Process D (tau 885ms) completed I/O; added to ready queue [Q D H B C F]
time 26321ms: Process E (tau 640ms) completed I/O; added to ready queue [Q E D H B C F]
time 26686ms: Process A (tau 607ms) completed a CPU burst; 82 bursts to go [Q E D H B C F]
time 26686ms: Recalculated tau = 765ms for process A [Q E D H B C F]
time 26686ms: Process A switching out of CPU; will block on I/O until time 28550ms [Q E D H B C F]
time 26690ms: Process E (tau 640ms) started using the CPU for 2127ms burst [Q D H B C F]
time 28550ms: Process A (tau 765ms) completed I/O; added to ready queue [Q A D H B C F]
time 28817ms: Process E (tau 640ms) completed a CPU burst; 78 bursts to go [Q A D H B C F]
time 28817ms: Recalculated tau = 1384ms for process E [Q A D H B C F]
time 28817ms: Process E switching out of CPU; will block on I/O until time 29877ms [Q A D H B C F]
time 28821ms: Process A (tau 765ms) started using the CPU for 25ms burst [Q D H B C F]
time 28846ms: Process A (tau 765ms) completed a CPU burst; 81 bursts to go [Q D H B C F]
time 28846ms: Recalculated tau = 395ms for process A [Q D H B C F]
time 28846ms: Process A switching out of CPU; will block on I/O until time 29541ms [Q D H B C F]
time 28850ms: Process D (tau 885ms) started using the CPU for 2089ms burst [Q H B C F]
time 29541ms: Process A (tau 395ms) completed I/O; added to ready queue [Q A H B C F]
time 29877ms: Process E (tau 1384ms) completed I/O; added to ready queue [Q A H E B C F]
time 30939ms: Process D (tau 885ms) completed a CPU burst; 49 bursts to go [Q A H E B C F]
time 30939ms: Recalculated tau = 1487ms for process D [Q A H E B C F]
time 30939ms: Process D switching out of CPU; will block on I/O until time 31163ms [Q A H E B C F]
time 30943ms: Process A (tau 395ms) started using the CPU for 977ms burst [Q H E B C F]
time 31163ms: Process D (tau 1487ms) completed I/O; added to ready queue [Q H E D B C F]
time 31920ms: Process A (tau 395ms) completed a CPU burst; 80 bursts to go [Q H E D B C F]
time 31920ms: Recalculated tau = 686ms for process A [Q H E D B C F]
time 31920ms: Process A switching out of CPU; will block on I/O until time 32816ms [Q H E D B C F]
time 31924ms: Process H (tau 1011ms) started using the CPU for 2705ms burst [Q E D B C F]
time 32816ms: Process A (tau 686ms) completed I/O; added to ready queue [Q A E D B C F]
time 34629ms: Process H (tau 1011ms) completed a CPU burst; 45 bursts to go [Q A E D B C F]
time 34629ms: Recalculated tau = 1858ms for process H [Q A E D B C F]
time 34629ms: Process H switching out of CPU; will block on I/O until time 35032ms [Q A E D B C F]
time 34633ms: Process A (tau 686ms) started using the CPU for 1095ms burst [Q E D B C F]
time 35032ms: Process H (tau 1858ms) completed I/O; added to ready queue [Q E D B H C F]
time 35728ms: Process A (tau 686ms) completed a CPU burst; 79 bursts to go [Q E D B H C F]
time 35728ms: Recalculated tau = 891ms for process A [Q E D B H C F]
time 35728ms: Process A switching out of CPU; will block on I/O until time 36069ms [Q E D B H C F]
time 35732ms: Process E (tau 1384ms) started using the CPU for 351ms burst [Q D B H C F]
time 36069ms: Process A (tau 891ms) completed I/O; added to ready queue [Q A D B H C F]
time 36083ms: Process E (tau 1384ms) completed a CPU burst; 77 bursts to go [Q A D B H C F]
time 36083ms: Recalculated tau = 868ms for process E [Q A D B H C F]
time 36083ms: Process E switching out of CPU; will block on I/O until time 36182ms [Q A D B H C F]
time 36087ms: Process A (tau 891ms) started using the CPU for 117ms burst [Q D B H C F]
time 36182ms: Process E (tau 868ms) completed I/O; added to ready queue [Q E D B H C F]
time 36204ms: Process A (tau 891ms) completed a CPU burst; 78 bursts to go [Q E D B H C F]
time 36204ms: Recalculated tau = 504ms for process A [Q E D B H C F]
time 36204ms: Process A switching out of CPU; will block on I/O until time 37919ms [Q E D B H C F]
time 36208ms: Process E (tau 868ms) started using the CPU for 2531ms burst [Q D B H C F]
time 37919ms: Process A (tau 504ms) completed I/O; added to ready queue [Q A D B H C F]
time 38739ms: Process E (tau 868ms) completed a CPU burst; 76 bursts to go [Q A D B H C F]
time 38739ms: Recalculated tau = 1700ms for process E [Q A D B H C F]
time 38739ms: Process E switching out of CPU; will block on I/O until time 39792ms [Q A D B H C F]
time 38743ms: Process A (tau 504ms) started using the CPU for 533ms burst [Q D B H C F]
time 39276ms: Process A (tau 504ms) completed a CPU burst; 77 bursts to go [Q D B H C F]
time 39276ms: Recalculated tau = 519ms for process A [Q D B H C F]
time 39276ms: Process A switching out of CPU; will block on I/O until time 39900ms [Q D B H C F]
time 39280ms: Process D (tau 1487ms) started using the CPU for 432ms burst [Q B H C F]
time 39712ms: Process D (tau 1487ms) completed a CPU burst; 48 bursts to go [Q B H C F]
time 39712ms: Recalculated tau = 960ms for process D [Q B H C F]
time 39712ms: Process D switching out of CPU; will block on I/O until time 40757ms [Q B H C F]
time 39716ms: Process B (tau 1546ms) started using the CPU for 21ms burst [Q H C F]
time 39737ms: Process B (tau 1546ms) completed a CPU burst; 2 bursts to go [Q H C F]
time 39737ms: Recalculated tau = 784ms for process B [Q H C F]
time 39737ms: Process B switching out of CPU; will block on I/O until time 39926ms [Q H C F]
time 39741ms: Process H (tau 1858ms) started using the CPU for 1716ms burst [Q C F]
time 39792ms: Process E (tau 1700ms) completed I/O; added to ready queue [Q E C F]
time 39900ms: Process A (tau 519ms) completed I/O; added to ready queue [Q A E C F]
time 39926ms: Process B (tau 784ms) completed I/O; added to ready queue [Q A B E C F]
time 40757ms: Process D (tau 960ms) completed I/O; added to ready queue [Q A B D E C F]
time 41457ms: Process H (tau 1858ms) completed a CPU burst; 44 bursts to go [Q A B D E C F]
time 41457ms: Recalculated tau = 1787ms for process H [Q A B D E C F]
time 41457ms: Process H switching out of CPU; will block on I/O until time 41904ms [Q A B D E C F]
time 41461ms: Process A (tau 519ms) started using the CPU for 274ms burst [Q B D E C F]
time 41735ms: Process A (tau 519ms) completed a CPU burst; 76 bursts to go [Q B D E C F]
time 41735ms: Recalculated tau = 397ms for process A [Q B D E C F]
time 41735ms: Process A switching out of CPU; will block on I/O until time 44094ms [Q B D E C F]
time 41739ms: Process B (tau 784ms) started using the CPU for 909ms burst [Q D E C F]
time 41904ms: Process H (tau 1787ms) completed I/O; added to ready queue [Q D E H C F]
time 42648ms: Process B (tau 784ms) completed a CPU burst; 1 burst to go [Q D E H C F]
time 42648ms: Recalculated tau = 847ms for process B [Q D E H C F]
time 42648ms: Process B switching out of CPU; will block on I/O until time 45037ms [Q D E H C F]
time 42652ms: Process D (tau 960ms) started using the CPU for 812ms burst [Q E H C F]
time 43464ms: Process D (tau 960ms) completed a CPU burst; 47 bursts to go [Q E H C F]
time 43464ms: Recalculated tau = 886ms for process D [Q E H C F]
time 43464ms: Process D switching out of CPU; will block on I/O until time 43862ms [Q E H C F]
time 43468ms: Process E (tau 1700ms) started using the CPU for 2079ms burst [Q H C F]
time 43862ms: Process D (tau 886ms) completed I/O; added to ready queue [Q D H C F]
time 44094ms: Process A (tau 397ms) completed I/O; added to ready queue [Q A D H C F]
time 45037ms: Process B (tau 847ms) completed I/O; added to ready queue [Q A B D H C F]
time 45547ms: Process E (tau 1700ms) completed a CPU burst; 75 bursts to go [Q A B D H C F]
time 45547ms: Recalculated tau = 1890ms for process E [Q A B D H C F]
time 45547ms: Process E switching out of CPU; will block on I/O until time 46618ms [Q A B D H C F]
time 45551ms: Process A (tau 397ms) started using the CPU for 562ms burst [Q B D H C F]
time 46113ms: Process A (tau 397ms) completed a CPU burst; 75 bursts to go [Q B D H C F]
time 46113ms: Recalculated tau = 480ms for process A [Q B D H C F]
time 46113ms: Process A switching out of CPU; will block on I/O until time 48752ms [Q B D H C F]
time 46117ms: Process B (tau 847ms) started using the CPU for 70ms burst [Q D H C F]
time 46187ms: Process B terminated [Q D H C F]
time 46191ms: Process D (tau 886ms) started using the CPU for 1501ms burst [Q H C F]
time 46618ms: Process E (tau 1890ms) completed I/O; added to ready queue [Q H E C F]
time 47692ms: Process D (tau 886ms) completed a CPU burst; 46 bursts to go [Q H E C F]
time 47692ms: Recalculated tau = 1194ms for process D [Q H E C F]
time 47692ms: Process D switching out of CPU; will block on I/O until time 48619ms [Q H E C F]
time 47696ms: Process H (tau 1787ms) started using the CPU for 615ms burst [Q E C F]
time 48311ms: Process H (tau 1787ms) completed a CPU burst; 43 bursts to go [Q E C F]
time 48311ms: Recalculated tau = 1201ms for process H [Q E C F]
time 48311ms: Process H switching out of CPU; will block on I/O until time 48488ms [Q E C F]
time 48315ms: Process E (tau 1890ms) started using the CPU for 466ms burst [Q C F]
time 48488ms: Process H (tau 1201ms) completed I/O; added to ready queue [Q H C F]
time 48619ms: Process D (tau 1194ms) completed I/O; added to ready queue [Q D H C F]
time 48752ms: Process A (tau 480ms) completed I/O; added to ready queue [Q A D H C F]
time 48781ms: Process E (tau 1890ms) completed a CPU burst; 74 bursts to go [Q A D H C F]
time 48781ms: Recalculated tau = 1178ms for process E [Q A D H C F]
time 48781ms: Process E switching out of CPU; will block on I/O until time 50083ms [Q A D H C F]
time 48785ms: Process A (tau 480ms) started using the CPU for 2553ms burst [Q D H C F]
time 50083ms: Process E (tau 1178ms) completed I/O; added to ready queue [Q E D H C F]
time 51338ms: Process A (tau 480ms) completed a CPU burst; 74 bursts to go [Q E D H C F]
time 51338ms: Recalculated tau = 1517ms for process A [Q E D H C F]
time 51338ms: Process A switching out of CPU; will block on I/O until time 51480ms [Q E D H C F]
time 51342ms: Process E (tau 1178ms) started using the CPU for 564ms burst [Q D H C F]
time 51480ms: Process A (tau 1517ms) completed I/O; added to ready queue [Q D H A C F]
time 51906ms: Process E (tau 1178ms) completed a CPU burst; 73 bursts to go [Q D H A C F]
time 51906ms: Recalculated tau = 871ms for process E [Q D H A C F]
time 51906ms: Process E switching out of CPU; will block on I/O until time 53550ms [Q D H A C F]
time 51910ms: Process D (tau 1194ms) started using the CPU for 1717ms burst [Q H A C F]
time 53550ms: Process E (tau 871ms) completed I/O; added to ready queue [Q E H A C F]
time 53627ms: Process D (tau 1194ms) completed a CPU burst; 45 bursts to go [Q E H A C F]
time 53627ms: Recalculated tau = 1456ms for process D [Q E H A C F]
time 53627ms: Process D switching out of CPU; will block on I/O until time 53811ms [Q E H A C F]
time 53631ms: Process E (tau 871ms) started using the CPU for 1518ms burst [Q H A C F]
time 53811ms: Process D (tau 1456ms) completed I/O; added to ready queue [Q H D A C F]
time 55149ms: Process E (tau 871ms) completed a CPU burst; 72 bursts to go [Q H D A C F]
time 55149ms: Recalculated tau = 1195ms for process E [Q H D A C F]
time 55149ms: Process E switching out of CPU; will block on I/O until time 55815ms [Q H D A C F]
time 55153ms: Process H (tau 1201ms) started using the CPU for 828ms burst [Q D A C F]
time 55815ms: Process E (tau 1195ms) completed I/O; added to ready queue [Q E D A C F]
time 55981ms: Process H (tau 1201ms) completed a CPU burst; 42 bursts to go [Q E D A C F]
time 55981ms: Recalculated tau = 1015ms for process H [Q E D A C F]
time 55981ms: Process H switching out of CPU; will block on I/O until time 57822ms [Q E D A C F]
time 55985ms: Process E (tau 1195ms) started using the CPU for 740ms burst [Q D A C F]
time 56725ms: Process E (tau 1195ms) completed a CPU burst; 71 bursts to go [Q D A C F]
time 56725ms: Recalculated tau = 968ms for process E [Q D A C F]
time 56725ms: Process E switching out of CPU; will block on I/O until time 57426ms [Q D A C F]
time 56729ms: Process D (tau 1456ms) started using the CPU for 1319ms burst [Q A C F]
time 57426ms: Process E (tau 968ms) completed I/O; added to ready queue [Q E A C F]
time 57822ms: Process H (tau 1015ms) completed I/O; added to ready queue [Q E H A C F]
time 58048ms: Process D (tau 1456ms) completed a CPU burst; 44 bursts to go [Q E H A C F]
time 58048ms: Recalculated tau = 1388ms for process D [Q E H A C F]
time 58048ms: Process D switching out of CPU; will block on I/O until time 58409ms [Q E H A C F]
time 58052ms: Process E (tau 968ms) started using the CPU for 420ms burst [Q H A C F]
time 58409ms: Process D (tau 1388ms) completed I/O; added to ready queue [Q H D A C F]
time 58472ms: Process E (tau 968ms) completed a CPU burst; 70 bursts to go [Q H D A C F]
time 58472ms: Recalculated tau = 694ms for process E [Q H D A C F]
time 58472ms: Process E switching out of CPU; will block on I/O until time 58794ms [Q H D A C F]
time 58476ms: Process H (tau 1015ms) started using the CPU for 863ms burst [Q D A C F]
time 58794ms: Process E (tau 694ms) completed I/O; added to ready queue [Q E D A C F]
time 59339ms: Process H (tau 1015ms) completed a CPU burst; 41 bursts to go [Q E D A C F]
time 59339ms: Recalculated tau = 939ms for process H [Q E D A C F]
time 59339ms: Process H switching out of CPU; will block on I/O until time 60008ms [Q E D A C F]
time 59343ms: Process E (tau 694ms) started using the CPU for 1497ms burst [Q D A C F]
time 60008ms: Process H (tau 939ms) completed I/O; added to ready queue [Q H D A C F]
time 60840ms: Process E (tau 694ms) completed a CPU burst; 69 bursts to go [Q H D A C F]
time 60840ms: Recalculated tau = 1096ms for process E [Q H D A C F]
time 60840ms: Process E switching out of CPU; will block on I/O until time 61333ms [Q H D A C F]
time 60844ms: Process H (tau 939ms) started using the CPU for 64ms burst [Q D A C F]
time 60908ms: Process H (tau 939ms) completed a CPU burst; 40 bursts to go [Q D A C F]
time 60908ms: Recalculated tau = 502ms for process H [Q D A C F]
time 60908ms: Process H switching out of CPU; will block on I/O until time 61609ms [Q D A C F]
time 60912ms: Process D (tau 1388ms) started using the CPU for 2816ms burst [Q A C F]
time 61333ms: Process E (tau 1096ms) completed I/O; added to ready queue [Q E A C F]
time 61609ms: Process H (tau 502ms) completed I/O; added to ready queue [Q H E A C F]
time 63728ms: Process D (tau 1388ms) completed a CPU burst; 43 bursts to go [Q H E A C F]
time 63728ms: Recalculated tau = 2102ms for process D [Q H E A C F]
time 63728ms: Process D switching out of CPU; will block on I/O until time 65049ms [Q H E A C F]
time 63732ms: Process H (tau 502ms) started using the CPU for 1329ms burst [Q E A C F]
time 65049ms: Process D (tau 2102ms) completed I/O; added to ready queue [Q E A D C F]
time 65061ms: Process H (tau 502ms) completed a CPU burst; 39 bursts to go [Q E A D C F]
time 65061ms: Recalculated tau = 916ms for process H [Q E A D C F]
time 65061ms: Process H switching out of CPU; will block on I/O until time 65504ms [Q E A D C F]
time 65065ms: Process E (tau 1096ms) started using the CPU for 985ms burst [Q A D C F]
time 65504ms: Process H (tau 916ms) completed I/O; added to ready queue [Q H A D C F]
time 66050ms: Process E (tau 1096ms) completed a CPU burst; 68 bursts to go [Q H A D C F]
time 66050ms: Recalculated tau = 1041ms for process E [Q H A D C F]
time 66050ms: Process E switching out of CPU; will block on I/O until time 66162ms [Q H A D C F]
time 66054ms: Process H (tau 916ms) started using the CPU for 2061ms burst [Q A D C F]
time 66162ms: Process E (tau 1041ms) completed I/O; added to ready queue [Q E A D C F]
time 68115ms: Process H (tau 916ms) completed a CPU burst; 38 bursts to go [Q E A D C F]
time 68115ms: Recalculated tau = 1489ms for process H [Q E A D C F]
time 68115ms: Process H switching out of CPU; will block on I/O until time 68458ms [Q E A D C F]
time 68119ms: Process E (tau 1041ms) started using the CPU for 1145ms burst [Q A D C F]
time 68458ms: Process H (tau 1489ms) completed I/O; added to ready queue [Q H A D C F]
time 69264ms: Process E (tau 1041ms) completed a CPU burst; 67 bursts to go [Q H A D C F]
time 69264ms: Recalculated tau = 1093ms for process E [Q H A D C F]
time 69264ms: Process E switching out of CPU; will block on I/O until time 70201ms [Q H A D C F]
time 69268ms: Process H (tau 1489ms) started using the CPU for 1088ms burst [Q A D C F]
time 70201ms: Process E (tau 1093ms) completed I/O; added to ready queue [Q E A D C F]
time 70356ms: Process H (tau 1489ms) completed a CPU burst; 37 bursts to go [Q E A D C F]
time 70356ms: Recalculated tau = 1289ms for process H [Q E A D C F]
time 70356ms: Process H switching out of CPU; will block on I/O until time 70385ms [Q E A D C F]
time 70360ms: Process E (tau 1093ms) started using the CPU for 593ms burst [Q A D C F]
time 70385ms: Process H (tau 1289ms) completed I/O; added to ready queue [Q H A D C F]
time 70953ms: Process E (tau 1093ms) completed a CPU burst; 66 bursts to go [Q H A D C F]
time 70953ms: Recalculated tau = 843ms for process E [Q H A D C F]
time 70953ms: Process E switching out of CPU; will block on I/O until time 71501ms [Q H A D C F]
time 70957ms: Process H (tau 1289ms) started using the CPU for 92ms burst [Q A D C F]
time 71049ms: Process H (tau 1289ms) completed a CPU burst; 36 bursts to go [Q A D C F]
time 71049ms: Recalculated tau = 691ms for process H [Q A D C F]
time 71049ms: Process H switching out of CPU; will block on I/O until time 72431ms [Q A D C F]
time 71053ms: Process A (tau 1517ms) started using the CPU for 1023ms burst [Q D C F]
time 71501ms: Process E (tau 843ms) completed I/O; added to ready queue [Q E D C F]
time 72076ms: Process A (tau 1517ms) completed a CPU burst; 73 bursts to go [Q E D C F]
time 72076ms: Recalculated tau = 1270ms for process A [Q E D C F]
time 72076ms: Process A switching out of CPU; will block on I/O until time 73092ms [Q E D C F]
time 72080ms: Process E (tau 843ms) started using the CPU for 1078ms burst [Q D C F]
time 72431ms: Process H (tau 691ms) completed I/O; added to ready queue [Q H D C F]
time 73092ms: Process A (tau 1270ms) completed I/O; added to ready queue [Q H A D C F]
time 73158ms: Process E (tau 843ms) completed a CPU burst; 65 bursts to go [Q H A D C F]
time 73158ms: Recalculated tau = 961ms for process E [Q H A D C F]
time 73158ms: Process E switching out of CPU; will block on I/O until time 73557ms [Q H A D C F]
time 73162ms: Process H (tau 691ms) started using the CPU for 769ms burst [Q A D C F]
time 73557ms: Process E (tau 961ms) completed I/O; added to ready queue [Q E A D C F]
time 73931ms: Process H (tau 691ms) completed a CPU burst; 35 bursts to go [Q E A D C F]
time 73931ms: Recalculated tau = 730ms for process H [Q E A D C F]
time 73931ms: Process H switching out of CPU; will block on I/O until time 74925ms [Q E A D C F]
time 73935ms: Process E (tau 961ms) started using the CPU for 1045ms burst [Q A D C F]
time 74925ms: Process H (tau 730ms) completed I/O; added to ready queue [Q H A D C F]
time 74980ms: Process E (tau 961ms) completed a CPU burst; 64 bursts to go [Q H A D C F]
time 74980ms: Recalculated tau = 1003ms for process E [Q H A D C F]
time 74980ms: Process E switching out of CPU; will block on I/O until time 75622ms [Q H A D C F]
time 74984ms: Process H (tau 730ms) started using the CPU for 2270ms burst [Q A D C F]
time 75622ms: Process E (tau 1003ms) completed I/O; added to ready queue [Q E A D C F]
time 77254ms: Process H (tau 730ms) completed a CPU burst; 34 bursts to go [Q E A D C F]
time 77254ms: Recalculated tau = 1500ms for process H [Q E A D C F]
time 77254ms: Process H switching out of CPU; will block on I/O until time 77744ms [Q E A D C F]
time 77258ms: Process E (tau 1003ms) started using the CPU for 910ms burst [Q A D C F]
time 77744ms: Process H (tau 1500ms) completed I/O; added to ready queue [Q A H D C F]
time 78168ms: Process E (tau 1003ms) completed a CPU burst; 63 bursts to go [Q A H D C F]
time 78168ms: Recalculated tau = 957ms for process E [Q A H D C F]
time 78168ms: Process E switching out of CPU; will block on I/O until time 81117ms [Q A H D C F]
time 78172ms: Process A (tau 1270ms) started using the CPU for 319ms burst [Q H D C F]
time 78491ms: Process A (tau 1270ms) completed a CPU burst; 72 bursts to go [Q H D C F]
time 78491ms: Recalculated tau = 795ms for process A [Q H D C F]
time 78491ms: Process A switching out of CPU; will block on I/O until time 78731ms [Q H D C F]
time 78495ms: Process H (tau 1500ms) started using the CPU for 2381ms burst [Q D C F]
time 78731ms: Process A (tau 795ms) completed I/O; added to ready queue [Q A D C F]
time 80876ms: Process H (tau 1500ms) completed a CPU burst; 33 bursts to go [Q A D C F]
time 80876ms: Recalculated tau = 1941ms for process H [Q A D C F]
time 80876ms: Process H switching out of CPU; will block on I/O until time 82358ms [Q A D C F]
time 80880ms: Process A (tau 795ms) started using the CPU for 1872ms burst [Q D C F]
time 81117ms: Process E (tau 957ms) completed I/O; added to ready queue [Q E D C F]
time 82358ms: Process H (tau 1941ms) completed I/O; added to ready queue [Q E H D C F]
time 82752ms: Process A (tau 795ms) completed a CPU burst; 71 bursts to go [Q E H D C F]
time 82752ms: Recalculated tau = 1334ms for process A [Q E H D C F]
time 82752ms: Process A switching out of CPU; will block on I/O until time 84095ms [Q E H D C F]
time 82756ms: Process E (tau 957ms) started using the CPU for 2671ms burst [Q H D C F]
time 84095ms: Process A (tau 1334ms) completed I/O; added to ready queue [Q A H D C F]
time 85427ms: Process E (tau 957ms) completed a CPU burst; 62 bursts to go [Q A H D C F]
time 85427ms: Recalculated tau = 1814ms for process E [Q A H D C F]
time 85427ms: Process E switching out of CPU; will block on I/O until time 85458ms [Q A H D C F]
time 85431ms: Process A (tau 1334ms) started using the CPU for 1788ms burst [Q H D C F]
time 85458ms: Process E (tau 1814ms) completed I/O; added to ready queue [Q E H D C F]
time 87219ms: Process A (tau 1334ms) completed a CPU burst; 70 bursts to go [Q E H D C F]
time 87219ms: Recalculated tau = 1561ms for process A [Q E H D C F]
time 87219ms: Process A switching out of CPU; will block on I/O until time 87371ms [Q E H D C F]
time 87223ms: Process E (tau 1814ms) started using the CPU for 734ms burst [Q H D C F]
time 87371ms: Process A (tau 1561ms) completed I/O; added to ready queue [Q A H D C F]
time 87957ms: Process E (tau 1814ms) completed a CPU burst; 61 bursts to go [Q A H D C F]
time 87957ms: Recalculated tau = 1274ms for process E [Q A H D C F]
time 87957ms: Process E switching out of CPU; will block on I/O until time 88100ms [Q A H D C F]
time 87961ms: Process A (tau 1561ms) started using the CPU for 313ms burst [Q H D C F]
time 88100ms: Process E (tau 1274ms) completed I/O; added to ready queue [Q E H D C F]
time 88274ms: Process A (tau 1561ms) completed a CPU burst; 69 bursts to go [Q E H D C F]
time 88274ms: Recalculated tau = 937ms for process A [Q E H D C F]
time 88274ms: Process A switching out of CPU; will block on I/O until time 88357ms [Q E H D C F]
time 88278ms: Process E (tau 1274ms) started using the CPU for 215ms burst [Q H D C F]
time 88357ms: Process A (tau 937ms) completed I/O; added to ready queue [Q A H D C F]
time 88493ms: Process E (tau 1274ms) completed a CPU burst; 60 bursts to go [Q A H D C F]
time 88493ms: Recalculated tau = 745ms for process E [Q A H D C F]
time 88493ms: Process E switching out of CPU; will block on I/O until time 89106ms [Q A H D C F]
time 88497ms: Process A (tau 937ms) started using the CPU for 1135ms burst [Q H D C F]
time 89106ms: Process E (tau 745ms) completed I/O; added to ready queue [Q E H D C F]
time 89632ms: Process A (tau 937ms) completed a CPU burst; 68 bursts to go [Q E H D C F]
time 89632ms: Recalculated tau = 1036ms for process A [Q E H D C F]
time 89632ms: Process A switching out of CPU; will block on I/O until time 89784ms [Q E H D C F]
time 89636ms: Process E (tau 745ms) started using the CPU for 1141ms burst [Q H D C F]
time 89784ms: Process A (tau 1036ms) completed I/O; added to ready queue [Q A H D C F]
time 90777ms: Process E (tau 745ms) completed a CPU burst; 59 bursts to go [Q A H D C F]
time 90777ms: Recalculated tau = 943ms for process E [Q A H D C F]
time 90777ms: Process E switching out of CPU; will block on I/O until time 92742ms [Q A H D C F]
time 90781ms: Process A (tau 1036ms) started using the CPU for 1068ms burst [Q H D C F]
time 91849ms: Process A (tau 1036ms) completed a CPU burst; 67 bursts to go [Q H D C F]
time 91849ms: Recalculated tau = 1052ms for process A [Q H D C F]
time 91849ms: Process A switching out of CPU; will block on I/O until time 91928ms [Q H D C F]
time 91853ms: Process H (tau 1941ms) started using the CPU for 49ms burst [Q D C F]
time 91902ms: Process H (tau 1941ms) completed a CPU burst; 32 bursts to go [Q D C F]
time 91902ms: Recalculated tau = 995ms for process H [Q D C F]
time 91902ms: Process H switching out of CPU; will block on I/O until time 92246ms [Q D C F]
time 91906ms: Process D (tau 2102ms) started using the CPU for 2717ms burst [Q C F]
time 91928ms: Process A (tau 1052ms) completed I/O; added to ready queue [Q A C F]
time 92246ms: Process H (tau 995ms) completed I/O; added to ready queue [Q H A C F]
time 92742ms: Process E (tau 943ms) completed I/O; added to ready queue [Q E H A C F]
time 94623ms: Process D (tau 2102ms) completed a CPU burst; 42 bursts to go [Q E H A C F]
time 94623ms: Recalculated tau = 2410ms for process D [Q E H A C F]
time 94623ms: Process D switching out of CPU; will block on I/O until time 95237ms [Q E H A C F]
time 94627ms: Process E (tau 943ms) started using the CPU for 197ms burst [Q H A C F]
time 94824ms: Process E (tau 943ms) completed a CPU burst; 58 bursts to go [Q H A C F]
time 94824ms: Recalculated tau = 570ms for process E [Q H A C F]
time 94824ms: Process E switching out of CPU; will block on I/O until time 98535ms [Q H A C F]
time 94828ms: Process H (tau 995ms) started using the CPU for 1969ms burst [Q A C F]
time 95237ms: Process D (tau 2410ms) completed I/O; added to ready queue [Q A C F D]
time 96797ms: Process H (tau 995ms) completed a CPU burst; 31 bursts to go [Q A C F D]
time 96797ms: Recalculated tau = 1482ms for process H [Q A C F D]
time 96797ms: Process H switching out of CPU; will block on I/O until time 98479ms [Q A C F D]
time 96801ms: Process A (tau 1052ms) started using the CPU for 447ms burst [Q C F D]
time 97248ms: Process A (tau 1052ms) completed a CPU burst; 66 bursts to go [Q C F D]
time 97248ms: Recalculated tau = 750ms for process A [Q C F D]
time 97248ms: Process A switching out of CPU; will block on I/O until time 97299ms [Q C F D]
time 97252ms: Process C (tau 2137ms) started using the CPU for 633ms burst [Q F D]
time 97299ms: Process A (tau 750ms) completed I/O; added to ready queue [Q A F D]
time 97885ms: Process C (tau 2137ms) completed a CPU burst; 93 bursts to go [Q A F D]
time 97885ms: Recalculated tau = 1385ms for process C [Q A F D]
time 97885ms: Process C switching out of CPU; will block on I/O until time 97931ms [Q A F D]
time 97889ms: Process A (tau 750ms) started using the CPU for 200ms burst [Q F D]
time 97931ms: Process C (tau 1385ms) completed I/O; added to ready queue [Q C F D]
time 98089ms: Process A (tau 750ms) completed a CPU burst; 65 bursts to go [Q C F D]
time 98089ms: Recalculated tau = 475ms for process A [Q C F D]
time 98089ms: Process A switching out of CPU; will block on I/O until time 99206ms [Q C F D]
time 98093ms: Process C (tau 1385ms) started using the CPU for 512ms burst [Q F D]
time 98479ms: Process H (tau 1482ms) completed I/O; added to ready queue [Q H F D]
time 98535ms: Process E (tau 570ms) completed I/O; added to ready queue [Q E H F D]
time 98605ms: Process C (tau 1385ms) completed a CPU burst; 92 bursts to go [Q E H F D]
time 98605ms: Recalculated tau = 949ms for process C [Q E H F D]
time 98605ms: Process C switching out of CPU; will block on I/O until time 100199ms [Q E H F D]
time 98609ms: Process E (tau 570ms) started using the CPU for 708ms burst [Q H F D]
time 99206ms: Process A (tau 475ms) completed I/O; added to ready queue [Q A H F D]
time 99317ms: Process E (tau 570ms) completed a CPU burst; 57 bursts to go [Q A H F D]
time 99317ms: Recalculated tau = 639ms for process E [Q A H F D]
time 99317ms: Process E switching out of CPU; will block on I/O until time 100610ms [Q A H F D]
time 99321ms: Process A (tau 475ms) started using the CPU for 722ms burst [Q H F D]
time 100043ms: Process A (tau 475ms) completed a CPU burst; 64 bursts to go [Q H F D]
time 100043ms: Recalculated tau = 599ms for process A [Q H F D]
time 100043ms: Process A switching out of CPU; will block on I/O until time 100850ms [Q H F D]
time 100047ms: Process H (tau 1482ms) started using the CPU for 622ms burst [Q F D]
time 100199ms: Process C (tau 949ms) completed I/O; added to ready queue [Q C F D]
time 100610ms: Process E (tau 639ms) completed I/O; added to ready queue [Q E C F D]
time 100669ms: Process H (tau 1482ms) completed a CPU burst; 30 bursts to go [Q E C F D]
time 100669ms: Recalculated tau = 1052ms for process H [Q E C F D]
time 100669ms: Process H switching out of CPU; will block on I/O until time 101671ms [Q E C F D]
time 100673ms: Process E (tau 639ms) started using the CPU for 691ms burst [Q C F D]
time 100850ms: Process A (tau 599ms) completed I/O; added to ready queue [Q A C F D]
time 101364ms: Process E (tau 639ms) completed a CPU burst; 56 bursts to go [Q A C F D]
time 101364ms: Recalculated tau = 665ms for process E [Q A C F D]
time 101364ms: Process E switching out of CPU; will block on I/O until time 102098ms [Q A C F D]
time 101368ms: Process A (tau 599ms) started using the CPU for 196ms burst [Q C F D]
time 101564ms: Process A (tau 599ms) completed a CPU burst; 63 bursts to go [Q C F D]
time 101564ms: Recalculated tau = 398ms for process A [Q C F D]
time 101564ms: Process A switching out of CPU; will block on I/O until time 102314ms [Q C F D]
time 101568ms: Process C (tau 949ms) started using the CPU for 102ms burst [Q F D]
time 101670ms: Process C (tau 949ms) completed a CPU burst; 91 bursts to go [Q F D]
time 101670ms: Recalculated tau = 526ms for process C [Q F D]
time 101670ms: Process C switching out of CPU; will block on I/O until time 101811ms [Q F D]
time 101671ms: Process H (tau 1052ms) completed I/O; added to ready queue [Q H F D]
time 101674ms: Process H (tau 1052ms) started using the CPU for 2420ms burst [Q F D]
time 101811ms: Process C (tau 526ms) completed I/O; added to ready queue [Q C F D]
time 102098ms: Process E (tau 665ms) completed I/O; added to ready queue [Q C E F D]
time 102314ms: Process A (tau 398ms) completed I/O; added to ready queue [Q A C E F D]
time 104094ms: Process H (tau 1052ms) completed a CPU burst; 29 bursts to go [Q A C E F D]
time 104094ms: Recalculated tau = 1736ms for process H [Q A C E F D]
time 104094ms: Process H switching out of CPU; will block on I/O until time 104545ms [Q A C E F D]
time 104098ms: Process A (tau 398ms) started using the CPU for 3198ms burst [Q C E F D]
time 104545ms: Process H (tau 1736ms) completed I/O; added to ready queue [Q C E H F D]
time 107296ms: Process A (tau 398ms) completed a CPU burst; 62 bursts to go [Q C E H F D]
time 107296ms: Recalculated tau = 1798ms for process A [Q C E H F D]
time 107296ms: Process A switching out of CPU; will block on I/O until time 109656ms [Q C E H F D]
time 107300ms: Process C (tau 526ms) started using the CPU for 346ms burst [Q E H F D]
time 107646ms: Process C (tau 526ms) completed a CPU burst; 90 bursts to go [Q E H F D]
time 107646ms: Recalculated tau = 436ms for process C [Q E H F D]
time 107646ms: Process C switching out of CPU; will block on I/O until time 108675ms [Q E H F D]
time 107650ms: Process E (tau 665ms) started using the CPU for 98ms burst [Q H F D]
time 107748ms: Process E (tau 665ms) completed a CPU burst; 55 bursts to go [Q H F D]
time 107748ms: Recalculated tau = 382ms for process E [Q H F D]
time 107748ms: Process E switching out of CPU; will block on I/O until time 109059ms [Q H F D]
time 107752ms: Process H (tau 1736ms) started using the CPU for 1623ms burst [Q F D]
time 108675ms: Process C (tau 436ms) completed I/O; added to ready queue [Q C F D]
time 109059ms: Process E (tau 382ms) completed I/O; added to ready queue [Q E C F D]
time 109375ms: Process H (tau 1736ms) completed a CPU burst; 28 bursts to go [Q E C F D]
time 109375ms: Recalculated tau = 1680ms for process H [Q E C F D]
time 109375ms: Process H switching out of CPU; will block on I/O until time 109734ms [Q E C F D]
time 109379ms: Process E (tau 382ms) started using the CPU for 660ms burst [Q C F D]
time 109656ms: Process A (tau 1798ms) completed I/O; added to ready queue [Q C A F D]
time 109734ms: Process H (tau 1680ms) completed I/O; added to ready queue [Q C H A F D]
time 110039ms: Process E (tau 382ms) completed a CPU burst; 54 bursts to go [Q C H A F D]
time 110039ms: Recalculated tau = 521ms for process E [Q C H A F D]
time 110039ms: Process E switching out of CPU; will block on I/O until time 112402ms [Q C H A F D]
time 110043ms: Process C (tau 436ms) started using the CPU for 81ms burst [Q H A F D]
time 110124ms: Process C (tau 436ms) completed a CPU burst; 89 bursts to go [Q H A F D]
time 110124ms: Recalculated tau = 259ms for process C [Q H A F D]
time 110124ms: Process C switching out of CPU; will block on I/O until time 111372ms [Q H A F D]
time 110128ms: Process H (tau 1680ms) started using the CPU for 202ms burst [Q A F D]
time 110330ms: Process H (tau 1680ms) completed a CPU burst; 27 bursts to go [Q A F D]
time 110330ms: Recalculated tau = 941ms for process H [Q A F D]
time 110330ms: Process H switching out of CPU; will block on I/O until time 111293ms [Q A F D]
time 110334ms: Process A (tau 1798ms) started using the CPU for 687ms burst [Q F D]
time 111021ms: Process A (tau 1798ms) completed a CPU burst; 61 bursts to go [Q F D]
time 111021ms: Recalculated tau = 1243ms for process A [Q F D]
time 111021ms: Process A switching out of CPU; will block on I/O until time 111346ms [Q F D]
time 111025ms: Process F (tau 2309ms) started using the CPU for 2701ms burst [Q D]
time 111293ms: Process H (tau 941ms) completed I/O; added to ready queue [Q H D]
time 111346ms: Process A (tau 1243ms) completed I/O; added to ready queue [Q H A D]
time 111372ms: Process C (tau 259ms) completed I/O; added to ready queue [Q C H A D]
time 112402ms: Process E (tau 521ms) completed I/O; added to ready queue [Q C E H A D]
time 113726ms: Process F (tau 2309ms) completed a CPU burst; 91 bursts to go [Q C E H A D]
time 113726ms: Recalculated tau = 2505ms for process F [Q C E H A D]
time 113726ms: Process F switching out of CPU; will block on I/O until time 117339ms [Q C E H A D]
time 113730ms: Process C (tau 259ms) started using the CPU for 1562ms burst [Q E H A D]
time 115292ms: Process C (tau 259ms) completed a CPU burst; 88 bursts to go [Q E H A D]
time 115292ms: Recalculated tau = 911ms for process C [Q E H A D]
time 115292ms: Process C switching out of CPU; will block on I/O until time 115783ms [Q E H A D]
time 115296ms: Process E (tau 521ms) started using the CPU for 445ms burst [Q H A D]
time 115741ms: Process E (tau 521ms) completed a CPU burst; 53 bursts to go [Q H A D]
time 115741ms: Recalculated tau = 483ms for process E [Q H A D]
time 115741ms: Process E switching out of CPU; will block on I/O until time 117579ms [Q H A D]
time 115745ms: Process H (tau 941ms) started using the CPU for 244ms burst [Q A D]
time 115783ms: Process C (tau 911ms) completed I/O; added to ready queue [Q C A D]
time 115989ms: Process H (tau 941ms) completed a CPU burst; 26 bursts to go [Q C A D]
time 115989ms: Recalculated tau = 593ms for process H [Q C A D]
time 115989ms: Process H switching out of CPU; will block on I/O until time 117292ms [Q C A D]
time 115993ms: Process C (tau 911ms) started using the CPU for 280ms burst [Q A D]
time 116273ms: Process C (tau 911ms) completed a CPU burst; 87 bursts to go [Q A D]
time 116273ms: Recalculated tau = 596ms for process C [Q A D]
time 116273ms: Process C switching out of CPU; will block on I/O until time 116285ms [Q A D]
time 116277ms: Process A (tau 1243ms) started using the CPU for 1663ms burst [Q D]
time 116285ms: Process C (tau 596ms) completed I/O; added to ready queue [Q C D]
time 117292ms: Process H (tau 593ms) completed I/O; added to ready queue [Q H C D]
time 117339ms: Process F (tau 2505ms) completed I/O; added to ready queue [Q H C D F]
time 117579ms: Process E (tau 483ms) completed I/O; added to ready queue [Q E H C D F]
time 117940ms: Process A (tau 1243ms) completed a CPU burst; 60 bursts to go [Q E H C D F]
time 117940ms: Recalculated tau = 1453ms for process A [Q E H C D F]
time 117940ms: Process A switching out of CPU; will block on I/O until time 118638ms [Q E H C D F]
time 117944ms: Process E (tau 483ms) started using the CPU for 458ms burst [Q H C D F]
time 118402ms: Process E (tau 483ms) completed a CPU burst; 52 bursts to go [Q H C D F]
time 118402ms: Recalculated tau = 471ms for process E [Q H C D F]
time 118402ms: Process E switching out of CPU; will block on I/O until time 119963ms [Q H C D F]
time 118406ms: Process H (tau 593ms) started using the CPU for 45ms burst [Q C D F]
time 118451ms: Process H (tau 593ms) completed a CPU burst; 25 bursts to go [Q C D F]
time 118451ms: Recalculated tau = 319ms for process H [Q C D F]
time 118451ms: Process H switching out of CPU; will block on I/O until time 120848ms [Q C D F]
time 118455ms: Process C (tau 596ms) started using the CPU for 348ms burst [Q D F]
time 118638ms: Process A (tau 1453ms) completed I/O; added to ready queue [Q A D F]
time 118803ms: Process C (tau 596ms) completed a CPU burst; 86 bursts to go [Q A D F]
time 118803ms: Recalculated tau = 472ms for process C [Q A D F]
time 118803ms: Process C switching out of CPU; will block on I/O until time 119761ms [Q A D F]
time 118807ms: Process A (tau 1453ms) started using the CPU for 174ms burst [Q D F]
time 118981ms: Process A (tau 1453ms) completed a CPU burst; 59 bursts to go [Q D F]
time 118981ms: Recalculated tau = 814ms for process A [Q D F]
time 118981ms: Process A switching out of CPU; will block on I/O until time 119061ms [Q D F]
time 118985ms: Process D (tau 2410ms) started using the CPU for 508ms burst [Q F]
time 119061ms: Process A (tau 814ms) completed I/O; added to ready queue [Q A F]
time 119493ms: Process D (tau 2410ms) completed a CPU burst; 41 bursts to go [Q A F]
time 119493ms: Recalculated tau = 1459ms for process D [Q A F]
time 119493ms: Process D switching out of CPU; will block on I/O until time 120740ms [Q A F]
time 119497ms: Process A (tau 814ms) started using the CPU for 2151ms burst [Q F]
time 119761ms: Process C (tau 472ms) completed I/O; added to ready queue [Q C F]
time 119963ms: Process E (tau 471ms) completed I/O; added to ready queue [Q E C F]
time 120740ms: Process D (tau 1459ms) completed I/O; added to ready queue [Q E C D F]
time 120848ms: Process H (tau 319ms) completed I/O; added to ready queue [Q H E C D F]
time 121648ms: Process A (tau 814ms) completed a CPU burst; 58 bursts to go [Q H E C D F]
time 121648ms: Recalculated tau = 1483ms for process A [Q H E C D F]
time 121648ms: Process A switching out of CPU; will block on I/O until time 121881ms [Q H E C D F]
time 121652ms: Process H (tau 319ms) started using the CPU for 1078ms burst [Q E C D F]
time 121881ms: Process A (tau 1483ms) completed I/O; added to ready queue [Q E C D A F]
time 122730ms: Process H (tau 319ms) completed a CPU burst; 24 bursts to go [Q E C D A F]
time 122730ms: Recalculated tau = 699ms for process H [Q E C D A F]
time 122730ms: Process H switching out of CPU; will block on I/O until time 123980ms [Q E C D A F]
time 122734ms: Process E (tau 471ms) started using the CPU for 170ms burst [Q C D A F]
time 122904ms: Process E (tau 471ms) completed a CPU burst; 51 bursts to go [Q C D A F]
time 122904ms: Recalculated tau = 321ms for process E [Q C D A F]
time 122904ms: Process E switching out of CPU; will block on I/O until time 123156ms [Q C D A F]
time 122908ms: Process C (tau 472ms) started using the CPU for 849ms burst [Q D A F]
time 123156ms: Process E (tau 321ms) completed I/O; added to ready queue [Q E D A F]
time 123757ms: Process C (tau 472ms) completed a CPU burst; 85 bursts to go [Q E D A F]
time 123757ms: Recalculated tau = 661ms for process C [Q E D A F]
time 123757ms: Process C switching out of CPU; will block on I/O until time 123772ms [Q E D A F]
time 123761ms: Process E (tau 321ms) started using the CPU for 774ms burst [Q D A F]
time 123772ms: Process C (tau 661ms) completed I/O; added to ready queue [Q C D A F]
time 123980ms: Process H (tau 699ms) completed I/O; added to ready queue [Q C H D A F]
time 124535ms: Process E (tau 321ms) completed a CPU burst; 50 bursts to go [Q C H D A F]
time 124535ms: Recalculated tau = 548ms for process E [Q C H D A F]
time 124535ms: Process E switching out of CPU; will block on I/O until time 126670ms [Q C H D A F]
time 124539ms: Process C (tau 661ms) started using the CPU for 238ms burst [Q H D A F]
time 124777ms: Process C (tau 661ms) completed a CPU burst; 84 bursts to go [Q H D A F]
time 124777ms: Recalculated tau = 450ms for process C [Q H D A F]
time 124777ms: Process C switching out of CPU; will block on I/O until time 125114ms [Q H D A F]
time 124781ms: Process H (tau 699ms) started using the CPU for 1191ms burst [Q D A F]
time 125114ms: Process C (tau 450ms) completed I/O; added to ready queue [Q C D A F]
time 125972ms: Process H (tau 699ms) completed a CPU burst; 23 bursts to go [Q C D A F]
time 125972ms: Recalculated tau = 945ms for process H [Q C D A F]
time 125972ms: Process H switching out of CPU; will block on I/O until time 127787ms [Q C D A F]
time 125976ms: Process C (tau 450ms) started using the CPU for 1698ms burst [Q D A F]
time 126670ms: Process E (tau 548ms) completed I/O; added to ready queue [Q E D A F]
time 127674ms: Process C (tau 450ms) completed a CPU burst; 83 bursts to go [Q E D A F]
time 127674ms: Recalculated tau = 1074ms for process C [Q E D A F]
time 127674ms: Process C switching out of CPU; will block on I/O until time 128473ms [Q E D A F]
time 127678ms: Process E (tau 548ms) started using the CPU for 365ms burst [Q D A F]
time 127787ms: Process H (tau 945ms) completed I/O; added to ready queue [Q H D A F]
time 128043ms: Process E (tau 548ms) completed a CPU burst; 49 bursts to go [Q H D A F]
time 128043ms: Recalculated tau = 457ms for process E [Q H D A F]
time 128043ms: Process E switching out of CPU; will block on I/O until time 129029ms [Q H D A F]
time 128047ms: Process H (tau 945ms) started using the CPU for 118ms burst [Q D A F]
time 128165ms: Process H (tau 945ms) completed a CPU burst; 22 bursts to go [Q D A F]
time 128165ms: Recalculated tau = 532ms for process H [Q D A F]
time 128165ms: Process H switching out of CPU; will block on I/O until time 128267ms [Q D A F]
time 128169ms: Process D (tau 1459ms) started using the CPU for 205ms burst [Q A F]
time 128267ms: Process H (tau 532ms) completed I/O; added to ready queue [Q H A F]
time 128374ms: Process D (tau 1459ms) completed a CPU burst; 40 bursts to go [Q H A F]
time 128374ms: Recalculated tau = 832ms for process D [Q H A F]
time 128374ms: Process D switching out of CPU; will block on I/O until time 129084ms [Q H A F]
time 128378ms: Process H (tau 532ms) started using the CPU for 182ms burst [Q A F]
time 128473ms: Process C (tau 1074ms) completed I/O; added to ready queue [Q C A F]
time 128560ms: Process H (tau 532ms) completed a CPU burst; 21 bursts to go [Q C A F]
time 128560ms: Recalculated tau = 357ms for process H [Q C A F]
time 128560ms: Process H switching out of CPU; will block on I/O until time 128956ms [Q C A F]
time 128564ms: Process C (tau 1074ms) started using the CPU for 1563ms burst [Q A F]
time 128956ms: Process H (tau 357ms) completed I/O; added to ready queue [Q H A F]
time 129029ms: Process E (tau 457ms) completed I/O; added to ready queue [Q H E A F]
time 129084ms: Process D (tau 832ms) completed I/O; added to ready queue [Q H E D A F]
time 130127ms: Process C (tau 1074ms) completed a CPU burst; 82 bursts to go [Q H E D A F]
time 130127ms: Recalculated tau = 1319ms for process C [Q H E D A F]
time 130127ms: Process C switching out of CPU; will block on I/O until time 130467ms [Q H E D A F]
time 130131ms: Process H (tau 357ms) started using the CPU for 1827ms burst [Q E D A F]
time 130467ms: Process C (tau 1319ms) completed I/O; added to ready queue [Q E D C A F]
time 131958ms: Process H (tau 357ms) completed a CPU burst; 20 bursts to go [Q E D C A F]
time 131958ms: Recalculated tau = 1092ms for process H [Q E D C A F]
time 131958ms: Process H switching out of CPU; will block on I/O until time 132506ms [Q E D C A F]
time 131962ms: Process E (tau 457ms) started using the CPU for 16ms burst [Q D C A F]
time 131978ms: Process E (tau 457ms) completed a CPU burst; 48 bursts to go [Q D C A F]
time 131978ms: Recalculated tau = 237ms for process E [Q D C A F]
time 131978ms: Process E switching out of CPU; will block on I/O until time 132190ms [Q D C A F]
time 131982ms: Process D (tau 832ms) started using the CPU for 1404ms burst [Q C A F]
time 132190ms: Process E (tau 237ms) completed I/O; added to ready queue [Q E C A F]
time 132506ms: Process H (tau 1092ms) completed I/O; added to ready queue [Q E H C A F]
time 133386ms: Process D (tau 832ms) completed a CPU burst; 39 bursts to go [Q E H C A F]
time 133386ms: Recalculated tau = 1118ms for process D [Q E H C A F]
time 133386ms: Process D switching out of CPU; will block on I/O until time 134577ms [Q E H C A F]
time 133390ms: Process E (tau 237ms) started using the CPU for 800ms burst [Q H C A F]
time 134190ms: Process E (tau 237ms) completed a CPU burst; 47 bursts to go [Q H C A F]
time 134190ms: Recalculated tau = 519ms for process E [Q H C A F]
time 134190ms: Process E switching out of CPU; will block on I/O until time 134840ms [Q H C A F]
time 134194ms: Process H (tau 1092ms) started using the CPU for 2ms burst [Q C A F]
time 134196ms: Process H (tau 1092ms) completed a CPU burst; 19 bursts to go [Q C A F]
time 134196ms: Recalculated tau = 547ms for process H [Q C A F]
time 134196ms: Process H switching out of CPU; will block on I/O until time 135491ms [Q C A F]
time 134200ms: Process C (tau 1319ms) started using the CPU for 1428ms burst [Q A F]
time 134577ms: Process D (tau 1118ms) completed I/O; added to ready queue [Q D A F]
time 134840ms: Process E (tau 519ms) completed I/O; added to ready queue [Q E D A F]
time 135491ms: Process H (tau 547ms) completed I/O; added to ready queue [Q E H D A F]
time 135628ms: Process C (tau 1319ms) completed a CPU burst; 81 bursts to go [Q E H D A F]
time 135628ms: Recalculated tau = 1374ms for process C [Q E H D A F]
time 135628ms: Process C switching out of CPU; will block on I/O until time 137315ms [Q E H D A F]
time 135632ms: Process E (tau 519ms) started using the CPU for 520ms burst [Q H D A F]
time 136152ms: Process E (tau 519ms) completed a CPU burst; 46 bursts to go [Q H D A F]
time 136152ms: Recalculated tau = 520ms for process E [Q H D A F]
time 136152ms: Process E switching out of CPU; will block on I/O until time 137670ms [Q H D A F]
time 136156ms: Process H (tau 547ms) started using the CPU for 398ms burst [Q D A F]
time 136554ms: Process H (tau 547ms) completed a CPU burst; 18 bursts to go [Q D A F]
time 136554ms: Recalculated tau = 473ms for process H [Q D A F]
time 136554ms: Process H switching out of CPU; will block on I/O until time 137465ms [Q D A F]
time 136558ms: Process D (tau 1118ms) started using the CPU for 3202ms burst [Q A F]
time 137315ms: Process C (tau 1374ms) completed I/O; added to ready queue [Q C A F]
time 137465ms: Process H (tau 473ms) completed I/O; added to ready queue [Q H C A F]
time 137670ms: Process E (tau 520ms) completed I/O; added to ready queue [Q H E C A F]
time 139760ms: Process D (tau 1118ms) completed a CPU burst; 38 bursts to go [Q H E C A F]
time 139760ms: Recalculated tau = 2160ms for process D [Q H E C A F]
time 139760ms: Process D switching out of CPU; will block on I/O until time 141062ms [Q H E C A F]
time 139764ms: Process H (tau 473ms) started using the CPU for 1096ms burst [Q E C A F]
time 140860ms: Process H (tau 473ms) completed a CPU burst; 17 bursts to go [Q E C A F]
time 140860ms: Recalculated tau = 785ms for process H [Q E C A F]
time 140860ms: Process H switching out of CPU; will block on I/O until time 143965ms [Q E C A F]
time 140864ms: Process E (tau 520ms) started using the CPU for 284ms burst [Q C A F]
time 141062ms: Process D (tau 2160ms) completed I/O; added to ready queue [Q C A D F]
time 141148ms: Process E (tau 520ms) completed a CPU burst; 45 bursts to go [Q C A D F]
time 141148ms: Recalculated tau = 402ms for process E [Q C A D F]
time 141148ms: Process E switching out of CPU; will block on I/O until time 141408ms [Q C A D F]
time 141152ms: Process C (tau 1374ms) started using the CPU for 1761ms burst [Q A D F]
time 141408ms: Process E (tau 402ms) completed I/O; added to ready queue [Q E A D F]
time 142913ms: Process C (tau 1374ms) completed a CPU burst; 80 bursts to go [Q E A D F]
time 142913ms: Recalculated tau = 1568ms for process C [Q E A D F]
time 142913ms: Process C switching out of CPU; will block on I/O until time 143692ms [Q E A D F]
time 142917ms: Process E (tau 402ms) started using the CPU for 2021ms burst [Q A D F]
time 143692ms: Process C (tau 1568ms) completed I/O; added to ready queue [Q A C D F]
time 143965ms: Process H (tau 785ms) completed I/O; added to ready queue [Q H A C D F]
time 144938ms: Process E (tau 402ms) completed a CPU burst; 44 bursts to go [Q H A C D F]
time 144938ms: Recalculated tau = 1212ms for process E [Q H A C D F]
time 144938ms: Process E switching out of CPU; will block on I/O until time 148053ms [Q H A C D F]
time 144942ms: Process H (tau 785ms) started using the CPU for 286ms burst [Q A C D F]
time 145228ms: Process H (tau 785ms) completed a CPU burst; 16 bursts to go [Q A C D F]
time 145228ms: Recalculated tau = 536ms for process H [Q A C D F]
time 145228ms: Process H switching out of CPU; will block on I/O until time 145369ms [Q A C D F]
time 145232ms: Process A (tau 1483ms) started using the CPU for 322ms burst [Q C D F]
time 145369ms: Process H (tau 536ms) completed I/O; added to ready queue [Q H C D F]
time 145554ms: Process A (tau 1483ms) completed a CPU burst; 57 bursts to go [Q H C D F]
time 145554ms: Recalculated tau = 903ms for process A [Q H C D F]
time 145554ms: Process A switching out of CPU; will block on I/O until time 146535ms [Q H C D F]
time 145558ms: Process H (tau 536ms) started using the CPU for 1908ms burst [Q C D F]
time 146535ms: Process A (tau 903ms) completed I/O; added to ready queue [Q A C D F]
time 147466ms: Process H (tau 536ms) completed a CPU burst; 15 bursts to go [Q A C D F]
time 147466ms: Recalculated tau = 1222ms for process H [Q A C D F]
time 147466ms: Process H switching out of CPU; will block on I/O until time 149428ms [Q A C D F]
time 147470ms: Process A (tau 903ms) started using the CPU for 468ms burst [Q C D F]
time 147938ms: Process A (tau 903ms) completed a CPU burst; 56 bursts to go [Q C D F]
time 147938ms: Recalculated tau = 686ms for process A [Q C D F]
time 147938ms: Process A switching out of CPU; will block on I/O until time 148224ms [Q C D F]
time 147942ms: Process C (tau 1568ms) started using the CPU for 1852ms burst [Q D F]
time 148053ms: Process E (tau 1212ms) completed I/O; added to ready queue [Q E D F]
time 148224ms: Process A (tau 686ms) completed I/O; added to ready queue [Q A E D F]
time 149428ms: Process H (tau 1222ms) completed I/O; added to ready queue [Q A E H D F]
time 149794ms: Process C (tau 1568ms) completed a CPU burst; 79 bursts to go [Q A E H D F]
time 149794ms: Recalculated tau = 1710ms for process C [Q A E H D F]
time 149794ms: Process C switching out of CPU; will block on I/O until time 150201ms [Q A E H D F]
time 149798ms: Process A (tau 686ms) started using the CPU for 2475ms burst [Q E H D F]
time 150201ms: Process C (tau 1710ms) completed I/O; added to ready queue [Q E H C D F]
time 152273ms: Process A (tau 686ms) completed a CPU burst; 55 bursts to go [Q E H C D F]
time 152273ms: Recalculated tau = 1581ms for process A [Q E H C D F]
time 152273ms: Process A switching out of CPU; will block on I/O until time 152364ms [Q E H C D F]
time 152277ms: Process E (tau 1212ms) started using the CPU for 329ms burst [Q H C D F]
time 152364ms: Process A (tau 1581ms) completed I/O; added to ready queue [Q H A C D F]
time 152606ms: Process E (tau 1212ms) completed a CPU burst; 43 bursts to go [Q H A C D F]
time 152606ms: Recalculated tau = 771ms for process E [Q H A C D F]
time 152606ms: Process E switching out of CPU; will block on I/O until time 152797ms [Q H A C D F]
time 152610ms: Process H (tau 1222ms) started using the CPU for 3276ms burst [Q A C D F]
time 152797ms: Process E (tau 771ms) completed I/O; added to ready queue [Q E A C D F]
time 155886ms: Process H (tau 1222ms) completed a CPU burst; 14 bursts to go [Q E A C D F]
time 155886ms: Recalculated tau = 2249ms for process H [Q E A C D F]
time 155886ms: Process H switching out of CPU; will block on I/O until time 156142ms [Q E A C D F]
time 155890ms: Process E (tau 771ms) started using the CPU for 654ms burst [Q A C D F]
time 156142ms: Process H (tau 2249ms) completed I/O; added to ready queue [Q A C D H F]
time 156544ms: Process E (tau 771ms) completed a CPU burst; 42 bursts to go [Q A C D H F]
time 156544ms: Recalculated tau = 713ms for process E [Q A C D H F]
time 156544ms: Process E switching out of CPU; will block on I/O until time 157430ms [Q A C D H F]
time 156548ms: Process A (tau 1581ms) started using the CPU for 639ms burst [Q C D H F]
time 157187ms: Process A (tau 1581ms) completed a CPU burst; 54 bursts to go [Q C D H F]
time 157187ms: Recalculated tau = 1110ms for process A [Q C D H F]
time 157187ms: Process A switching out of CPU; will block on I/O until time 157831ms [Q C D H F]
time 157191ms: Process C (tau 1710ms) started using the CPU for 230ms burst [Q D H F]
time 157421ms: Process C (tau 1710ms) completed a CPU burst; 78 bursts to go [Q D H F]
time 157421ms: Recalculated tau = 970ms for process C [Q D H F]
time 157421ms: Process C switching out of CPU; will block on I/O until time 158206ms [Q D H F]
time 157425ms: Process D (tau 2160ms) started using the CPU for 521ms burst [Q H F]
time 157430ms: Process E (tau 713ms) completed I/O; added to ready queue [Q E H F]
time 157831ms: Process A (tau 1110ms) completed I/O; added to ready queue [Q E A H F]
time 157946ms: Process D (tau 2160ms) completed a CPU burst; 37 bursts to go [Q E A H F]
time 157946ms: Recalculated tau = 1341ms for process D [Q E A H F]
time 157946ms: Process D switching out of CPU; will block on I/O until time 160529ms [Q E A H F]
time 157950ms: Process E (tau 713ms) started using the CPU for 539ms burst [Q A H F]
time 158206ms: Process C (tau 970ms) completed I/O; added to ready queue [Q C A H F]
time 158489ms: Process E (tau 713ms) completed a CPU burst; 41 bursts to go [Q C A H F]
time 158489ms: Recalculated tau = 626ms for process E [Q C A H F]
time 158489ms: Process E switching out of CPU; will block on I/O until time 160048ms [Q C A H F]
time 158493ms: Process C (tau 970ms) started using the CPU for 768ms burst [Q A H F]
time 159261ms: Process C (tau 970ms) completed a CPU burst; 77 bursts to go [Q A H F]
time 159261ms: Recalculated tau = 869ms for process C [Q A H F]
time 159261ms: Process C switching out of CPU; will block on I/O until time 159456ms [Q A H F]
time 159265ms: Process A (tau 1110ms) started using the CPU for 2457ms burst [Q H F]
time 159456ms: Process C (tau 869ms) completed I/O; added to ready queue [Q C H F]
time 160048ms: Process E (tau 626ms) completed I/O; added to ready queue [Q E C H F]
time 160529ms: Process D (tau 1341ms) completed I/O; added to ready queue [Q E C D H F]
time 161722ms: Process A (tau 1110ms) completed a CPU burst; 53 bursts to go [Q E C D H F]
time 161722ms: Recalculated tau = 1784ms for process A [Q E C D H F]
time 161722ms: Process A switching out of CPU; will block on I/O until time 164386ms [Q E C D H F]
time 161726ms: Process E (tau 626ms) started using the CPU for 1801ms burst [Q C D H F]
time 163527ms: Process E (tau 626ms) completed a CPU burst; 40 bursts to go [Q C D H F]
time 163527ms: Recalculated tau = 1214ms for process E [Q C D H F]
time 163527ms: Process E switching out of CPU; will block on I/O until time 166149ms [Q C D H F]
time 163531ms: Process C (tau 869ms) started using the CPU for 106ms burst [Q D H F]
time 163637ms: Process C (tau 869ms) completed a CPU burst; 76 bursts to go [Q D H F]
time 163637ms: Recalculated tau = 488ms for process C [Q D H F]
time 163637ms: Process C switching out of CPU; will block on I/O until time 164208ms [Q D H F]
time 163641ms: Process D (tau 1341ms) started using the CPU for 713ms burst [Q H F]
time 164208ms: Process C (tau 488ms) completed I/O; added to ready queue [Q C H F]
time 164354ms: Process D (tau 1341ms) completed a CPU burst; 36 bursts to go [Q C H F]
time 164354ms: Recalculated tau = 1027ms for process D [Q C H F]
time 164354ms: Process D switching out of CPU; will block on I/O until time 165610ms [Q C H F]
time 164358ms: Process C (tau 488ms) started using the CPU for 1544ms burst [Q H F]
time 164386ms: Process A (tau 1784ms) completed I/O; added to ready queue [Q A H F]
time 165610ms: Process D (tau 1027ms) completed I/O; added to ready queue [Q D A H F]
time 165902ms: Process C (tau 488ms) completed a CPU burst; 75 bursts to go [Q D A H F]
time 165902ms: Recalculated tau = 1016ms for process C [Q D A H F]
time 165902ms: Process C switching out of CPU; will block on I/O until time 167423ms [Q D A H F]
time 165906ms: Process D (tau 1027ms) started using the CPU for 152ms burst [Q A H F]
time 166058ms: Process D (tau 1027ms) completed a CPU burst; 35 bursts to go [Q A H F]
time 166058ms: Recalculated tau = 590ms for process D [Q A H F]
time 166058ms: Process D switching out of CPU; will block on I/O until time 166678ms [Q A H F]
time 166062ms: Process A (tau 1784ms) started using the CPU for 184ms burst [Q H F]
time 166149ms: Process E (tau 1214ms) completed I/O; added to ready queue [Q E H F]
time 166246ms: Process A (tau 1784ms) completed a CPU burst; 52 bursts to go [Q E H F]
time 166246ms: Recalculated tau = 984ms for process A [Q E H F]
time 166246ms: Process A switching out of CPU; will block on I/O until time 166996ms [Q E H F]
time 166250ms: Process E (tau 1214ms) started using the CPU for 343ms burst [Q H F]
time 166593ms: Process E (tau 1214ms) completed a CPU burst; 39 bursts to go [Q H F]
time 166593ms: Recalculated tau = 779ms for process E [Q H F]
time 166593ms: Process E switching out of CPU; will block on I/O until time 166906ms [Q H F]
time 166597ms: Process H (tau 2249ms) started using the CPU for 1008ms burst [Q F]
time 166678ms: Process D (tau 590ms) completed I/O; added to ready queue [Q D F]
time 166906ms: Process E (tau 779ms) completed I/O; added to ready queue [Q D E F]
time 166996ms: Process A (tau 984ms) completed I/O; added to ready queue [Q D E A F]
time 167423ms: Process C (tau 1016ms) completed I/O; added to ready queue [Q D E A C F]
time 167605ms: Process H (tau 2249ms) completed a CPU burst; 13 bursts to go [Q D E A C F]
time 167605ms: Recalculated tau = 1629ms for process H [Q D E A C F]
time 167605ms: Process H switching out of CPU; will block on I/O until time 167626ms [Q D E A C F]
time 167609ms: Process D (tau 590ms) started using the CPU for 666ms burst [Q E A C F]
time 167626ms: Process H (tau 1629ms) completed I/O; added to ready queue [Q E A C H F]
time 168275ms: Process D (tau 590ms) completed a CPU burst; 34 bursts to go [Q E A C H F]
time 168275ms: Recalculated tau = 628ms for process D [Q E A C H F]
time 168275ms: Process D switching out of CPU; will block on I/O until time 169012ms [Q E A C H F]
time 168279ms: Process E (tau 779ms) started using the CPU for 141ms burst [Q A C H F]
time 168420ms: Process E (tau 779ms) completed a CPU burst; 38 bursts to go [Q A C H F]
time 168420ms: Recalculated tau = 460ms for process E [Q A C H F]
time 168420ms: Process E switching out of CPU; will block on I/O until time 170743ms [Q A C H F]
time 168424ms: Process A (tau 984ms) started using the CPU for 141ms burst [Q C H F]
time 168565ms: Process A (tau 984ms) completed a CPU burst; 51 bursts to go [Q C H F]
time 168565ms: Recalculated tau = 563ms for process A [Q C H F]
time 168565ms: Process A switching out of CPU; will block on I/O until time 168851ms [Q C H F]
time 168569ms: Process C (tau 1016ms) started using the CPU for 147ms burst [Q H F]
time 168716ms: Process C (tau 1016ms) completed a CPU burst; 74 bursts to go [Q H F]
time 168716ms: Recalculated tau = 582ms for process C [Q H F]
time 168716ms: Process C switching out of CPU; will block on I/O until time 168837ms [Q H F]
time 168720ms: Process H (tau 1629ms) started using the CPU for 3004ms burst [Q F]
time 168837ms: Process C (tau 582ms) completed I/O; added to ready queue [Q C F]
time 168851ms: Process A (tau 563ms) completed I/O; added to ready queue [Q A C F]
time 169012ms: Process D (tau 628ms) completed I/O; added to ready queue [Q A C D F]
time 170743ms: Process E (tau 460ms) completed I/O; added to ready queue [Q E A C D F]
time 171724ms: Process H (tau 1629ms) completed a CPU burst; 12 bursts to go [Q E A C D F]
time 171724ms: Recalculated tau = 2317ms for process H [Q E A C D F]
time 171724ms: Process H switching out of CPU; will block on I/O until time 171914ms [Q E A C D F]
time 171728ms: Process E (tau 460ms) started using the CPU for 616ms burst [Q A C D F]
time 171914ms: Process H (tau 2317ms) completed I/O; added to ready queue [Q A C D H F]
time 172344ms: Process E (tau 460ms) completed a CPU burst; 37 bursts to go [Q A C D H F]
time 172344ms: Recalculated tau = 538ms for process E [Q A C D H F]
time 172344ms: Process E switching out of CPU; will block on I/O until time 172787ms [Q A C D H F]
time 172348ms: Process A (tau 563ms) started using the CPU for 2915ms burst [Q C D H F]
time 172787ms: Process E (tau 538ms) completed I/O; added to ready queue [Q E C D H F]
time 175263ms: Process A (tau 563ms) completed a CPU burst; 50 bursts to go [Q E C D H F]
time 175263ms: Recalculated tau = 1739ms for process A [Q E C D H F]
time 175263ms: Process A switching out of CPU; will block on I/O until time 175790ms [Q E C D H F]
time 175267ms: Process E (tau 538ms) started using the CPU for 1898ms burst [Q C D H F]
time 175790ms: Process A (tau 1739ms) completed I/O; added to ready queue [Q C D A H F]
time 177165ms: Process E (tau 538ms) completed a CPU burst; 36 bursts to go [Q C D A H F]
time 177165ms: Recalculated tau = 1218ms for process E [Q C D A H F]
time 177165ms: Process E switching out of CPU; will block on I/O until time 177196ms [Q C D A H F]
time 177169ms: Process C (tau 582ms) started using the CPU for 2148ms burst [Q D A H F]
time 177196ms: Process E (tau 1218ms) completed I/O; added to ready queue [Q D E A H F]
time 179317ms: Process C (tau 582ms) completed a CPU burst; 73 bursts to go [Q D E A H F]
time 179317ms: Recalculated tau = 1365ms for process C [Q D E A H F]
time 179317ms: Process C switching out of CPU; will block on I/O until time 180861ms [Q D E A H F]
time 179321ms: Process D (tau 628ms) started using the CPU for 3886ms burst [Q E A H F]
time 180861ms: Process C (tau 1365ms) completed I/O; added to ready queue [Q E C A H F]
time 183207ms: Process D (tau 628ms) completed a CPU burst; 33 bursts to go [Q E C A H F]
time 183207ms: Recalculated tau = 2257ms for process D [Q E C A H F]
time 183207ms: Process D switching out of CPU; will block on I/O until time 184192ms [Q E C A H F]
time 183211ms: Process E (tau 1218ms) started using the CPU for 2027ms burst [Q C A H F]
time 184192ms: Process D (tau 2257ms) completed I/O; added to ready queue [Q C A D H F]
time 185238ms: Process E (tau 1218ms) completed a CPU burst; 35 bursts to go [Q C A D H F]
time 185238ms: Recalculated tau = 1623ms for process E [Q C A D H F]
time 185238ms: Process E switching out of CPU; will block on I/O until time 185407ms [Q C A D H F]
time 185242ms: Process C (tau 1365ms) started using the CPU for 1935ms burst [Q A D H F]
time 185407ms: Process E (tau 1623ms) completed I/O; added to ready queue [Q E A D H F]
time 187177ms: Process C (tau 1365ms) completed a CPU burst; 72 bursts to go [Q E A D H F]
time 187177ms: Recalculated tau = 1650ms for process C [Q E A D H F]
time 187177ms: Process C switching out of CPU; will block on I/O until time 187316ms [Q E A D H F]
time 187181ms: Process E (tau 1623ms) started using the CPU for 1328ms burst [Q A D H F]
time 187316ms: Process C (tau 1650ms) completed I/O; added to ready queue [Q C A D H F]
time 188509ms: Process E (tau 1623ms) completed a CPU burst; 34 bursts to go [Q C A D H F]
time 188509ms: Recalculated tau = 1476ms for process E [Q C A D H F]
time 188509ms: Process E switching out of CPU; will block on I/O until time 189928ms [Q C A D H F]
time 188513ms: Process C (tau 1650ms) started using the CPU for 142ms burst [Q A D H F]
time 188655ms: Process C (tau 1650ms) completed a CPU burst; 71 bursts to go [Q A D H F]
time 188655ms: Recalculated tau = 896ms for process C [Q A D H F]
time 188655ms: Process C switching out of CPU; will block on I/O until time 190067ms [Q A D H F]
time 188659ms: Process A (tau 1739ms) started using the CPU for 541ms burst [Q D H F]
time 189200ms: Process A (tau 1739ms) completed a CPU burst; 49 bursts to go [Q D H F]
time 189200ms: Recalculated tau = 1140ms for process A [Q D H F]
time 189200ms: Process A switching out of CPU; will block on I/O until time 190695ms [Q D H F]
time 189204ms: Process D (tau 2257ms) started using the CPU for 1149ms burst [Q H F]
time 189928ms: Process E (tau 1476ms) completed I/O; added to ready queue [Q E H F]
time 190067ms: Process C (tau 896ms) completed I/O; added to ready queue [Q C E H F]
time 190353ms: Process D (tau 2257ms) completed a CPU burst; 32 bursts to go [Q C E H F]
time 190353ms: Recalculated tau = 1703ms for process D [Q C E H F]
time 190353ms: Process D switching out of CPU; will block on I/O until time 190515ms [Q C E H F]
time 190357ms: Process C (tau 896ms) started using the CPU for 2295ms burst [Q E H F]
time 190515ms: Process D (tau 1703ms) completed I/O; added to ready queue [Q E D H F]
time 190695ms: Process A (tau 1140ms) completed I/O; added to ready queue [Q A E D H F]
time 192652ms: Process C (tau 896ms) completed a CPU burst; 70 bursts to go [Q A E D H F]
time 192652ms: Recalculated tau = 1596ms for process C [Q A E D H F]
time 192652ms: Process C switching out of CPU; will block on I/O until time 193421ms [Q A E D H F]
time 192656ms: Process A (tau 1140ms) started using the CPU for 65ms burst [Q E D H F]
time 192721ms: Process A (tau 1140ms) completed a CPU burst; 48 bursts to go [Q E D H F]
time 192721ms: Recalculated tau = 603ms for process A [Q E D H F]
time 192721ms: Process A switching out of CPU; will block on I/O until time 194262ms [Q E D H F]
time 192725ms: Process E (tau 1476ms) started using the CPU for 298ms burst [Q D H F]
time 193023ms: Process E (tau 1476ms) completed a CPU burst; 33 bursts to go [Q D H F]
time 193023ms: Recalculated tau = 887ms for process E [Q D H F]
time 193023ms: Process E switching out of CPU; will block on I/O until time 193779ms [Q D H F]
time 193027ms: Process D (tau 1703ms) started using the CPU for 1085ms burst [Q H F]
time 193421ms: Process C (tau 1596ms) completed I/O; added to ready queue [Q C H F]
time 193779ms: Process E (tau 887ms) completed I/O; added to ready queue [Q E C H F]
time 194112ms: Process D (tau 1703ms) completed a CPU burst; 31 bursts to go [Q E C H F]
time 194112ms: Recalculated tau = 1394ms for process D [Q E C H F]
time 194112ms: Process D switching out of CPU; will block on I/O until time 195324ms [Q E C H F]
time 194116ms: Process E (tau 887ms) started using the CPU for 114ms burst [Q C H F]
time 194230ms: Process E (tau 887ms) completed a CPU burst; 32 bursts to go [Q C H F]
time 194230ms: Recalculated tau = 501ms for process E [Q C H F]
time 194230ms: Process E switching out of CPU; will block on I/O until time 195070ms [Q C H F]
time 194234ms: Process C (tau 1596ms) started using the CPU for 43ms burst [Q H F]
time 194262ms: Process A (tau 603ms) completed I/O; added to ready queue [Q A H F]
time 194277ms: Process C (tau 1596ms) completed a CPU burst; 69 bursts to go [Q A H F]
time 194277ms: Recalculated tau = 820ms for process C [Q A H F]
time 194277ms: Process C switching out of CPU; will block on I/O until time 195978ms [Q A H F]
time 194281ms: Process A (tau 603ms) started using the CPU for 1213ms burst [Q H F]
time 195070ms: Process E (tau 501ms) completed I/O; added to ready queue [Q E H F]
time 195324ms: Process D (tau 1394ms) completed I/O; added to ready queue [Q E D H F]
time 195494ms: Process A (tau 603ms) completed a CPU burst; 47 bursts to go [Q E D H F]
time 195494ms: Recalculated tau = 908ms for process A [Q E D H F]
time 195494ms: Process A switching out of CPU; will block on I/O until time 196928ms [Q E D H F]
time 195498ms: Process E (tau 501ms) started using the CPU for 387ms burst [Q D H F]
time 195885ms: Process E (tau 501ms) completed a CPU burst; 31 bursts to go [Q D H F]
time 195885ms: Recalculated tau = 444ms for process E [Q D H F]
time 195885ms: Process E switching out of CPU; will block on I/O until time 196697ms [Q D H F]
time 195889ms: Process D (tau 1394ms) started using the CPU for 1095ms burst [Q H F]
time 195978ms: Process C (tau 820ms) completed I/O; added to ready queue [Q C H F]
time 196697ms: Process E (tau 444ms) completed I/O; added to ready queue [Q E C H F]
time 196928ms: Process A (tau 908ms) completed I/O; added to ready queue [Q E C A H F]
time 196984ms: Process D (tau 1394ms) completed a CPU burst; 30 bursts to go [Q E C A H F]
time 196984ms: Recalculated tau = 1245ms for process D [Q E C A H F]
time 196984ms: Process D switching out of CPU; will block on I/O until time 199178ms [Q E C A H F]
time 196988ms: Process E (tau 444ms) started using the CPU for 2392ms burst [Q C A H F]
time 199178ms: Process D (tau 1245ms) completed I/O; added to ready queue [Q C A D H F]
time 199380ms: Process E (tau 444ms) completed a CPU burst; 30 bursts to go [Q C A D H F]
time 199380ms: Recalculated tau = 1418ms for process E [Q C A D H F]
time 199380ms: Process E switching out of CPU; will block on I/O until time 199559ms [Q C A D H F]
time 199384ms: Process C (tau 820ms) started using the CPU for 1236ms burst [Q A D H F]
time 199559ms: Process E (tau 1418ms) completed I/O; added to ready queue [Q A D E H F]
time 200620ms: Process C (tau 820ms) completed a CPU burst; 68 bursts to go [Q A D E H F]
time 200620ms: Recalculated tau = 1028ms for process C [Q A D E H F]
time 200620ms: Process C switching out of CPU; will block on I/O until time 201829ms [Q A D E H F]
time 200624ms: Process A (tau 908ms) started using the CPU for 676ms burst [Q D E H F]
time 201300ms: Process A (tau 908ms) completed a CPU burst; 46 bursts to go [Q D E H F]
time 201300ms: Recalculated tau = 792ms for process A [Q D E H F]
time 201300ms: Process A switching out of CPU; will block on I/O until time 201351ms [Q D E H F]
time 201304ms: Process D (tau 1245ms) started using the CPU for 24ms burst [Q E H F]
time 201328ms: Process D (tau 1245ms) completed a CPU burst; 29 bursts to go [Q E H F]
time 201328ms: Recalculated tau = 635ms for process D [Q E H F]
time 201328ms: Process D switching out of CPU; will block on I/O until time 203340ms [Q E H F]
time 201332ms: Process E (tau 1418ms) started using the CPU for 608ms burst [Q H F]
time 201351ms: Process A (tau 792ms) completed I/O; added to ready queue [Q A H F]
time 201829ms: Process C (tau 1028ms) completed I/O; added to ready queue [Q A C H F]
time 201940ms: Process E (tau 1418ms) completed a CPU burst; 29 bursts to go [Q A C H F]
time 201940ms: Recalculated tau = 1013ms for process E [Q A C H F]
time 201940ms: Process E switching out of CPU; will block on I/O until time 202935ms [Q A C H F]
time 201944ms: Process A (tau 792ms) started using the CPU for 1128ms burst [Q C H F]
time 202935ms: Process E (tau 1013ms) completed I/O; added to ready queue [Q E C H F]
time 203072ms: Process A (tau 792ms) completed a CPU burst; 45 bursts to go [Q E C H F]
time 203072ms: Recalculated tau = 960ms for process A [Q E C H F]
time 203072ms: Process A switching out of CPU; will block on I/O until time 203251ms [Q E C H F]
time 203076ms: Process E (tau 1013ms) started using the CPU for 307ms burst [Q C H F]
time 203251ms: Process A (tau 960ms) completed I/O; added to ready queue [Q A C H F]
time 203340ms: Process D (tau 635ms) completed I/O; added to ready queue [Q D A C H F]
time 203383ms: Process E (tau 1013ms) completed a CPU burst; 28 bursts to go [Q D A C H F]
time 203383ms: Recalculated tau = 660ms for process E [Q D A C H F]
time 203383ms: Process E switching out of CPU; will block on I/O until time 203456ms [Q D A C H F]
time 203387ms: Process D (tau 635ms) started using the CPU for 751ms burst [Q A C H F]
time 203456ms: Process E (tau 660ms) completed I/O; added to ready queue [Q E A C H F]
time 204138ms: Process D (tau 635ms) completed a CPU burst; 28 bursts to go [Q E A C H F]
time 204138ms: Recalculated tau = 693ms for process D [Q E A C H F]
time 204138ms: Process D switching out of CPU; will block on I/O until time 204584ms [Q E A C H F]
time 204142ms: Process E (tau 660ms) started using the CPU for 64ms burst [Q A C H F]
time 204206ms: Process E (tau 660ms) completed a CPU burst; 27 bursts to go [Q A C H F]
time 204206ms: Recalculated tau = 362ms for process E [Q A C H F]
time 204206ms: Process E switching out of CPU; will block on I/O until time 205610ms [Q A C H F]
time 204210ms: Process A (tau 960ms) started using the CPU for 229ms burst [Q C H F]
time 204439ms: Process A (tau 960ms) completed a CPU burst; 44 bursts to go [Q C H F]
time 204439ms: Recalculated tau = 595ms for process A [Q C H F]
time 204439ms: Process A switching out of CPU; will block on I/O until time 204453ms [Q C H F]
time 204443ms: Process C (tau 1028ms) started using the CPU for 41ms burst [Q H F]
time 204453ms: Process A (tau 595ms) completed I/O; added to ready queue [Q A H F]
time 204484ms: Process C (tau 1028ms) completed a CPU burst; 67 bursts to go [Q A H F]
time 204484ms: Recalculated tau = 535ms for process C [Q A H F]
time 204484ms: Process C switching out of CPU; will block on I/O until time 205779ms [Q A H F]
time 204488ms: Process A (tau 595ms) started using the CPU for 390ms burst [Q H F]
time 204584ms: Process D (tau 693ms) completed I/O; added to ready queue [Q D H F]
time 204878ms: Process A (tau 595ms) completed a CPU burst; 43 bursts to go [Q D H F]
time 204878ms: Recalculated tau = 493ms for process A [Q D H F]
time 204878ms: Process A switching out of CPU; will block on I/O until time 206748ms [Q D H F]
time 204882ms: Process D (tau 693ms) started using the CPU for 824ms burst [Q H F]
time 205610ms: Process E (tau 362ms) completed I/O; added to ready queue [Q E H F]
time 205706ms: Process D (tau 693ms) completed a CPU burst; 27 bursts to go [Q E H F]
time 205706ms: Recalculated tau = 759ms for process D [Q E H F]
time 205706ms: Process D switching out of CPU; will block on I/O until time 205732ms [Q E H F]
time 205710ms: Process E (tau 362ms) started using the CPU for 1477ms burst [Q H F]
time 205732ms: Process D (tau 759ms) completed I/O; added to ready queue [Q D H F]
time 205779ms: Process C (tau 535ms) completed I/O; added to ready queue [Q C D H F]
time 206748ms: Process A (tau 493ms) completed I/O; added to ready queue [Q A C D H F]
time 207187ms: Process E (tau 362ms) completed a CPU burst; 26 bursts to go [Q A C D H F]
time 207187ms: Recalculated tau = 920ms for process E [Q A C D H F]
time 207187ms: Process E switching out of CPU; will block on I/O until time 208615ms [Q A C D H F]
time 207191ms: Process A (tau 493ms) started using the CPU for 905ms burst [Q C D H F]
time 208096ms: Process A (tau 493ms) completed a CPU burst; 42 bursts to go [Q C D H F]
time 208096ms: Recalculated tau = 699ms for process A [Q C D H F]
time 208096ms: Process A switching out of CPU; will block on I/O until time 208484ms [Q C D H F]
time 208100ms: Process C (tau 535ms) started using the CPU for 626ms burst [Q D H F]
time 208484ms: Process A (tau 699ms) completed I/O; added to ready queue [Q A D H F]
time 208615ms: Process E (tau 920ms) completed I/O; added to ready queue [Q A D E H F]
time 208726ms: Process C (tau 535ms) completed a CPU burst; 66 bursts to go [Q A D E H F]
time 208726ms: Recalculated tau = 581ms for process C [Q A D E H F]
time 208726ms: Process C switching out of CPU; will block on I/O until time 209765ms [Q A D E H F]
time 208730ms: Process A (tau 699ms) started using the CPU for 118ms burst [Q D E H F]
time 208848ms: Process A (tau 699ms) completed a CPU burst; 41 bursts to go [Q D E H F]
time 208848ms: Recalculated tau = 409ms for process A [Q D E H F]
time 208848ms: Process A switching out of CPU; will block on I/O until time 208916ms [Q D E H F]
time 208852ms: Process D (tau 759ms) started using the CPU for 135ms burst [Q E H F]
time 208916ms: Process A (tau 409ms) completed I/O; added to ready queue [Q A E H F]
time 208987ms: Process D (tau 759ms) completed a CPU burst; 26 bursts to go [Q A E H F]
time 208987ms: Recalculated tau = 447ms for process D [Q A E H F]
time 208987ms: Process D switching out of CPU; will block on I/O until time 211428ms [Q A E H F]
time 208991ms: Process A (tau 409ms) started using the CPU for 179ms burst [Q E H F]
time 209170ms: Process A (tau 409ms) completed a CPU burst; 40 bursts to go [Q E H F]
time 209170ms: Recalculated tau = 294ms for process A [Q E H F]
time 209170ms: Process A switching out of CPU; will block on I/O until time 211362ms [Q E H F]
time 209174ms: Process E (tau 920ms) started using the CPU for 1615ms burst [Q H F]
time 209765ms: Process C (tau 581ms) completed I/O; added to ready queue [Q C H F]
time 210789ms: Process E (tau 920ms) completed a CPU burst; 25 bursts to go [Q C H F]
time 210789ms: Recalculated tau = 1268ms for process E [Q C H F]
time 210789ms: Process E switching out of CPU; will block on I/O until time 211347ms [Q C H F]
time 210793ms: Process C (tau 581ms) started using the CPU for 378ms burst [Q H F]
time 211171ms: Process C (tau 581ms) completed a CPU burst; 65 bursts to go [Q H F]
time 211171ms: Recalculated tau = 480ms for process C [Q H F]
time 211171ms: Process C switching out of CPU; will block on I/O until time 211434ms [Q H F]
time 211175ms: Process H (tau 2317ms) started using the CPU for 1207ms burst [Q F]
time 211347ms: Process E (tau 1268ms) completed I/O; added to ready queue [Q E F]
time 211362ms: Process A (tau 294ms) completed I/O; added to ready queue [Q A E F]
time 211428ms: Process D (tau 447ms) completed I/O; added to ready queue [Q A D E F]
time 211434ms: Process C (tau 480ms) completed I/O; added to ready queue [Q A D C E F]
time 212382ms: Process H (tau 2317ms) completed a CPU burst; 11 bursts to go [Q A D C E F]
time 212382ms: Recalculated tau = 1762ms for process H [Q A D C E F]
time 212382ms: Process H switching out of CPU; will block on I/O until time 213474ms [Q A D C E F]
time 212386ms: Process A (tau 294ms) started using the CPU for 513ms burst [Q D C E F]
time 212899ms: Process A (tau 294ms) completed a CPU burst; 39 bursts to go [Q D C E F]
time 212899ms: Recalculated tau = 404ms for process A [Q D C E F]
time 212899ms: Process A switching out of CPU; will block on I/O until time 213214ms [Q D C E F]
time 212903ms: Process D (tau 447ms) started using the CPU for 760ms burst [Q C E F]
time 213214ms: Process A (tau 404ms) completed I/O; added to ready queue [Q A C E F]
time 213474ms: Process H (tau 1762ms) completed I/O; added to ready queue [Q A C E H F]
time 213663ms: Process D (tau 447ms) completed a CPU burst; 25 bursts to go [Q A C E H F]
time 213663ms: Recalculated tau = 604ms for process D [Q A C E H F]
time 213663ms: Process D switching out of CPU; will block on I/O until time 213690ms [Q A C E H F]
time 213667ms: Process A (tau 404ms) started using the CPU for 469ms burst [Q C E H F]
time 213690ms: Process D (tau 604ms) completed I/O; added to ready queue [Q C D E H F]
time 214136ms: Process A (tau 404ms) completed a CPU burst; 38 bursts to go [Q C D E H F]
time 214136ms: Recalculated tau = 437ms for process A [Q C D E H F]
time 214136ms: Process A switching out of CPU; will block on I/O until time 214354ms [Q C D E H F]
time 214140ms: Process C (tau 480ms) started using the CPU for 528ms burst [Q D E H F]
time 214354ms: Process A (tau 437ms) completed I/O; added to ready queue [Q A D E H F]
time 214668ms: Process C (tau 480ms) completed a CPU burst; 64 bursts to go [Q A D E H F]
time 214668ms: Recalculated tau = 504ms for process C [Q A D E H F]
time 214668ms: Process C switching out of CPU; will block on I/O until time 215920ms [Q A D E H F]
time 214672ms: Process A (tau 437ms) started using the CPU for 2254ms burst [Q D E H F]
time 215920ms: Process C (tau 504ms) completed I/O; added to ready queue [Q C D E H F]
time 216926ms: Process A (tau 437ms) completed a CPU burst; 37 bursts to go [Q C D E H F]
time 216926ms: Recalculated tau = 1346ms for process A [Q C D E H F]
time 216926ms: Process A switching out of CPU; will block on I/O until time 218390ms [Q C D E H F]
time 216930ms: Process C (tau 504ms) started using the CPU for 3578ms burst [Q D E H F]
time 218390ms: Process A (tau 1346ms) completed I/O; added to ready queue [Q D E A H F]
time 220508ms: Process C (tau 504ms) completed a CPU burst; 63 bursts to go [Q D E A H F]
time 220508ms: Recalculated tau = 2041ms for process C [Q D E A H F]
time 220508ms: Process C switching out of CPU; will block on I/O until time 220710ms [Q D E A H F]
time 220512ms: Process D (tau 604ms) started using the CPU for 1466ms burst [Q E A H F]
time 220710ms: Process C (tau 2041ms) completed I/O; added to ready queue [Q E A H C F]
time 221978ms: Process D (tau 604ms) completed a CPU burst; 24 bursts to go [Q E A H C F]
time 221978ms: Recalculated tau = 1035ms for process D [Q E A H C F]
time 221978ms: Process D switching out of CPU; will block on I/O until time 222036ms [Q E A H C F]
time 221982ms: Process E (tau 1268ms) started using the CPU for 297ms burst [Q A H C F]
time 222036ms: Process D (tau 1035ms) completed I/O; added to ready queue [Q D A H C F]
time 222279ms: Process E (tau 1268ms) completed a CPU burst; 24 bursts to go [Q D A H C F]
time 222279ms: Recalculated tau = 783ms for process E [Q D A H C F]
time 222279ms: Process E switching out of CPU; will block on I/O until time 222422ms [Q D A H C F]
time 222283ms: Process D (tau 1035ms) started using the CPU for 1071ms burst [Q A H C F]
time 222422ms: Process E (tau 783ms) completed I/O; added to ready queue [Q E A H C F]
time 223354ms: Process D (tau 1035ms) completed a CPU burst; 23 bursts to go [Q E A H C F]
time 223354ms: Recalculated tau = 1053ms for process D [Q E A H C F]
time 223354ms: Process D switching out of CPU; will block on I/O until time 224594ms [Q E A H C F]
time 223358ms: Process E (tau 783ms) started using the CPU for 785ms burst [Q A H C F]
time 224143ms: Process E (tau 783ms) completed a CPU burst; 23 bursts to go [Q A H C F]
time 224143ms: Recalculated tau = 784ms for process E [Q A H C F]
time 224143ms: Process E switching out of CPU; will block on I/O until time 226698ms [Q A H C F]
time 224147ms: Process A (tau 1346ms) started using the CPU for 1566ms burst [Q H C F]
time 224594ms: Process D (tau 1053ms) completed I/O; added to ready queue [Q D H C F]
time 225713ms: Process A (tau 1346ms) completed a CPU burst; 36 bursts to go [Q D H C F]
time 225713ms: Recalculated tau = 1456ms for process A [Q D H C F]
time 225713ms: Process A switching out of CPU; will block on I/O until time 226632ms [Q D H C F]
time 225717ms: Process D (tau 1053ms) started using the CPU for 75ms burst [Q H C F]
time 225792ms: Process D (tau 1053ms) completed a CPU burst; 22 bursts to go [Q H C F]
time 225792ms: Recalculated tau = 564ms for process D [Q H C F]
time 225792ms: Process D switching out of CPU; will block on I/O until time 228200ms [Q H C F]
time 225796ms: Process H (tau 1762ms) started using the CPU for 424ms burst [Q C F]
time 226220ms: Process H (tau 1762ms) completed a CPU burst; 10 bursts to go [Q C F]
time 226220ms: Recalculated tau = 1093ms for process H [Q C F]
time 226220ms: Process H switching out of CPU; will block on I/O until time 226577ms [Q C F]
time 226224ms: Process C (tau 2041ms) started using the CPU for 551ms burst [Q F]
time 226577ms: Process H (tau 1093ms) completed I/O; added to ready queue [Q H F]
time 226632ms: Process A (tau 1456ms) completed I/O; added to ready queue [Q H A F]
time 226698ms: Process E (tau 784ms) completed I/O; added to ready queue [Q E H A F]
time 226775ms: Process C (tau 2041ms) completed a CPU burst; 62 bursts to go [Q E H A F]
time 226775ms: Recalculated tau = 1296ms for process C [Q E H A F]
time 226775ms: Process C switching out of CPU; will block on I/O until time 230650ms [Q E H A F]
time 226779ms: Process E (tau 784ms) started using the CPU for 941ms burst [Q H A F]
time 227720ms: Process E (tau 784ms) completed a CPU burst; 22 bursts to go [Q H A F]
time 227720ms: Recalculated tau = 863ms for process E [Q H A F]
time 227720ms: Process E switching out of CPU; will block on I/O until time 229074ms [Q H A F]
time 227724ms: Process H (tau 1093ms) started using the CPU for 1359ms burst [Q A F]
time 228200ms: Process D (tau 564ms) completed I/O; added to ready queue [Q D A F]
time 229074ms: Process E (tau 863ms) completed I/O; added to ready queue [Q D E A F]
time 229083ms: Process H (tau 1093ms) completed a CPU burst; 9 bursts to go [Q D E A F]
time 229083ms: Recalculated tau = 1226ms for process H [Q D E A F]
time 229083ms: Process H switching out of CPU; will block on I/O until time 229354ms [Q D E A F]
time 229087ms: Process D (tau 564ms) started using the CPU for 492ms burst [Q E A F]
time 229354ms: Process H (tau 1226ms) completed I/O; added to ready queue [Q E H A F]
time 229579ms: Process D (tau 564ms) completed a CPU burst; 21 bursts to go [Q E H A F]
time 229579ms: Recalculated tau = 528ms for process D [Q E H A F]
time 229579ms: Process D switching out of CPU; will block on I/O until time 231878ms [Q E H A F]
time 229583ms: Process E (tau 863ms) started using the CPU for 1400ms burst [Q H A F]
time 230650ms: Process C (tau 1296ms) completed I/O; added to ready queue [Q H C A F]
time 230983ms: Process E (tau 863ms) completed a CPU burst; 21 bursts to go [Q H C A F]
time 230983ms: Recalculated tau = 1132ms for process E [Q H C A F]
time 230983ms: Process E switching out of CPU; will block on I/O until time 231845ms [Q H C A F]
time 230987ms: Process H (tau 1226ms) started using the CPU for 1357ms burst [Q C A F]
time 231845ms: Process E (tau 1132ms) completed I/O; added to ready queue [Q E C A F]
time 231878ms: Process D (tau 528ms) completed I/O; added to ready queue [Q D E C A F]
time 232344ms: Process H (tau 1226ms) completed a CPU burst; 8 bursts to go [Q D E C A F]
time 232344ms: Recalculated tau = 1292ms for process H [Q D E C A F]
time 232344ms: Process H switching out of CPU; will block on I/O until time 232404ms [Q D E C A F]
time 232348ms: Process D (tau 528ms) started using the CPU for 22ms burst [Q E C A F]
time 232370ms: Process D (tau 528ms) completed a CPU burst; 20 bursts to go [Q E C A F]
time 232370ms: Recalculated tau = 275ms for process D [Q E C A F]
