Process A [NEW] (arrival time 9 ms) 16 CPU bursts
time 0ms: Simulator started for FCFS [Q <empty>]
time 9ms: Process A arrived; added to ready queue [Q A]
time 11ms: Process A started using the CPU for 56ms burst [Q <empty>]
time 92ms: Process A completed I/O; added to ready queue [Q A]
time 94ms: Process A started using the CPU for 60ms burst [Q <empty>]
time 309ms: Process A completed I/O; added to ready queue [Q A]
time 311ms: Process A started using the CPU for 39ms burst [Q <empty>]
time 402ms: Process A completed I/O; added to ready queue [Q A]
time 404ms: Process A started using the CPU for 47ms burst [Q <empty>]
time 455ms: Process A completed I/O; added to ready queue [Q A]
time 457ms: Process A started using the CPU for 137ms burst [Q <empty>]
time 620ms: Process A completed I/O; added to ready queue [Q A]
time 622ms: Process A started using the CPU for 64ms burst [Q <empty>]
time 703ms: Process A completed I/O; added to ready queue [Q A]
time 705ms: Process A started using the CPU for 68ms burst [Q <empty>]
time 839ms: Process A completed I/O; added to ready queue [Q A]
time 841ms: Process A started using the CPU for 113ms burst [Q <empty>]
time 972ms: Process A completed I/O; added to ready queue [Q A]
time 974ms: Process A started using the CPU for 11ms burst [Q <empty>]
time 1149ms: Process A completed I/O; added to ready queue [Q A]
time 1151ms: Process A started using the CPU for 24ms burst [Q <empty>]
time 1294ms: Process A completed I/O; added to ready queue [Q A]
time 1296ms: Process A started using the CPU for 76ms burst [Q <empty>]
time 1402ms: Process A completed I/O; added to ready queue [Q A]
time 1404ms: Process A started using the CPU for 122ms burst [Q <empty>]
time 1561ms: Process A completed I/O; added to ready queue [Q A]
time 1563ms: Process A started using the CPU for 9ms burst [Q <empty>]
time 1642ms: Process A completed I/O; added to ready queue [Q A]
time 1644ms: Process A started using the CPU for 62ms burst [Q <empty>]
time 1785ms: Process A completed I/O; added to ready queue [Q A]
time 1787ms: Process A started using the CPU for 200ms burst [Q <empty>]
time 2000ms: Process A completed I/O; added to ready queue [Q A]
time 2002ms: Process A started using the CPU for 197ms burst [Q <empty>]
time 2201ms: Simulator ended for FCFS [Q <empty>]
